package net.minecraft.src;
import java.util.Random;

import net.minecraft.block.Block;
import net.minecraft.item.Item;
import net.minecraft.item.ItemStack;
import net.minecraft.tileentity.TileEntityChest;
import net.minecraft.util.WeightedRandomChestContent;
import net.minecraft.world.World;
import net.minecraft.world.gen.feature.WorldGenerator;
import java.util.Random;

public class WorldGenLummy extends WorldGenerator
{
	private static final WeightedRandomChestContent[] bonusChestContent = new WeightedRandomChestContent[]
			{
			new WeightedRandomChestContent(Item.appleRed.itemID, 0, 4, 5, 40),
			new WeightedRandomChestContent(mod_BlocksGalore.WHITESpawn.blockID, 0, 1, 6, 25),
			new WeightedRandomChestContent(mod_BlocksGalore.GUARDSpawn.blockID, 0, 1, 6, 50),
			new WeightedRandomChestContent(mod_BlocksGalore.WIZARDSpawn.blockID, 0, 1, 6, 10),
			new WeightedRandomChestContent(Block.blockDiamond.blockID, 0, 1, 2, 10),
			new WeightedRandomChestContent(Item.swordStone.itemID, 0, 1, 4, 40),
			new WeightedRandomChestContent(Item.bow.itemID, 0, 1, 1, 20),
			new WeightedRandomChestContent(mod_MagicBow.Yewbow.itemID, 0, 1, 4, 10),
			new WeightedRandomChestContent(Item.arrow.itemID, 500, 20, 30, 40),
			};

	public WorldGenLummy() { }

	public boolean generate(World world, Random rand, int i, int j, int k) {
		//check that each corner is one of the valid spawn blocks
		if(world.getBlockId(i, j - 1, k) == Block.grass.blockID && world.getBlockId(i, j, k) == 0){

		world.setBlock(i + 0, j + 0, k + 0, Block.grass.blockID);
		world.setBlock(i + 0, j + 0, k + 1, Block.grass.blockID);
		world.setBlock(i + 0, j + 0, k + 2, Block.grass.blockID);
		world.setBlock(i + 0, j + 0, k + 3, Block.grass.blockID);
		world.setBlock(i + 0, j + 0, k + 4, Block.grass.blockID);
		world.setBlock(i + 0, j + 0, k + 5, Block.grass.blockID);
		world.setBlock(i + 0, j + 0, k + 6, Block.grass.blockID);
		world.setBlock(i + 0, j + 0, k + 7, Block.grass.blockID);
		world.setBlock(i + 0, j + 0, k + 8, Block.grass.blockID);
		world.setBlock(i + 0, j + 0, k + 9, Block.grass.blockID);
		world.setBlock(i + 0, j + 0, k + 10, Block.grass.blockID);
		world.setBlock(i + 0, j + 0, k + 11, Block.grass.blockID);
		world.setBlock(i + 0, j + 0, k + 12, Block.grass.blockID);
		world.setBlock(i + 0, j + 0, k + 13, Block.grass.blockID);
		world.setBlock(i + 0, j + 0, k + 14, Block.grass.blockID);
		world.setBlock(i + 0, j + 0, k + 15, Block.grass.blockID);
		world.setBlock(i + 0, j + 0, k + 16, Block.grass.blockID);
		world.setBlock(i + 1, j + 0, k + 0, Block.grass.blockID);
		world.setBlock(i + 1, j + 0, k + 1, Block.grass.blockID);
		world.setBlock(i + 1, j + 0, k + 2, Block.grass.blockID);
		world.setBlock(i + 1, j + 0, k + 3, Block.grass.blockID);
		world.setBlock(i + 1, j + 0, k + 4, Block.grass.blockID);
		world.setBlock(i + 1, j + 0, k + 5, Block.grass.blockID);
		world.setBlock(i + 1, j + 0, k + 6, Block.grass.blockID);
		world.setBlock(i + 1, j + 0, k + 7, Block.grass.blockID);
		world.setBlock(i + 1, j + 0, k + 8, Block.grass.blockID);
		world.setBlock(i + 1, j + 0, k + 9, Block.grass.blockID);
		world.setBlock(i + 1, j + 0, k + 10, Block.grass.blockID);
		world.setBlock(i + 1, j + 0, k + 11, Block.grass.blockID);
		world.setBlock(i + 1, j + 0, k + 12, Block.grass.blockID);
		world.setBlock(i + 1, j + 0, k + 13, Block.grass.blockID);
		world.setBlock(i + 1, j + 0, k + 14, Block.grass.blockID);
		world.setBlock(i + 1, j + 0, k + 15, Block.grass.blockID);
		world.setBlock(i + 1, j + 0, k + 16, Block.grass.blockID);
		world.setBlock(i + 1, j + 0, k + 17, Block.grass.blockID);
		world.setBlock(i + 1, j + 0, k + 18, Block.grass.blockID);
		world.setBlock(i + 1, j + 0, k + 19, Block.grass.blockID);
		world.setBlock(i + 1, j + 0, k + 20, Block.grass.blockID);
		world.setBlock(i + 2, j + 0, k + 0, Block.grass.blockID);
		world.setBlock(i + 2, j + 0, k + 1, Block.grass.blockID);
		world.setBlock(i + 2, j + 0, k + 2, Block.grass.blockID);
		world.setBlock(i + 2, j + 0, k + 3, Block.grass.blockID);
		world.setBlock(i + 2, j + 0, k + 4, Block.grass.blockID);
		world.setBlock(i + 2, j + 0, k + 5, Block.grass.blockID);
		world.setBlock(i + 2, j + 0, k + 6, Block.grass.blockID);
		world.setBlock(i + 2, j + 0, k + 7, Block.grass.blockID);
		world.setBlock(i + 2, j + 0, k + 8, Block.grass.blockID);
		world.setBlock(i + 2, j + 0, k + 9, Block.grass.blockID);
		world.setBlock(i + 2, j + 0, k + 10, Block.grass.blockID);
		world.setBlock(i + 2, j + 0, k + 11, Block.grass.blockID);
		world.setBlock(i + 2, j + 0, k + 12, Block.grass.blockID);
		world.setBlock(i + 2, j + 0, k + 13, Block.grass.blockID);
		world.setBlock(i + 2, j + 0, k + 14, Block.grass.blockID);
		world.setBlock(i + 2, j + 0, k + 15, Block.grass.blockID);
		world.setBlock(i + 2, j + 0, k + 16, Block.grass.blockID);
		world.setBlock(i + 2, j + 0, k + 17, Block.grass.blockID);
		world.setBlock(i + 2, j + 0, k + 18, Block.grass.blockID);
		world.setBlock(i + 2, j + 0, k + 19, Block.grass.blockID);
		world.setBlock(i + 2, j + 0, k + 20, Block.grass.blockID);
		world.setBlock(i + 2, j + 0, k + 21, Block.grass.blockID);
		world.setBlock(i + 2, j + 0, k + 22, Block.grass.blockID);
		world.setBlock(i + 2, j + 0, k + 23, Block.grass.blockID);
		world.setBlock(i + 2, j + 0, k + 24, Block.grass.blockID);
		world.setBlock(i + 2, j + 0, k + 25, Block.grass.blockID);
		world.setBlock(i + 3, j + 0, k + 0, Block.grass.blockID);
		world.setBlock(i + 3, j + 0, k + 1, Block.grass.blockID);
		world.setBlock(i + 3, j + 0, k + 2, Block.grass.blockID);
		world.setBlock(i + 3, j + 0, k + 3, Block.grass.blockID);
		world.setBlock(i + 3, j + 0, k + 4, Block.grass.blockID);
		world.setBlock(i + 3, j + 0, k + 5, Block.grass.blockID);
		world.setBlock(i + 3, j + 0, k + 6, Block.grass.blockID);
		world.setBlock(i + 3, j + 0, k + 7, Block.grass.blockID);
		world.setBlock(i + 3, j + 0, k + 8, Block.grass.blockID);
		world.setBlock(i + 3, j + 0, k + 9, Block.grass.blockID);
		world.setBlock(i + 3, j + 0, k + 10, Block.grass.blockID);
		world.setBlock(i + 3, j + 0, k + 11, Block.grass.blockID);
		world.setBlock(i + 3, j + 0, k + 12, Block.grass.blockID);
		world.setBlock(i + 3, j + 0, k + 13, Block.grass.blockID);
		world.setBlock(i + 3, j + 0, k + 14, Block.grass.blockID);
		world.setBlock(i + 3, j + 0, k + 15, Block.grass.blockID);
		world.setBlock(i + 3, j + 0, k + 16, Block.grass.blockID);
		world.setBlock(i + 3, j + 0, k + 17, Block.grass.blockID);
		world.setBlock(i + 3, j + 0, k + 18, Block.grass.blockID);
		world.setBlock(i + 3, j + 0, k + 19, Block.grass.blockID);
		world.setBlock(i + 3, j + 0, k + 20, Block.grass.blockID);
		world.setBlock(i + 3, j + 0, k + 21, Block.grass.blockID);
		world.setBlock(i + 3, j + 0, k + 22, Block.grass.blockID);
		world.setBlock(i + 3, j + 0, k + 23, Block.grass.blockID);
		world.setBlock(i + 3, j + 0, k + 24, Block.grass.blockID);
		world.setBlock(i + 3, j + 0, k + 25, Block.grass.blockID);
		world.setBlock(i + 3, j + 0, k + 26, Block.grass.blockID);
		world.setBlock(i + 4, j + 0, k + 0, Block.grass.blockID);
		world.setBlock(i + 4, j + 0, k + 1, Block.grass.blockID);
		world.setBlock(i + 4, j + 0, k + 2, Block.grass.blockID);
		world.setBlock(i + 4, j + 0, k + 3, Block.grass.blockID);
		world.setBlock(i + 4, j + 0, k + 4, Block.grass.blockID);
		world.setBlock(i + 4, j + 0, k + 5, Block.grass.blockID);
		world.setBlock(i + 4, j + 0, k + 6, Block.grass.blockID);
		world.setBlock(i + 4, j + 0, k + 7, Block.grass.blockID);
		world.setBlock(i + 4, j + 0, k + 8, Block.grass.blockID);
		world.setBlock(i + 4, j + 0, k + 9, Block.grass.blockID);
		world.setBlock(i + 4, j + 0, k + 10, Block.dirt.blockID);
		world.setBlock(i + 4, j + 0, k + 11, Block.dirt.blockID);
		world.setBlock(i + 4, j + 0, k + 12, Block.dirt.blockID);
		world.setBlock(i + 4, j + 0, k + 13, Block.dirt.blockID);
		world.setBlock(i + 4, j + 0, k + 14, Block.dirt.blockID);
		world.setBlock(i + 4, j + 0, k + 15, Block.dirt.blockID);
		world.setBlock(i + 4, j + 0, k + 16, Block.dirt.blockID);
		world.setBlock(i + 4, j + 0, k + 17, Block.dirt.blockID);
		world.setBlock(i + 4, j + 0, k + 18, Block.dirt.blockID);
		world.setBlock(i + 4, j + 0, k + 19, Block.dirt.blockID);
		world.setBlock(i + 4, j + 0, k + 20, Block.dirt.blockID);
		world.setBlock(i + 4, j + 0, k + 21, Block.dirt.blockID);
		world.setBlock(i + 4, j + 0, k + 22, Block.dirt.blockID);
		world.setBlock(i + 4, j + 0, k + 23, Block.dirt.blockID);
		world.setBlock(i + 4, j + 0, k + 24, Block.dirt.blockID);
		world.setBlock(i + 4, j + 0, k + 25, Block.dirt.blockID);
		world.setBlock(i + 4, j + 0, k + 26, Block.grass.blockID);
		world.setBlock(i + 4, j + 0, k + 27, Block.grass.blockID);
		world.setBlock(i + 4, j + 0, k + 28, Block.grass.blockID);
		world.setBlock(i + 4, j + 1, k + 10, Block.stoneBrick.blockID);
		world.setBlock(i + 4, j + 1, k + 11, Block.stoneBrick.blockID);
		world.setBlock(i + 4, j + 1, k + 12, Block.stoneBrick.blockID);
		world.setBlock(i + 4, j + 1, k + 13, Block.stoneBrick.blockID);
		world.setBlock(i + 4, j + 1, k + 14, Block.stoneBrick.blockID);
		world.setBlock(i + 4, j + 1, k + 15, Block.stoneBrick.blockID);
		world.setBlock(i + 4, j + 1, k + 16, Block.stoneBrick.blockID);
		world.setBlock(i + 4, j + 1, k + 17, Block.stoneBrick.blockID);
		world.setBlock(i + 4, j + 1, k + 18, Block.stoneBrick.blockID);
		world.setBlock(i + 4, j + 1, k + 19, Block.stoneBrick.blockID);
		world.setBlock(i + 4, j + 1, k + 20, Block.stoneBrick.blockID);
		world.setBlock(i + 4, j + 1, k + 21, Block.stoneBrick.blockID);
		world.setBlock(i + 4, j + 1, k + 22, Block.stoneBrick.blockID);
		world.setBlock(i + 4, j + 1, k + 23, Block.stoneBrick.blockID);
		world.setBlock(i + 4, j + 1, k + 24, Block.stoneBrick.blockID);
		world.setBlock(i + 4, j + 1, k + 25, Block.stoneBrick.blockID);
		world.setBlock(i + 4, j + 2, k + 10, Block.stoneBrick.blockID);
		world.setBlock(i + 4, j + 2, k + 11, Block.stoneBrick.blockID);
		world.setBlock(i + 4, j + 2, k + 12, Block.stoneBrick.blockID);
		world.setBlock(i + 4, j + 2, k + 13, Block.stoneBrick.blockID);
		world.setBlock(i + 4, j + 2, k + 14, Block.stoneBrick.blockID);
		world.setBlock(i + 4, j + 2, k + 15, Block.stoneBrick.blockID);
		world.setBlock(i + 4, j + 2, k + 16, Block.stoneBrick.blockID);
		world.setBlock(i + 4, j + 2, k + 17, Block.stoneBrick.blockID);
		world.setBlock(i + 4, j + 2, k + 18, Block.stoneBrick.blockID);
		world.setBlock(i + 4, j + 2, k + 19, Block.stoneBrick.blockID);
		world.setBlock(i + 4, j + 2, k + 20, Block.stoneBrick.blockID);
		world.setBlock(i + 4, j + 2, k + 21, Block.stoneBrick.blockID);
		world.setBlock(i + 4, j + 2, k + 22, Block.stoneBrick.blockID);
		world.setBlock(i + 4, j + 2, k + 23, Block.stoneBrick.blockID);
		world.setBlock(i + 4, j + 2, k + 24, Block.stoneBrick.blockID);
		world.setBlock(i + 4, j + 2, k + 25, Block.stoneBrick.blockID);
		world.setBlock(i + 4, j + 3, k + 0, Block.leaves.blockID);
		world.setBlock(i + 4, j + 3, k + 1, Block.leaves.blockID);
		world.setBlock(i + 4, j + 3, k + 10, Block.stoneBrick.blockID);
		world.setBlock(i + 4, j + 3, k + 11, Block.stoneBrick.blockID);
		world.setBlock(i + 4, j + 3, k + 12, Block.stoneBrick.blockID);
		world.setBlock(i + 4, j + 3, k + 13, Block.stoneBrick.blockID);
		world.setBlock(i + 4, j + 3, k + 14, Block.stoneBrick.blockID);
		world.setBlock(i + 4, j + 3, k + 15, Block.stoneBrick.blockID);
		world.setBlock(i + 4, j + 3, k + 16, Block.stoneBrick.blockID);
		world.setBlock(i + 4, j + 3, k + 17, Block.stoneBrick.blockID);
		world.setBlock(i + 4, j + 3, k + 18, Block.stoneBrick.blockID);
		world.setBlock(i + 4, j + 3, k + 19, Block.stoneBrick.blockID);
		world.setBlock(i + 4, j + 3, k + 20, Block.stoneBrick.blockID);
		world.setBlock(i + 4, j + 3, k + 21, Block.stoneBrick.blockID);
		world.setBlock(i + 4, j + 3, k + 22, Block.stoneBrick.blockID);
		world.setBlock(i + 4, j + 3, k + 23, Block.stoneBrick.blockID);
		world.setBlock(i + 4, j + 3, k + 24, Block.stoneBrick.blockID);
		world.setBlock(i + 4, j + 3, k + 25, Block.stoneBrick.blockID);
		world.setBlock(i + 4, j + 4, k + 0, Block.leaves.blockID);
		world.setBlock(i + 4, j + 4, k + 10, Block.stoneBrick.blockID);
		world.setBlock(i + 4, j + 4, k + 11, Block.stoneBrick.blockID);
		world.setBlock(i + 4, j + 4, k + 12, Block.stoneBrick.blockID);
		world.setBlock(i + 4, j + 4, k + 13, Block.stoneBrick.blockID);
		world.setBlock(i + 4, j + 4, k + 14, Block.stoneBrick.blockID);
		world.setBlock(i + 4, j + 4, k + 15, Block.stoneBrick.blockID);
		world.setBlock(i + 4, j + 4, k + 16, Block.stoneBrick.blockID);
		world.setBlock(i + 4, j + 4, k + 17, Block.stoneBrick.blockID);
		world.setBlock(i + 4, j + 4, k + 18, Block.stoneBrick.blockID);
		world.setBlock(i + 4, j + 4, k + 19, Block.stoneBrick.blockID);
		world.setBlock(i + 4, j + 4, k + 20, Block.stoneBrick.blockID);
		world.setBlock(i + 4, j + 4, k + 21, Block.stoneBrick.blockID);
		world.setBlock(i + 4, j + 4, k + 22, Block.stoneBrick.blockID);
		world.setBlock(i + 4, j + 4, k + 23, Block.stoneBrick.blockID);
		world.setBlock(i + 4, j + 4, k + 24, Block.stoneBrick.blockID);
		world.setBlock(i + 4, j + 4, k + 25, Block.stoneBrick.blockID);
		world.setBlock(i + 4, j + 5, k + 10, Block.stairsStoneBrick.blockID, 3, k);
		world.setBlock(i + 4, j + 5, k + 11, Block.stairsStoneBrick.blockID, 3, k);
		world.setBlock(i + 4, j + 5, k + 12, Block.stairsStoneBrick.blockID, 3, k);
		world.setBlock(i + 4, j + 5, k + 13, Block.stairsStoneBrick.blockID, 3, k);
		world.setBlock(i + 4, j + 5, k + 14, Block.stairsStoneBrick.blockID, 3, k);
		world.setBlock(i + 4, j + 5, k + 15, Block.stairsStoneBrick.blockID, 3, k);
		world.setBlock(i + 4, j + 5, k + 16, Block.stairsStoneBrick.blockID, 3, k);
		world.setBlock(i + 4, j + 5, k + 17, Block.stairsStoneBrick.blockID, 3, k);
		world.setBlock(i + 4, j + 5, k + 18, Block.stairsStoneBrick.blockID, 3, k);
		world.setBlock(i + 4, j + 5, k + 19, Block.stairsStoneBrick.blockID, 3, k);
		world.setBlock(i + 4, j + 5, k + 20, Block.stairsStoneBrick.blockID, 3, k);
		world.setBlock(i + 4, j + 5, k + 21, Block.stairsStoneBrick.blockID, 3, k);
		world.setBlock(i + 4, j + 5, k + 22, Block.stairsStoneBrick.blockID, 3, k);
		world.setBlock(i + 4, j + 5, k + 23, Block.stairsStoneBrick.blockID, 3, k);
		world.setBlock(i + 4, j + 5, k + 24, Block.stairsStoneBrick.blockID, 3, k);
		world.setBlock(i + 4, j + 5, k + 25, Block.stairsStoneBrick.blockID, 3, k);
		world.setBlock(i + 5, j + 0, k + 0, Block.grass.blockID);
		world.setBlock(i + 5, j + 0, k + 1, Block.grass.blockID);
		world.setBlock(i + 5, j + 0, k + 2, Block.grass.blockID);
		world.setBlock(i + 5, j + 0, k + 3, Block.grass.blockID);
		world.setBlock(i + 5, j + 0, k + 4, Block.grass.blockID);
		world.setBlock(i + 5, j + 0, k + 5, Block.grass.blockID);
		world.setBlock(i + 5, j + 0, k + 6, Block.grass.blockID);
		world.setBlock(i + 5, j + 0, k + 7, Block.grass.blockID);
		world.setBlock(i + 5, j + 0, k + 8, Block.grass.blockID);
		world.setBlock(i + 5, j + 0, k + 9, Block.dirt.blockID);
		world.setBlock(i + 5, j + 0, k + 10, Block.grass.blockID);
		world.setBlock(i + 5, j + 0, k + 11, Block.grass.blockID);
		world.setBlock(i + 5, j + 0, k + 12, Block.grass.blockID);
		world.setBlock(i + 5, j + 0, k + 13, Block.grass.blockID);
		world.setBlock(i + 5, j + 0, k + 14, Block.grass.blockID);
		world.setBlock(i + 5, j + 0, k + 15, Block.grass.blockID);
		world.setBlock(i + 5, j + 0, k + 16, Block.grass.blockID);
		world.setBlock(i + 5, j + 0, k + 17, Block.grass.blockID);
		world.setBlock(i + 5, j + 0, k + 18, Block.grass.blockID);
		world.setBlock(i + 5, j + 0, k + 19, Block.grass.blockID);
		world.setBlock(i + 5, j + 0, k + 20, Block.grass.blockID);
		world.setBlock(i + 5, j + 0, k + 21, Block.grass.blockID);
		world.setBlock(i + 5, j + 0, k + 22, Block.grass.blockID);
		world.setBlock(i + 5, j + 0, k + 23, Block.grass.blockID);
		world.setBlock(i + 5, j + 0, k + 24, Block.grass.blockID);
		world.setBlock(i + 5, j + 0, k + 25, Block.grass.blockID);
		world.setBlock(i + 5, j + 0, k + 26, Block.dirt.blockID);
		world.setBlock(i + 5, j + 0, k + 27, Block.grass.blockID);
		world.setBlock(i + 5, j + 0, k + 28, Block.grass.blockID);
		world.setBlock(i + 5, j + 0, k + 29, Block.grass.blockID);
		world.setBlock(i + 5, j + 0, k + 30, Block.grass.blockID);
		world.setBlock(i + 5, j + 0, k + 31, Block.grass.blockID);
		world.setBlock(i + 5, j + 0, k + 32, Block.grass.blockID);
		world.setBlock(i + 5, j + 0, k + 33, Block.grass.blockID);
		world.setBlock(i + 5, j + 0, k + 34, Block.grass.blockID);
		world.setBlock(i + 5, j + 0, k + 35, Block.grass.blockID);
		world.setBlock(i + 5, j + 0, k + 36, Block.grass.blockID);
		world.setBlock(i + 5, j + 0, k + 37, Block.grass.blockID);
		world.setBlock(i + 5, j + 0, k + 38, Block.grass.blockID);
		world.setBlock(i + 5, j + 0, k + 39, Block.grass.blockID);
		world.setBlock(i + 5, j + 0, k + 40, Block.grass.blockID);
		world.setBlock(i + 5, j + 0, k + 41, Block.grass.blockID);
		world.setBlock(i + 5, j + 0, k + 42, Block.grass.blockID);
		world.setBlock(i + 5, j + 0, k + 43, Block.grass.blockID);
		world.setBlock(i + 5, j + 0, k + 44, Block.grass.blockID);
		world.setBlock(i + 5, j + 0, k + 45, Block.grass.blockID);
		world.setBlock(i + 5, j + 1, k + 9, Block.stoneBrick.blockID);
		world.setBlock(i + 5, j + 1, k + 26, Block.stoneBrick.blockID);
		world.setBlock(i + 5, j + 2, k + 9, Block.stoneBrick.blockID);
		world.setBlock(i + 5, j + 2, k + 26, Block.stoneBrick.blockID);
		world.setBlock(i + 5, j + 3, k + 0, Block.leaves.blockID);
		world.setBlock(i + 5, j + 3, k + 1, Block.leaves.blockID);
		world.setBlock(i + 5, j + 3, k + 9, Block.stoneBrick.blockID);
		world.setBlock(i + 5, j + 3, k + 26, Block.stoneBrick.blockID);
		world.setBlock(i + 5, j + 4, k + 0, Block.leaves.blockID);
		world.setBlock(i + 5, j + 4, k + 1, Block.leaves.blockID);
		world.setBlock(i + 5, j + 4, k + 9, Block.stoneBrick.blockID);
		world.setBlock(i + 5, j + 4, k + 26, Block.stoneBrick.blockID);
		world.setBlock(i + 5, j + 5, k + 0, Block.leaves.blockID);
		world.setBlock(i + 5, j + 5, k + 9, Block.stairsStoneBrick.blockID, 3, k);
		world.setBlock(i + 5, j + 5, k + 26, Block.stairsStoneBrick.blockID, 3, k);
		world.setBlock(i + 6, j + 0, k + 0, Block.grass.blockID);
		world.setBlock(i + 6, j + 0, k + 1, Block.grass.blockID);
		world.setBlock(i + 6, j + 0, k + 2, Block.grass.blockID);
		world.setBlock(i + 6, j + 0, k + 3, Block.grass.blockID);
		world.setBlock(i + 6, j + 0, k + 4, Block.grass.blockID);
		world.setBlock(i + 6, j + 0, k + 5, Block.grass.blockID);
		world.setBlock(i + 6, j + 0, k + 6, Block.grass.blockID);
		world.setBlock(i + 6, j + 0, k + 7, Block.grass.blockID);
		world.setBlock(i + 6, j + 0, k + 8, Block.dirt.blockID);
		world.setBlock(i + 6, j + 0, k + 9, Block.grass.blockID);
		world.setBlock(i + 6, j + 0, k + 10, Block.grass.blockID);
		world.setBlock(i + 6, j + 0, k + 11, Block.grass.blockID);
		world.setBlock(i + 6, j + 0, k + 12, Block.grass.blockID);
		world.setBlock(i + 6, j + 0, k + 13, Block.grass.blockID);
		world.setBlock(i + 6, j + 0, k + 14, Block.grass.blockID);
		world.setBlock(i + 6, j + 0, k + 15, Block.grass.blockID);
		world.setBlock(i + 6, j + 0, k + 16, Block.grass.blockID);
		world.setBlock(i + 6, j + 0, k + 17, Block.grass.blockID);
		world.setBlock(i + 6, j + 0, k + 18, Block.grass.blockID);
		world.setBlock(i + 6, j + 0, k + 19, Block.grass.blockID);
		world.setBlock(i + 6, j + 0, k + 20, Block.grass.blockID);
		world.setBlock(i + 6, j + 0, k + 21, Block.grass.blockID);
		world.setBlock(i + 6, j + 0, k + 22, Block.grass.blockID);
		world.setBlock(i + 6, j + 0, k + 23, Block.grass.blockID);
		world.setBlock(i + 6, j + 0, k + 24, Block.grass.blockID);
		world.setBlock(i + 6, j + 0, k + 25, Block.grass.blockID);
		world.setBlock(i + 6, j + 0, k + 26, Block.grass.blockID);
		world.setBlock(i + 6, j + 0, k + 27, Block.dirt.blockID);
		world.setBlock(i + 6, j + 0, k + 28, Block.dirt.blockID);
		world.setBlock(i + 6, j + 0, k + 29, Block.dirt.blockID);
		world.setBlock(i + 6, j + 0, k + 30, Block.dirt.blockID);
		world.setBlock(i + 6, j + 0, k + 31, Block.dirt.blockID);
		world.setBlock(i + 6, j + 0, k + 32, Block.dirt.blockID);
		world.setBlock(i + 6, j + 0, k + 33, Block.dirt.blockID);
		world.setBlock(i + 6, j + 0, k + 34, Block.dirt.blockID);
		world.setBlock(i + 6, j + 0, k + 35, Block.dirt.blockID);
		world.setBlock(i + 6, j + 0, k + 36, Block.dirt.blockID);
		world.setBlock(i + 6, j + 0, k + 37, Block.dirt.blockID);
		world.setBlock(i + 6, j + 0, k + 38, Block.dirt.blockID);
		world.setBlock(i + 6, j + 0, k + 39, Block.dirt.blockID);
		world.setBlock(i + 6, j + 0, k + 40, Block.dirt.blockID);
		world.setBlock(i + 6, j + 0, k + 41, Block.dirt.blockID);
		world.setBlock(i + 6, j + 0, k + 42, Block.grass.blockID);
		world.setBlock(i + 6, j + 0, k + 43, Block.grass.blockID);
		world.setBlock(i + 6, j + 0, k + 44, Block.grass.blockID);
		world.setBlock(i + 6, j + 0, k + 45, Block.grass.blockID);
		world.setBlock(i + 6, j + 0, k + 46, Block.grass.blockID);
		world.setBlock(i + 6, j + 0, k + 47, Block.grass.blockID);
		world.setBlock(i + 6, j + 0, k + 48, Block.grass.blockID);
		world.setBlock(i + 6, j + 1, k + 8, Block.stoneBrick.blockID);
		world.setBlock(i + 6, j + 1, k + 27, Block.stoneBrick.blockID);
		world.setBlock(i + 6, j + 1, k + 28, Block.stoneBrick.blockID);
		world.setBlock(i + 6, j + 1, k + 29, Block.stoneBrick.blockID);
		world.setBlock(i + 6, j + 1, k + 30, Block.stoneBrick.blockID);
		world.setBlock(i + 6, j + 1, k + 31, Block.stoneBrick.blockID);
		world.setBlock(i + 6, j + 1, k + 32, Block.stoneBrick.blockID);
		world.setBlock(i + 6, j + 1, k + 33, Block.stoneBrick.blockID);
		world.setBlock(i + 6, j + 1, k + 34, Block.stoneBrick.blockID);
		world.setBlock(i + 6, j + 1, k + 35, Block.stoneBrick.blockID);
		world.setBlock(i + 6, j + 1, k + 36, Block.stoneBrick.blockID);
		world.setBlock(i + 6, j + 1, k + 37, Block.stoneBrick.blockID);
		world.setBlock(i + 6, j + 1, k + 38, Block.stoneBrick.blockID);
		world.setBlock(i + 6, j + 1, k + 39, Block.stoneBrick.blockID);
		world.setBlock(i + 6, j + 1, k + 40, Block.stoneBrick.blockID);
		world.setBlock(i + 6, j + 1, k + 41, Block.stoneBrick.blockID);
		world.setBlock(i + 6, j + 2, k + 8, Block.stoneBrick.blockID);
		world.setBlock(i + 6, j + 2, k + 27, Block.stoneBrick.blockID);
		world.setBlock(i + 6, j + 2, k + 28, Block.stoneBrick.blockID);
		world.setBlock(i + 6, j + 2, k + 29, Block.stoneBrick.blockID);
		world.setBlock(i + 6, j + 2, k + 30, Block.stoneBrick.blockID);
		world.setBlock(i + 6, j + 2, k + 31, Block.stoneBrick.blockID);
		world.setBlock(i + 6, j + 2, k + 32, Block.stoneBrick.blockID);
		world.setBlock(i + 6, j + 2, k + 33, Block.stoneBrick.blockID);
		world.setBlock(i + 6, j + 2, k + 34, Block.stoneBrick.blockID);
		world.setBlock(i + 6, j + 2, k + 35, Block.stoneBrick.blockID);
		world.setBlock(i + 6, j + 2, k + 36, Block.stoneBrick.blockID);
		world.setBlock(i + 6, j + 2, k + 37, Block.stoneBrick.blockID);
		world.setBlock(i + 6, j + 2, k + 38, Block.stoneBrick.blockID);
		world.setBlock(i + 6, j + 2, k + 39, Block.stoneBrick.blockID);
		world.setBlock(i + 6, j + 2, k + 40, Block.stoneBrick.blockID);
		world.setBlock(i + 6, j + 2, k + 41, Block.stoneBrick.blockID);
		world.setBlock(i + 6, j + 3, k + 0, Block.leaves.blockID);
		world.setBlock(i + 6, j + 3, k + 1, Block.leaves.blockID);
		world.setBlock(i + 6, j + 3, k + 8, Block.stoneBrick.blockID);
		world.setBlock(i + 6, j + 3, k + 27, Block.stoneBrick.blockID);
		world.setBlock(i + 6, j + 3, k + 28, Block.stoneBrick.blockID);
		world.setBlock(i + 6, j + 3, k + 29, Block.stoneBrick.blockID);
		world.setBlock(i + 6, j + 3, k + 30, Block.stoneBrick.blockID);
		world.setBlock(i + 6, j + 3, k + 31, Block.stoneBrick.blockID);
		world.setBlock(i + 6, j + 3, k + 32, Block.stoneBrick.blockID);
		world.setBlock(i + 6, j + 3, k + 33, Block.stoneBrick.blockID);
		world.setBlock(i + 6, j + 3, k + 34, Block.stoneBrick.blockID);
		world.setBlock(i + 6, j + 3, k + 35, Block.stoneBrick.blockID);
		world.setBlock(i + 6, j + 3, k + 36, Block.stoneBrick.blockID);
		world.setBlock(i + 6, j + 3, k + 37, Block.stoneBrick.blockID);
		world.setBlock(i + 6, j + 3, k + 38, Block.stoneBrick.blockID);
		world.setBlock(i + 6, j + 3, k + 39, Block.stoneBrick.blockID);
		world.setBlock(i + 6, j + 3, k + 40, Block.stoneBrick.blockID);
		world.setBlock(i + 6, j + 3, k + 41, Block.stoneBrick.blockID);
		world.setBlock(i + 6, j + 4, k + 0, Block.leaves.blockID);
		world.setBlock(i + 6, j + 4, k + 1, Block.leaves.blockID);
		world.setBlock(i + 6, j + 4, k + 8, Block.stoneBrick.blockID);
		world.setBlock(i + 6, j + 4, k + 27, Block.stoneBrick.blockID);
		world.setBlock(i + 6, j + 4, k + 28, Block.stoneBrick.blockID);
		world.setBlock(i + 6, j + 4, k + 29, Block.stoneBrick.blockID);
		world.setBlock(i + 6, j + 4, k + 30, Block.stoneBrick.blockID);
		world.setBlock(i + 6, j + 4, k + 31, Block.stoneBrick.blockID);
		world.setBlock(i + 6, j + 4, k + 32, Block.stoneBrick.blockID);
		world.setBlock(i + 6, j + 4, k + 33, Block.stoneBrick.blockID);
		world.setBlock(i + 6, j + 4, k + 34, Block.stoneBrick.blockID);
		world.setBlock(i + 6, j + 4, k + 35, Block.stoneBrick.blockID);
		world.setBlock(i + 6, j + 4, k + 36, Block.stoneBrick.blockID);
		world.setBlock(i + 6, j + 4, k + 37, Block.stoneBrick.blockID);
		world.setBlock(i + 6, j + 4, k + 38, Block.stoneBrick.blockID);
		world.setBlock(i + 6, j + 4, k + 39, Block.stoneBrick.blockID);
		world.setBlock(i + 6, j + 4, k + 40, Block.stoneBrick.blockID);
		world.setBlock(i + 6, j + 4, k + 41, Block.stoneBrick.blockID);
		world.setBlock(i + 6, j + 5, k + 0, Block.leaves.blockID);
		world.setBlock(i + 6, j + 5, k + 8, Block.stairsStoneBrick.blockID, 3, k);
		world.setBlock(i + 6, j + 5, k + 27, Block.stairsStoneBrick.blockID, 3, k);
		world.setBlock(i + 6, j + 5, k + 28, Block.stairsStoneBrick.blockID, 3, k);
		world.setBlock(i + 6, j + 5, k + 29, Block.stairsStoneBrick.blockID, 3, k);
		world.setBlock(i + 6, j + 5, k + 30, Block.stairsStoneBrick.blockID, 3, k);
		world.setBlock(i + 6, j + 5, k + 31, Block.stairsStoneBrick.blockID, 3, k);
		world.setBlock(i + 6, j + 5, k + 32, Block.stairsStoneBrick.blockID, 3, k);
		world.setBlock(i + 6, j + 5, k + 33, Block.stairsStoneBrick.blockID, 3, k);
		world.setBlock(i + 6, j + 5, k + 34, Block.stairsStoneBrick.blockID, 3, k);
		world.setBlock(i + 6, j + 5, k + 35, Block.stairsStoneBrick.blockID, 3, k);
		world.setBlock(i + 6, j + 5, k + 36, Block.stairsStoneBrick.blockID, 3, k);
		world.setBlock(i + 6, j + 5, k + 37, Block.stairsStoneBrick.blockID, 3, k);
		world.setBlock(i + 6, j + 5, k + 38, Block.stairsStoneBrick.blockID, 3, k);
		world.setBlock(i + 6, j + 5, k + 39, Block.stairsStoneBrick.blockID, 3, k);
		world.setBlock(i + 6, j + 5, k + 40, Block.stairsStoneBrick.blockID, 3, k);
		world.setBlock(i + 6, j + 5, k + 41, Block.stairsStoneBrick.blockID, 3, k);
		world.setBlock(i + 6, j + 6, k + 0, Block.leaves.blockID);
		world.setBlock(i + 7, j + 0, k + 0, Block.grass.blockID);
		world.setBlock(i + 7, j + 0, k + 1, Block.grass.blockID);
		world.setBlock(i + 7, j + 0, k + 2, Block.grass.blockID);
		world.setBlock(i + 7, j + 0, k + 3, Block.grass.blockID);
		world.setBlock(i + 7, j + 0, k + 4, Block.grass.blockID);
		world.setBlock(i + 7, j + 0, k + 5, Block.grass.blockID);
		world.setBlock(i + 7, j + 0, k + 6, Block.grass.blockID);
		world.setBlock(i + 7, j + 0, k + 7, Block.dirt.blockID);
		world.setBlock(i + 7, j + 0, k + 8, Block.grass.blockID);
		world.setBlock(i + 7, j + 0, k + 9, Block.grass.blockID);
		world.setBlock(i + 7, j + 0, k + 10, Block.grass.blockID);
		world.setBlock(i + 7, j + 0, k + 11, Block.grass.blockID);
		world.setBlock(i + 7, j + 0, k + 12, Block.dirt.blockID);
		world.setBlock(i + 7, j + 0, k + 13, Block.dirt.blockID);
		world.setBlock(i + 7, j + 0, k + 14, Block.dirt.blockID);
		world.setBlock(i + 7, j + 0, k + 15, Block.dirt.blockID);
		world.setBlock(i + 7, j + 0, k + 16, Block.dirt.blockID);
		world.setBlock(i + 7, j + 0, k + 17, Block.dirt.blockID);
		world.setBlock(i + 7, j + 0, k + 18, Block.grass.blockID);
		world.setBlock(i + 7, j + 0, k + 19, Block.grass.blockID);
		world.setBlock(i + 7, j + 0, k + 20, Block.grass.blockID);
		world.setBlock(i + 7, j + 0, k + 21, Block.grass.blockID);
		world.setBlock(i + 7, j + 0, k + 22, Block.grass.blockID);
		world.setBlock(i + 7, j + 0, k + 23, Block.grass.blockID);
		world.setBlock(i + 7, j + 0, k + 24, Block.grass.blockID);
		world.setBlock(i + 7, j + 0, k + 25, Block.grass.blockID);
		world.setBlock(i + 7, j + 0, k + 26, Block.grass.blockID);
		world.setBlock(i + 7, j + 0, k + 27, Block.grass.blockID);
		world.setBlock(i + 7, j + 0, k + 28, Block.grass.blockID);
		world.setBlock(i + 7, j + 0, k + 29, Block.grass.blockID);
		world.setBlock(i + 7, j + 0, k + 30, Block.grass.blockID);
		world.setBlock(i + 7, j + 0, k + 31, Block.grass.blockID);
		world.setBlock(i + 7, j + 0, k + 32, Block.grass.blockID);
		world.setBlock(i + 7, j + 0, k + 33, Block.grass.blockID);
		world.setBlock(i + 7, j + 0, k + 34, Block.grass.blockID);
		world.setBlock(i + 7, j + 0, k + 35, Block.grass.blockID);
		world.setBlock(i + 7, j + 0, k + 36, Block.grass.blockID);
		world.setBlock(i + 7, j + 0, k + 37, Block.grass.blockID);
		world.setBlock(i + 7, j + 0, k + 38, Block.grass.blockID);
		world.setBlock(i + 7, j + 0, k + 39, Block.grass.blockID);
		world.setBlock(i + 7, j + 0, k + 40, Block.grass.blockID);
		world.setBlock(i + 7, j + 0, k + 41, Block.grass.blockID);
		world.setBlock(i + 7, j + 0, k + 42, Block.dirt.blockID);
		world.setBlock(i + 7, j + 0, k + 43, Block.grass.blockID);
		world.setBlock(i + 7, j + 0, k + 44, Block.grass.blockID);
		world.setBlock(i + 7, j + 0, k + 45, Block.grass.blockID);
		world.setBlock(i + 7, j + 0, k + 46, Block.grass.blockID);
		world.setBlock(i + 7, j + 0, k + 47, Block.grass.blockID);
		world.setBlock(i + 7, j + 0, k + 48, Block.grass.blockID);
		world.setBlock(i + 7, j + 1, k + 7, Block.stoneBrick.blockID);
		world.setBlock(i + 7, j + 1, k + 12, Block.grass.blockID);
		world.setBlock(i + 7, j + 1, k + 13, Block.grass.blockID);
		world.setBlock(i + 7, j + 1, k + 14, Block.grass.blockID);
		world.setBlock(i + 7, j + 1, k + 15, Block.grass.blockID);
		world.setBlock(i + 7, j + 1, k + 16, Block.grass.blockID);
		world.setBlock(i + 7, j + 1, k + 17, Block.grass.blockID);
		world.setBlock(i + 7, j + 1, k + 42, Block.stoneBrick.blockID);
		world.setBlock(i + 7, j + 2, k + 7, Block.stoneBrick.blockID);
		world.setBlock(i + 7, j + 2, k + 42, Block.stoneBrick.blockID);
		world.setBlock(i + 7, j + 3, k + 0, Block.leaves.blockID);
		world.setBlock(i + 7, j + 3, k + 1, Block.leaves.blockID);
		world.setBlock(i + 7, j + 3, k + 7, Block.stoneBrick.blockID);
		world.setBlock(i + 7, j + 3, k + 42, Block.stoneBrick.blockID);
		world.setBlock(i + 7, j + 4, k + 0, Block.leaves.blockID);
		world.setBlock(i + 7, j + 4, k + 1, Block.leaves.blockID);
		world.setBlock(i + 7, j + 4, k + 7, Block.stoneBrick.blockID);
		world.setBlock(i + 7, j + 4, k + 42, Block.stoneBrick.blockID);
		world.setBlock(i + 7, j + 5, k + 7, Block.stairsStoneBrick.blockID);
		world.setBlock(i + 7, j + 5, k + 42, Block.stairsStoneBrick.blockID, 1, k);
		world.setBlock(i + 8, j + 0, k + 0, Block.grass.blockID);
		world.setBlock(i + 8, j + 0, k + 1, Block.grass.blockID);
		world.setBlock(i + 8, j + 0, k + 2, Block.grass.blockID);
		world.setBlock(i + 8, j + 0, k + 3, Block.grass.blockID);
		world.setBlock(i + 8, j + 0, k + 4, Block.grass.blockID);
		world.setBlock(i + 8, j + 0, k + 5, Block.grass.blockID);
		world.setBlock(i + 8, j + 0, k + 6, Block.grass.blockID);
		world.setBlock(i + 8, j + 0, k + 7, Block.dirt.blockID);
		world.setBlock(i + 8, j + 0, k + 8, Block.grass.blockID);
		world.setBlock(i + 8, j + 0, k + 9, Block.grass.blockID);
		world.setBlock(i + 8, j + 0, k + 10, Block.grass.blockID);
		world.setBlock(i + 8, j + 0, k + 11, Block.grass.blockID);
		world.setBlock(i + 8, j + 0, k + 12, Block.dirt.blockID);
		world.setBlock(i + 8, j + 0, k + 13, Block.grass.blockID);
		world.setBlock(i + 8, j + 0, k + 14, Block.grass.blockID);
		world.setBlock(i + 8, j + 0, k + 15, Block.grass.blockID);
		world.setBlock(i + 8, j + 0, k + 16, Block.grass.blockID);
		world.setBlock(i + 8, j + 0, k + 17, Block.dirt.blockID);
		world.setBlock(i + 8, j + 0, k + 18, Block.dirt.blockID);
		world.setBlock(i + 8, j + 0, k + 19, Block.grass.blockID);
		world.setBlock(i + 8, j + 0, k + 20, Block.grass.blockID);
		world.setBlock(i + 8, j + 0, k + 21, Block.grass.blockID);
		world.setBlock(i + 8, j + 0, k + 22, Block.grass.blockID);
		world.setBlock(i + 8, j + 0, k + 23, Block.grass.blockID);
		world.setBlock(i + 8, j + 0, k + 24, Block.grass.blockID);
		world.setBlock(i + 8, j + 0, k + 25, Block.grass.blockID);
		world.setBlock(i + 8, j + 0, k + 26, Block.grass.blockID);
		world.setBlock(i + 8, j + 0, k + 27, Block.grass.blockID);
		world.setBlock(i + 8, j + 0, k + 28, Block.grass.blockID);
		world.setBlock(i + 8, j + 0, k + 29, Block.grass.blockID);
		world.setBlock(i + 8, j + 0, k + 30, Block.grass.blockID);
		world.setBlock(i + 8, j + 0, k + 31, Block.grass.blockID);
		world.setBlock(i + 8, j + 0, k + 32, Block.grass.blockID);
		world.setBlock(i + 8, j + 0, k + 33, Block.grass.blockID);
		world.setBlock(i + 8, j + 0, k + 34, Block.grass.blockID);
		world.setBlock(i + 8, j + 0, k + 35, Block.grass.blockID);
		world.setBlock(i + 8, j + 0, k + 36, Block.grass.blockID);
		world.setBlock(i + 8, j + 0, k + 37, Block.grass.blockID);
		world.setBlock(i + 8, j + 0, k + 38, Block.grass.blockID);
		world.setBlock(i + 8, j + 0, k + 39, Block.grass.blockID);
		world.setBlock(i + 8, j + 0, k + 40, Block.grass.blockID);
		world.setBlock(i + 8, j + 0, k + 41, Block.grass.blockID);
		world.setBlock(i + 8, j + 0, k + 42, Block.grass.blockID);
		world.setBlock(i + 8, j + 0, k + 43, Block.dirt.blockID);
		world.setBlock(i + 8, j + 0, k + 44, Block.grass.blockID);
		world.setBlock(i + 8, j + 0, k + 45, Block.grass.blockID);
		world.setBlock(i + 8, j + 0, k + 46, Block.grass.blockID);
		world.setBlock(i + 8, j + 0, k + 47, Block.grass.blockID);
		world.setBlock(i + 8, j + 0, k + 48, Block.grass.blockID);
		world.setBlock(i + 8, j + 1, k + 7, Block.stoneBrick.blockID);
		world.setBlock(i + 8, j + 1, k + 12, Block.grass.blockID);
		world.setBlock(i + 8, j + 1, k + 17, Block.grass.blockID);
		world.setBlock(i + 8, j + 1, k + 18, Block.grass.blockID);
		world.setBlock(i + 8, j + 1, k + 43, Block.stoneBrick.blockID);
		world.setBlock(i + 8, j + 2, k + 7, Block.stoneBrick.blockID);
		world.setBlock(i + 8, j + 2, k + 13, Block.stoneBrick.blockID);
		world.setBlock(i + 8, j + 2, k + 14, Block.stoneBrick.blockID);
		world.setBlock(i + 8, j + 2, k + 15, Block.stoneBrick.blockID);
		world.setBlock(i + 8, j + 2, k + 16, Block.stoneBrick.blockID);
		world.setBlock(i + 8, j + 2, k + 43, Block.stoneBrick.blockID);
		world.setBlock(i + 8, j + 3, k + 0, Block.leaves.blockID);
		world.setBlock(i + 8, j + 3, k + 7, Block.stoneBrick.blockID);
		world.setBlock(i + 8, j + 3, k + 13, Block.stoneBrick.blockID);
		world.setBlock(i + 8, j + 3, k + 14, Block.stoneBrick.blockID);
		world.setBlock(i + 8, j + 3, k + 15, Block.stoneBrick.blockID);
		world.setBlock(i + 8, j + 3, k + 16, Block.stoneBrick.blockID);
		world.setBlock(i + 8, j + 3, k + 43, Block.stoneBrick.blockID);
		world.setBlock(i + 8, j + 4, k + 0, Block.leaves.blockID);
		world.setBlock(i + 8, j + 4, k + 7, Block.stoneBrick.blockID);
		world.setBlock(i + 8, j + 4, k + 13, Block.stoneBrick.blockID);
		world.setBlock(i + 8, j + 4, k + 14, Block.stoneBrick.blockID);
		world.setBlock(i + 8, j + 4, k + 15, Block.stoneBrick.blockID);
		world.setBlock(i + 8, j + 4, k + 16, Block.stoneBrick.blockID);
		world.setBlock(i + 8, j + 4, k + 43, Block.stoneBrick.blockID);
		world.setBlock(i + 8, j + 5, k + 7, Block.stairsStoneBrick.blockID);
		world.setBlock(i + 8, j + 5, k + 13, Block.stoneBrick.blockID);
		world.setBlock(i + 8, j + 5, k + 14, Block.stoneBrick.blockID);
		world.setBlock(i + 8, j + 5, k + 15, Block.stoneBrick.blockID);
		world.setBlock(i + 8, j + 5, k + 16, Block.stoneBrick.blockID);
		world.setBlock(i + 8, j + 5, k + 43, Block.stairsStoneBrick.blockID, 1, k);
		world.setBlock(i + 8, j + 6, k + 13, Block.stoneBrick.blockID);
		world.setBlock(i + 8, j + 6, k + 14, Block.stoneBrick.blockID);
		world.setBlock(i + 8, j + 6, k + 15, Block.glass.blockID);
		world.setBlock(i + 8, j + 6, k + 16, Block.stoneBrick.blockID);
		world.setBlock(i + 8, j + 7, k + 13, Block.stoneBrick.blockID);
		world.setBlock(i + 8, j + 7, k + 14, Block.stoneBrick.blockID);
		world.setBlock(i + 8, j + 7, k + 15, Block.stoneBrick.blockID);
		world.setBlock(i + 8, j + 7, k + 16, Block.stoneBrick.blockID);
		world.setBlock(i + 8, j + 8, k + 13, Block.stoneBrick.blockID);
		world.setBlock(i + 8, j + 8, k + 14, Block.stoneBrick.blockID);
		world.setBlock(i + 8, j + 8, k + 15, Block.stoneBrick.blockID);
		world.setBlock(i + 8, j + 8, k + 16, Block.stoneBrick.blockID);
		world.setBlock(i + 8, j + 9, k + 13, Block.stoneBrick.blockID);
		world.setBlock(i + 8, j + 9, k + 14, Block.stoneBrick.blockID);
		world.setBlock(i + 8, j + 9, k + 15, Block.stoneBrick.blockID);
		world.setBlock(i + 8, j + 9, k + 16, Block.stoneBrick.blockID);
		world.setBlock(i + 8, j + 10, k + 13, Block.stoneBrick.blockID);
		world.setBlock(i + 8, j + 10, k + 14, Block.stoneSingleSlab.blockID, 5, k);
		world.setBlock(i + 8, j + 10, k + 15, Block.stoneBrick.blockID);
		world.setBlock(i + 8, j + 10, k + 16, Block.stoneSingleSlab.blockID, 5, k);
		world.setBlock(i + 9, j + 0, k + 0, Block.grass.blockID);
		world.setBlock(i + 9, j + 0, k + 1, Block.grass.blockID);
		world.setBlock(i + 9, j + 0, k + 2, Block.grass.blockID);
		world.setBlock(i + 9, j + 0, k + 3, Block.grass.blockID);
		world.setBlock(i + 9, j + 0, k + 4, Block.grass.blockID);
		world.setBlock(i + 9, j + 0, k + 5, Block.grass.blockID);
		world.setBlock(i + 9, j + 0, k + 6, Block.grass.blockID);
		world.setBlock(i + 9, j + 0, k + 7, Block.dirt.blockID);
		world.setBlock(i + 9, j + 0, k + 8, Block.grass.blockID);
		world.setBlock(i + 9, j + 0, k + 9, Block.grass.blockID);
		world.setBlock(i + 9, j + 0, k + 10, Block.grass.blockID);
		world.setBlock(i + 9, j + 0, k + 11, Block.grass.blockID);
		world.setBlock(i + 9, j + 0, k + 12, Block.dirt.blockID);
		world.setBlock(i + 9, j + 0, k + 13, Block.grass.blockID);
		world.setBlock(i + 9, j + 0, k + 14, Block.grass.blockID);
		world.setBlock(i + 9, j + 0, k + 15, Block.grass.blockID);
		world.setBlock(i + 9, j + 0, k + 16, Block.grass.blockID);
		world.setBlock(i + 9, j + 0, k + 17, Block.grass.blockID);
		world.setBlock(i + 9, j + 0, k + 18, Block.dirt.blockID);
		world.setBlock(i + 9, j + 0, k + 19, Block.grass.blockID);
		world.setBlock(i + 9, j + 0, k + 20, Block.grass.blockID);
		world.setBlock(i + 9, j + 0, k + 21, Block.grass.blockID);
		world.setBlock(i + 9, j + 0, k + 22, Block.grass.blockID);
		world.setBlock(i + 9, j + 0, k + 23, Block.grass.blockID);
		world.setBlock(i + 9, j + 0, k + 24, Block.grass.blockID);
		world.setBlock(i + 9, j + 0, k + 25, Block.grass.blockID);
		world.setBlock(i + 9, j + 0, k + 26, Block.grass.blockID);
		world.setBlock(i + 9, j + 0, k + 27, Block.grass.blockID);
		world.setBlock(i + 9, j + 0, k + 28, Block.grass.blockID);
		world.setBlock(i + 9, j + 0, k + 29, Block.grass.blockID);
		world.setBlock(i + 9, j + 0, k + 30, Block.grass.blockID);
		world.setBlock(i + 9, j + 0, k + 31, Block.grass.blockID);
		world.setBlock(i + 9, j + 0, k + 32, Block.grass.blockID);
		world.setBlock(i + 9, j + 0, k + 33, Block.grass.blockID);
		world.setBlock(i + 9, j + 0, k + 34, Block.grass.blockID);
		world.setBlock(i + 9, j + 0, k + 35, Block.grass.blockID);
		world.setBlock(i + 9, j + 0, k + 36, Block.grass.blockID);
		world.setBlock(i + 9, j + 0, k + 37, Block.grass.blockID);
		world.setBlock(i + 9, j + 0, k + 38, Block.grass.blockID);
		world.setBlock(i + 9, j + 0, k + 39, Block.grass.blockID);
		world.setBlock(i + 9, j + 0, k + 40, Block.grass.blockID);
		world.setBlock(i + 9, j + 0, k + 41, Block.grass.blockID);
		world.setBlock(i + 9, j + 0, k + 42, Block.grass.blockID);
		world.setBlock(i + 9, j + 0, k + 43, Block.grass.blockID);
		world.setBlock(i + 9, j + 0, k + 44, Block.dirt.blockID);
		world.setBlock(i + 9, j + 0, k + 45, Block.grass.blockID);
		world.setBlock(i + 9, j + 0, k + 46, Block.grass.blockID);
		world.setBlock(i + 9, j + 0, k + 47, Block.grass.blockID);
		world.setBlock(i + 9, j + 0, k + 48, Block.grass.blockID);
		world.setBlock(i + 9, j + 1, k + 7, Block.stoneBrick.blockID);
		world.setBlock(i + 9, j + 1, k + 12, Block.grass.blockID);
		world.setBlock(i + 9, j + 1, k + 18, Block.grass.blockID);
		world.setBlock(i + 9, j + 1, k + 44, Block.stoneBrick.blockID);
		world.setBlock(i + 9, j + 2, k + 7, Block.stoneBrick.blockID);
		world.setBlock(i + 9, j + 2, k + 13, Block.stoneBrick.blockID);
		world.setBlock(i + 9, j + 2, k + 14, Block.cobblestone.blockID);
		world.setBlock(i + 9, j + 2, k + 15, Block.stoneBrick.blockID);
		world.setBlock(i + 9, j + 2, k + 16, Block.stoneBrick.blockID);
		world.setBlock(i + 9, j + 2, k + 17, Block.stoneBrick.blockID);
		world.setBlock(i + 9, j + 2, k + 44, Block.stoneBrick.blockID);
		world.setBlock(i + 9, j + 3, k + 7, Block.stoneBrick.blockID);
		world.setBlock(i + 9, j + 3, k + 13, Block.stoneBrick.blockID);
		world.setBlock(i + 9, j + 3, k + 15, Block.stoneDoubleSlab.blockID, 6, k);
		world.setBlock(i + 9, j + 3, k + 16, Block.stoneDoubleSlab.blockID, 6, k);
		world.setBlock(i + 9, j + 3, k + 17, Block.stoneBrick.blockID);
		world.setBlock(i + 9, j + 3, k + 44, Block.stoneBrick.blockID);
		world.setBlock(i + 9, j + 4, k + 7, Block.stoneBrick.blockID);
		world.setBlock(i + 9, j + 4, k + 13, Block.stoneBrick.blockID);
		world.setBlock(i + 9, j + 4, k + 14, Block.stoneDoubleSlab.blockID, 6, k);
		world.setBlock(i + 9, j + 4, k + 17, Block.stoneBrick.blockID);
		world.setBlock(i + 9, j + 4, k + 44, Block.stoneBrick.blockID);
		world.setBlock(i + 9, j + 5, k + 7, Block.stairsStoneBrick.blockID);
		world.setBlock(i + 9, j + 5, k + 13, Block.stoneBrick.blockID);
		world.setBlock(i + 9, j + 5, k + 17, Block.stoneBrick.blockID);
		world.setBlock(i + 9, j + 5, k + 44, Block.stairsStoneBrick.blockID, 1, k);
		world.setBlock(i + 9, j + 6, k + 13, Block.stoneBrick.blockID);
		world.setBlock(i + 9, j + 6, k + 16, Block.stoneDoubleSlab.blockID, 6, k);
		world.setBlock(i + 9, j + 6, k + 17, Block.stoneBrick.blockID);
		world.setBlock(i + 9, j + 7, k + 13, Block.stoneBrick.blockID);
		world.setBlock(i + 9, j + 7, k + 14, Block.stoneDoubleSlab.blockID, 6, k);
		world.setBlock(i + 9, j + 7, k + 15, Block.stoneDoubleSlab.blockID, 6, k);
		world.setBlock(i + 9, j + 7, k + 17, Block.stoneBrick.blockID);
		world.setBlock(i + 9, j + 8, k + 13, Block.stoneBrick.blockID);
		world.setBlock(i + 9, j + 8, k + 17, Block.stoneBrick.blockID);
		world.setBlock(i + 9, j + 9, k + 13, Block.stoneBrick.blockID);
		world.setBlock(i + 9, j + 9, k + 17, Block.stoneBrick.blockID);
		world.setBlock(i + 9, j + 10, k + 13, Block.stoneSingleSlab.blockID, 5, k);
		world.setBlock(i + 9, j + 10, k + 17, Block.stoneBrick.blockID);
		world.setBlock(i + 10, j + 0, k + 0, Block.grass.blockID);
		world.setBlock(i + 10, j + 0, k + 1, Block.grass.blockID);
		world.setBlock(i + 10, j + 0, k + 2, Block.grass.blockID);
		world.setBlock(i + 10, j + 0, k + 3, Block.grass.blockID);
		world.setBlock(i + 10, j + 0, k + 4, Block.grass.blockID);
		world.setBlock(i + 10, j + 0, k + 5, Block.grass.blockID);
		world.setBlock(i + 10, j + 0, k + 6, Block.grass.blockID);
		world.setBlock(i + 10, j + 0, k + 7, Block.dirt.blockID);
		world.setBlock(i + 10, j + 0, k + 8, Block.grass.blockID);
		world.setBlock(i + 10, j + 0, k + 9, Block.grass.blockID);
		world.setBlock(i + 10, j + 0, k + 10, Block.grass.blockID);
		world.setBlock(i + 10, j + 0, k + 11, Block.grass.blockID);
		world.setBlock(i + 10, j + 0, k + 12, Block.dirt.blockID);
		world.setBlock(i + 10, j + 0, k + 13, Block.grass.blockID);
		world.setBlock(i + 10, j + 0, k + 14, Block.grass.blockID);
		world.setBlock(i + 10, j + 0, k + 15, Block.grass.blockID);
		world.setBlock(i + 10, j + 0, k + 17, Block.grass.blockID);
		world.setBlock(i + 10, j + 0, k + 18, Block.dirt.blockID);
		world.setBlock(i + 10, j + 0, k + 19, Block.dirt.blockID);
		world.setBlock(i + 10, j + 0, k + 20, Block.dirt.blockID);
		world.setBlock(i + 10, j + 0, k + 21, Block.dirt.blockID);
		world.setBlock(i + 10, j + 0, k + 22, Block.dirt.blockID);
		world.setBlock(i + 10, j + 0, k + 23, Block.dirt.blockID);
		world.setBlock(i + 10, j + 0, k + 24, Block.dirt.blockID);
		world.setBlock(i + 10, j + 0, k + 25, Block.dirt.blockID);
		world.setBlock(i + 10, j + 0, k + 26, Block.dirt.blockID);
		world.setBlock(i + 10, j + 0, k + 27, Block.dirt.blockID);
		world.setBlock(i + 10, j + 0, k + 28, Block.dirt.blockID);
		world.setBlock(i + 10, j + 0, k + 29, Block.grass.blockID);
		world.setBlock(i + 10, j + 0, k + 30, Block.grass.blockID);
		world.setBlock(i + 10, j + 0, k + 31, Block.grass.blockID);
		world.setBlock(i + 10, j + 0, k + 32, Block.grass.blockID);
		world.setBlock(i + 10, j + 0, k + 33, Block.grass.blockID);
		world.setBlock(i + 10, j + 0, k + 34, Block.grass.blockID);
		world.setBlock(i + 10, j + 0, k + 35, Block.grass.blockID);
		world.setBlock(i + 10, j + 0, k + 36, Block.stone.blockID);
		world.setBlock(i + 10, j + 0, k + 37, Block.stone.blockID);
		world.setBlock(i + 10, j + 0, k + 38, Block.stone.blockID);
		world.setBlock(i + 10, j + 0, k + 39, Block.stone.blockID);
		world.setBlock(i + 10, j + 0, k + 40, Block.stone.blockID);
		world.setBlock(i + 10, j + 0, k + 41, Block.stone.blockID);
		world.setBlock(i + 10, j + 0, k + 42, Block.grass.blockID);
		world.setBlock(i + 10, j + 0, k + 43, Block.grass.blockID);
		world.setBlock(i + 10, j + 0, k + 44, Block.dirt.blockID);
		world.setBlock(i + 10, j + 0, k + 45, Block.grass.blockID);
		world.setBlock(i + 10, j + 0, k + 46, Block.grass.blockID);
		world.setBlock(i + 10, j + 0, k + 47, Block.grass.blockID);
		world.setBlock(i + 10, j + 0, k + 48, Block.grass.blockID);
		world.setBlock(i + 10, j + 1, k + 7, Block.stoneBrick.blockID);
		world.setBlock(i + 10, j + 1, k + 12, Block.grass.blockID);
		world.setBlock(i + 10, j + 1, k + 18, Block.dirt.blockID);
		world.setBlock(i + 10, j + 1, k + 19, Block.dirt.blockID);
		world.setBlock(i + 10, j + 1, k + 20, Block.grass.blockID);
		world.setBlock(i + 10, j + 1, k + 21, Block.grass.blockID);
		world.setBlock(i + 10, j + 1, k + 22, Block.grass.blockID);
		world.setBlock(i + 10, j + 1, k + 23, Block.grass.blockID);
		world.setBlock(i + 10, j + 1, k + 24, Block.grass.blockID);
		world.setBlock(i + 10, j + 1, k + 25, Block.grass.blockID);
		world.setBlock(i + 10, j + 1, k + 26, Block.grass.blockID);
		world.setBlock(i + 10, j + 1, k + 27, Block.grass.blockID);
		world.setBlock(i + 10, j + 1, k + 28, Block.grass.blockID);
		world.setBlock(i + 10, j + 1, k + 44, Block.stoneBrick.blockID);
		world.setBlock(i + 10, j + 2, k + 7, Block.stoneBrick.blockID);
		world.setBlock(i + 10, j + 2, k + 13, Block.stoneBrick.blockID);
		world.setBlock(i + 10, j + 2, k + 14, Block.cobblestone.blockID);
		world.setBlock(i + 10, j + 2, k + 15, Block.cobblestone.blockID);
		world.setBlock(i + 10, j + 2, k + 16, Block.stoneDoubleSlab.blockID, 6, k);
		world.setBlock(i + 10, j + 2, k + 17, Block.cobblestone.blockID);
		world.setBlock(i + 10, j + 2, k + 18, Block.stoneBrick.blockID);
		world.setBlock(i + 10, j + 2, k + 19, Block.stoneBrick.blockID);
		world.setBlock(i + 10, j + 2, k + 44, Block.stoneBrick.blockID);
		world.setBlock(i + 10, j + 3, k + 7, Block.stoneBrick.blockID);
		world.setBlock(i + 10, j + 3, k + 13, Block.stoneBrick.blockID);
		world.setBlock(i + 10, j + 3, k + 15, Block.stoneBrick.blockID);
		world.setBlock(i + 10, j + 3, k + 18, Block.stoneBrick.blockID);
		world.setBlock(i + 10, j + 3, k + 19, Block.stoneBrick.blockID);
		world.setBlock(i + 10, j + 3, k + 44, Block.stoneBrick.blockID);
		world.setBlock(i + 10, j + 4, k + 7, Block.stoneBrick.blockID);
		world.setBlock(i + 10, j + 4, k + 13, Block.stoneBrick.blockID);
		world.setBlock(i + 10, j + 4, k + 14, Block.stoneDoubleSlab.blockID, 6, k);
		world.setBlock(i + 10, j + 4, k + 15, Block.stoneBrick.blockID);
		world.setBlock(i + 10, j + 4, k + 18, Block.stoneBrick.blockID);
		world.setBlock(i + 10, j + 4, k + 19, Block.stoneBrick.blockID);
		world.setBlock(i + 10, j + 4, k + 44, Block.stoneBrick.blockID);
		world.setBlock(i + 10, j + 5, k + 7, Block.stairsStoneBrick.blockID);
		world.setBlock(i + 10, j + 5, k + 13, Block.stoneBrick.blockID);
		world.setBlock(i + 10, j + 5, k + 15, Block.stoneBrick.blockID);
		world.setBlock(i + 10, j + 5, k + 17, Block.cobblestone.blockID);
		world.setBlock(i + 10, j + 5, k + 18, Block.stoneBrick.blockID);
		world.setBlock(i + 10, j + 5, k + 19, Block.stoneBrick.blockID);
		world.setBlock(i + 10, j + 5, k + 44, Block.stairsStoneBrick.blockID, 1, k);
		world.setBlock(i + 10, j + 6, k + 13, Block.stoneBrick.blockID);
		world.setBlock(i + 10, j + 6, k + 15, Block.stoneBrick.blockID);
		world.setBlock(i + 10, j + 6, k + 16, Block.stoneDoubleSlab.blockID, 6, k);
		world.setBlock(i + 10, j + 6, k + 18, Block.stoneBrick.blockID);
		world.setBlock(i + 10, j + 6, k + 19, Block.stoneBrick.blockID);
		world.setBlock(i + 10, j + 7, k + 13, Block.stoneBrick.blockID);
		world.setBlock(i + 10, j + 7, k + 15, Block.stoneBrick.blockID);
		world.setBlock(i + 10, j + 7, k + 18, Block.stoneBrick.blockID);
		world.setBlock(i + 10, j + 7, k + 19, Block.stoneBrick.blockID);
		world.setBlock(i + 10, j + 8, k + 13, Block.stoneBrick.blockID);
		world.setBlock(i + 10, j + 8, k + 14, Block.stoneDoubleSlab.blockID, 6, k);
		world.setBlock(i + 10, j + 8, k + 15, Block.stoneBrick.blockID);
		world.setBlock(i + 10, j + 8, k + 18, Block.stoneBrick.blockID);
		world.setBlock(i + 10, j + 8, k + 19, Block.stoneBrick.blockID);
		world.setBlock(i + 10, j + 9, k + 13, Block.stoneBrick.blockID);
		world.setBlock(i + 10, j + 9, k + 15, Block.cobblestone.blockID);
		world.setBlock(i + 10, j + 9, k + 16, Block.cobblestone.blockID);
		world.setBlock(i + 10, j + 9, k + 17, Block.cobblestone.blockID);
		world.setBlock(i + 10, j + 9, k + 18, Block.stoneBrick.blockID);
		world.setBlock(i + 10, j + 9, k + 19, Block.stoneBrick.blockID);
		world.setBlock(i + 10, j + 10, k + 13, Block.stoneBrick.blockID);
		world.setBlock(i + 10, j + 10, k + 18, Block.stoneSingleSlab.blockID, 5, k);
		world.setBlock(i + 10, j + 10, k + 19, Block.stoneBrick.blockID);
		world.setBlock(i + 11, j + 0, k + 0, Block.grass.blockID);
		world.setBlock(i + 11, j + 0, k + 1, Block.grass.blockID);
		world.setBlock(i + 11, j + 0, k + 2, Block.grass.blockID);
		world.setBlock(i + 11, j + 0, k + 3, Block.grass.blockID);
		world.setBlock(i + 11, j + 0, k + 4, Block.grass.blockID);
		world.setBlock(i + 11, j + 0, k + 5, Block.grass.blockID);
		world.setBlock(i + 11, j + 0, k + 6, Block.grass.blockID);
		world.setBlock(i + 11, j + 0, k + 7, Block.dirt.blockID);
		world.setBlock(i + 11, j + 0, k + 8, Block.grass.blockID);
		world.setBlock(i + 11, j + 0, k + 9, Block.grass.blockID);
		world.setBlock(i + 11, j + 0, k + 10, Block.grass.blockID);
		world.setBlock(i + 11, j + 0, k + 11, Block.grass.blockID);
		world.setBlock(i + 11, j + 0, k + 12, Block.dirt.blockID);
		world.setBlock(i + 11, j + 0, k + 13, Block.stoneBrick.blockID);
		world.setBlock(i + 11, j + 0, k + 14, Block.grass.blockID);
		world.setBlock(i + 11, j + 0, k + 15, Block.grass.blockID);
		world.setBlock(i + 11, j + 0, k + 16, Block.grass.blockID);
		world.setBlock(i + 11, j + 0, k + 17, Block.grass.blockID);
		world.setBlock(i + 11, j + 0, k + 18, Block.grass.blockID);
		world.setBlock(i + 11, j + 0, k + 19, Block.grass.blockID);
		world.setBlock(i + 11, j + 0, k + 20, Block.grass.blockID);
		world.setBlock(i + 11, j + 0, k + 21, Block.grass.blockID);
		world.setBlock(i + 11, j + 0, k + 22, Block.grass.blockID);
		world.setBlock(i + 11, j + 0, k + 23, Block.grass.blockID);
		world.setBlock(i + 11, j + 0, k + 24, Block.grass.blockID);
		world.setBlock(i + 11, j + 0, k + 25, Block.grass.blockID);
		world.setBlock(i + 11, j + 0, k + 26, Block.grass.blockID);
		world.setBlock(i + 11, j + 0, k + 27, Block.grass.blockID);
		world.setBlock(i + 11, j + 0, k + 28, Block.dirt.blockID);
		world.setBlock(i + 11, j + 0, k + 29, Block.dirt.blockID);
		world.setBlock(i + 11, j + 0, k + 30, Block.grass.blockID);
		world.setBlock(i + 11, j + 0, k + 31, Block.grass.blockID);
		world.setBlock(i + 11, j + 0, k + 32, Block.grass.blockID);
		world.setBlock(i + 11, j + 0, k + 33, Block.grass.blockID);
		world.setBlock(i + 11, j + 0, k + 34, Block.grass.blockID);
		world.setBlock(i + 11, j + 0, k + 35, Block.grass.blockID);
		world.setBlock(i + 11, j + 0, k + 36, Block.stone.blockID);
		world.setBlock(i + 11, j + 0, k + 37, Block.stone.blockID);
		world.setBlock(i + 11, j + 0, k + 38, Block.stone.blockID);
		world.setBlock(i + 11, j + 0, k + 39, Block.stone.blockID);
		world.setBlock(i + 11, j + 0, k + 40, Block.stone.blockID);
		world.setBlock(i + 11, j + 0, k + 41, Block.stone.blockID);
		world.setBlock(i + 11, j + 0, k + 42, Block.grass.blockID);
		world.setBlock(i + 11, j + 0, k + 43, Block.grass.blockID);
		world.setBlock(i + 11, j + 0, k + 44, Block.dirt.blockID);
		world.setBlock(i + 11, j + 0, k + 45, Block.grass.blockID);
		world.setBlock(i + 11, j + 0, k + 46, Block.grass.blockID);
		world.setBlock(i + 11, j + 0, k + 47, Block.grass.blockID);
		world.setBlock(i + 11, j + 0, k + 48, Block.grass.blockID);
		world.setBlock(i + 11, j + 1, k + 7, Block.stoneBrick.blockID);
		world.setBlock(i + 11, j + 1, k + 12, Block.grass.blockID);
		world.setBlock(i + 11, j + 1, k + 13, Block.dirt.blockID);
		world.setBlock(i + 11, j + 1, k + 28, Block.grass.blockID);
		world.setBlock(i + 11, j + 1, k + 29, Block.grass.blockID);
		world.setBlock(i + 11, j + 1, k + 37, Block.stoneDoubleSlab.blockID);
		world.setBlock(i + 11, j + 1, k + 38, Block.stoneDoubleSlab.blockID);
		world.setBlock(i + 11, j + 1, k + 39, Block.stoneDoubleSlab.blockID);
		world.setBlock(i + 11, j + 1, k + 40, Block.stoneDoubleSlab.blockID);
		world.setBlock(i + 11, j + 1, k + 44, Block.stoneBrick.blockID);
		world.setBlock(i + 11, j + 2, k + 7, Block.stoneBrick.blockID);
		world.setBlock(i + 11, j + 2, k + 13, Block.stoneBrick.blockID);
		world.setBlock(i + 11, j + 2, k + 14, Block.cobblestone.blockID);
		world.setBlock(i + 11, j + 2, k + 15, Block.cobblestone.blockID);
		world.setBlock(i + 11, j + 2, k + 16, Block.cobblestone.blockID);
		world.setBlock(i + 11, j + 2, k + 17, Block.cobblestone.blockID);
		world.setBlock(i + 11, j + 2, k + 18, Block.cobblestone.blockID);
		world.setBlock(i + 11, j + 2, k + 19, Block.cobblestone.blockID);
		world.setBlock(i + 11, j + 2, k + 20, Block.stoneBrick.blockID);
		world.setBlock(i + 11, j + 2, k + 21, Block.stoneBrick.blockID);
		world.setBlock(i + 11, j + 2, k + 22, Block.stoneBrick.blockID);
		world.setBlock(i + 11, j + 2, k + 23, Block.stoneBrick.blockID);
		world.setBlock(i + 11, j + 2, k + 24, Block.stoneBrick.blockID);
		world.setBlock(i + 11, j + 2, k + 25, Block.stoneBrick.blockID);
		world.setBlock(i + 11, j + 2, k + 26, Block.stoneBrick.blockID);
		world.setBlock(i + 11, j + 2, k + 27, Block.stoneBrick.blockID);
		world.setBlock(i + 11, j + 2, k + 44, Block.stoneBrick.blockID);
		world.setBlock(i + 11, j + 3, k + 7, Block.stoneBrick.blockID);
		world.setBlock(i + 11, j + 3, k + 13, Block.stoneBrick.blockID);
		world.setBlock(i + 11, j + 3, k + 19, Block.stoneBrick.blockID);
		world.setBlock(i + 11, j + 3, k + 20, Block.stoneBrick.blockID);
		world.setBlock(i + 11, j + 3, k + 21, Block.stoneBrick.blockID);
		world.setBlock(i + 11, j + 3, k + 22, Block.stoneBrick.blockID);
		world.setBlock(i + 11, j + 3, k + 23, Block.stoneBrick.blockID);
		world.setBlock(i + 11, j + 3, k + 24, Block.stoneBrick.blockID);
		world.setBlock(i + 11, j + 3, k + 25, Block.stoneBrick.blockID);
		world.setBlock(i + 11, j + 3, k + 26, Block.stoneBrick.blockID);
		world.setBlock(i + 11, j + 3, k + 27, Block.stoneBrick.blockID);
		world.setBlock(i + 11, j + 3, k + 44, Block.stoneBrick.blockID);
		world.setBlock(i + 11, j + 4, k + 7, Block.stoneBrick.blockID);
		world.setBlock(i + 11, j + 4, k + 13, Block.stoneBrick.blockID);
		world.setBlock(i + 11, j + 4, k + 19, Block.stoneBrick.blockID);
		world.setBlock(i + 11, j + 4, k + 20, Block.stoneBrick.blockID);
		world.setBlock(i + 11, j + 4, k + 21, Block.stoneBrick.blockID);
		world.setBlock(i + 11, j + 4, k + 22, Block.stoneBrick.blockID);
		world.setBlock(i + 11, j + 4, k + 23, Block.stoneBrick.blockID);
		world.setBlock(i + 11, j + 4, k + 24, Block.stoneBrick.blockID);
		world.setBlock(i + 11, j + 4, k + 25, Block.stoneBrick.blockID);
		world.setBlock(i + 11, j + 4, k + 26, Block.stoneBrick.blockID);
		world.setBlock(i + 11, j + 4, k + 27, Block.stoneBrick.blockID);
		world.setBlock(i + 11, j + 4, k + 44, Block.stoneBrick.blockID);
		world.setBlock(i + 11, j + 5, k + 7, Block.stairsStoneBrick.blockID);
		world.setBlock(i + 11, j + 5, k + 13, Block.stoneBrick.blockID);
		world.setBlock(i + 11, j + 5, k + 14, Block.stoneDoubleSlab.blockID, 6, k);
		world.setBlock(i + 11, j + 5, k + 15, Block.stoneDoubleSlab.blockID, 6, k);
		world.setBlock(i + 11, j + 5, k + 16, Block.stoneDoubleSlab.blockID, 6, k);
		world.setBlock(i + 11, j + 5, k + 17, Block.cobblestone.blockID);
		world.setBlock(i + 11, j + 5, k + 18, Block.cobblestone.blockID);
		world.setBlock(i + 11, j + 5, k + 19, Block.stoneBrick.blockID);
		world.setBlock(i + 11, j + 5, k + 20, Block.stoneBrick.blockID);
		world.setBlock(i + 11, j + 5, k + 21, Block.stoneBrick.blockID);
		world.setBlock(i + 11, j + 5, k + 22, Block.stoneBrick.blockID);
		world.setBlock(i + 11, j + 5, k + 23, Block.stoneBrick.blockID);
		world.setBlock(i + 11, j + 5, k + 24, Block.stoneBrick.blockID);
		world.setBlock(i + 11, j + 5, k + 25, Block.stoneBrick.blockID);
		world.setBlock(i + 11, j + 5, k + 26, Block.stoneBrick.blockID);
		world.setBlock(i + 11, j + 5, k + 27, Block.stoneBrick.blockID);
		world.setBlock(i + 11, j + 5, k + 44, Block.stairsStoneBrick.blockID, 1, k);
		world.setBlock(i + 11, j + 6, k + 13, Block.stoneBrick.blockID);
		world.setBlock(i + 11, j + 6, k + 19, Block.stoneBrick.blockID);
		world.setBlock(i + 11, j + 6, k + 20, Block.stoneSingleSlab.blockID, 5, k);
		world.setBlock(i + 11, j + 6, k + 21, Block.stoneBrick.blockID);
		world.setBlock(i + 11, j + 6, k + 22, Block.stoneSingleSlab.blockID, 5, k);
		world.setBlock(i + 11, j + 6, k + 23, Block.stoneBrick.blockID);
		world.setBlock(i + 11, j + 6, k + 24, Block.stoneSingleSlab.blockID, 5, k);
		world.setBlock(i + 11, j + 6, k + 25, Block.stoneBrick.blockID);
		world.setBlock(i + 11, j + 6, k + 26, Block.stoneSingleSlab.blockID, 5, k);
		world.setBlock(i + 11, j + 6, k + 27, Block.stoneBrick.blockID);
		world.setBlock(i + 11, j + 7, k + 13, Block.stoneBrick.blockID);
		world.setBlock(i + 11, j + 7, k + 19, Block.stoneBrick.blockID);
		world.setBlock(i + 11, j + 8, k + 13, Block.stoneBrick.blockID);
		world.setBlock(i + 11, j + 8, k + 14, Block.stoneDoubleSlab.blockID, 6, k);
		world.setBlock(i + 11, j + 8, k + 19, Block.stoneBrick.blockID);
		world.setBlock(i + 11, j + 9, k + 13, Block.stoneBrick.blockID);
		world.setBlock(i + 11, j + 9, k + 15, Block.stoneDoubleSlab.blockID, 6, k);
		world.setBlock(i + 11, j + 9, k + 16, Block.stoneDoubleSlab.blockID, 6, k);
		world.setBlock(i + 11, j + 9, k + 17, Block.cobblestone.blockID);
		world.setBlock(i + 11, j + 9, k + 18, Block.cobblestone.blockID);
		world.setBlock(i + 11, j + 9, k + 19, Block.stoneBrick.blockID);
		world.setBlock(i + 11, j + 10, k + 13, Block.stoneSingleSlab.blockID, 5, k);
		world.setBlock(i + 11, j + 10, k + 19, Block.stoneSingleSlab.blockID, 5, k);
		world.setBlock(i + 12, j + 0, k + 0, Block.grass.blockID);
		world.setBlock(i + 12, j + 0, k + 1, Block.grass.blockID);
		world.setBlock(i + 12, j + 0, k + 2, Block.grass.blockID);
		world.setBlock(i + 12, j + 0, k + 3, Block.grass.blockID);
		world.setBlock(i + 12, j + 0, k + 4, Block.grass.blockID);
		world.setBlock(i + 12, j + 0, k + 5, Block.grass.blockID);
		world.setBlock(i + 12, j + 0, k + 6, Block.grass.blockID);
		world.setBlock(i + 12, j + 0, k + 7, Block.dirt.blockID);
		world.setBlock(i + 12, j + 0, k + 8, Block.grass.blockID);
		world.setBlock(i + 12, j + 0, k + 9, Block.grass.blockID);
		world.setBlock(i + 12, j + 0, k + 10, Block.grass.blockID);
		world.setBlock(i + 12, j + 0, k + 11, Block.grass.blockID);
		world.setBlock(i + 12, j + 0, k + 12, Block.dirt.blockID);
		world.setBlock(i + 12, j + 0, k + 13, Block.dirt.blockID);
		world.setBlock(i + 12, j + 0, k + 14, Block.dirt.blockID);
		world.setBlock(i + 12, j + 0, k + 15, Block.grass.blockID);
		world.setBlock(i + 12, j + 0, k + 16, Block.grass.blockID);
		world.setBlock(i + 12, j + 0, k + 17, Block.grass.blockID);
		world.setBlock(i + 12, j + 0, k + 18, Block.grass.blockID);
		world.setBlock(i + 12, j + 0, k + 19, Block.grass.blockID);
		world.setBlock(i + 12, j + 0, k + 20, Block.grass.blockID);
		world.setBlock(i + 12, j + 0, k + 21, Block.grass.blockID);
		world.setBlock(i + 12, j + 0, k + 22, Block.grass.blockID);
		world.setBlock(i + 12, j + 0, k + 23, Block.grass.blockID);
		world.setBlock(i + 12, j + 0, k + 24, Block.grass.blockID);
		world.setBlock(i + 12, j + 0, k + 25, Block.grass.blockID);
		world.setBlock(i + 12, j + 0, k + 26, Block.grass.blockID);
		world.setBlock(i + 12, j + 0, k + 27, Block.grass.blockID);
		world.setBlock(i + 12, j + 0, k + 28, Block.grass.blockID);
		world.setBlock(i + 12, j + 0, k + 29, Block.dirt.blockID);
		world.setBlock(i + 12, j + 0, k + 30, Block.dirt.blockID);
		world.setBlock(i + 12, j + 0, k + 31, Block.grass.blockID);
		world.setBlock(i + 12, j + 0, k + 32, Block.grass.blockID);
		world.setBlock(i + 12, j + 0, k + 33, Block.grass.blockID);
		world.setBlock(i + 12, j + 0, k + 34, Block.grass.blockID);
		world.setBlock(i + 12, j + 0, k + 35, Block.grass.blockID);
		world.setBlock(i + 12, j + 0, k + 36, Block.stone.blockID);
		world.setBlock(i + 12, j + 0, k + 37, Block.stone.blockID);
		world.setBlock(i + 12, j + 0, k + 38, Block.stone.blockID);
		world.setBlock(i + 12, j + 0, k + 39, Block.stone.blockID);
		world.setBlock(i + 12, j + 0, k + 40, Block.stone.blockID);
		world.setBlock(i + 12, j + 0, k + 41, Block.stone.blockID);
		world.setBlock(i + 12, j + 0, k + 42, Block.grass.blockID);
		world.setBlock(i + 12, j + 0, k + 43, Block.grass.blockID);
		world.setBlock(i + 12, j + 0, k + 44, Block.dirt.blockID);
		world.setBlock(i + 12, j + 0, k + 45, Block.grass.blockID);
		world.setBlock(i + 12, j + 0, k + 46, Block.grass.blockID);
		world.setBlock(i + 12, j + 0, k + 47, Block.grass.blockID);
		world.setBlock(i + 12, j + 0, k + 48, Block.grass.blockID);
		world.setBlock(i + 12, j + 1, k + 7, Block.stoneBrick.blockID);
		world.setBlock(i + 12, j + 1, k + 12, Block.grass.blockID);
		world.setBlock(i + 12, j + 1, k + 13, Block.grass.blockID);
		world.setBlock(i + 12, j + 1, k + 14, Block.dirt.blockID);
		world.setBlock(i + 12, j + 1, k + 29, Block.grass.blockID);
		world.setBlock(i + 12, j + 1, k + 30, Block.grass.blockID);
		world.setBlock(i + 12, j + 1, k + 37, Block.stoneDoubleSlab.blockID);
		world.setBlock(i + 12, j + 1, k + 40, Block.stoneDoubleSlab.blockID);
		world.setBlock(i + 12, j + 1, k + 44, Block.stoneBrick.blockID);
		world.setBlock(i + 12, j + 2, k + 7, Block.stoneBrick.blockID);
		world.setBlock(i + 12, j + 2, k + 14, Block.stoneBrick.blockID);
		world.setBlock(i + 12, j + 2, k + 15, Block.cobblestone.blockID);
		world.setBlock(i + 12, j + 2, k + 16, Block.cobblestone.blockID);
		world.setBlock(i + 12, j + 2, k + 17, Block.cobblestone.blockID);
		world.setBlock(i + 12, j + 2, k + 18, Block.cobblestone.blockID);
		world.setBlock(i + 12, j + 2, k + 19, Block.cobblestone.blockID);
		world.setBlock(i + 12, j + 2, k + 20, Block.cloth.blockID, 11, k);
		world.setBlock(i + 12, j + 2, k + 21, Block.cloth.blockID, 11, k);
		world.setBlock(i + 12, j + 2, k + 22, Block.cloth.blockID, 11, k);
		world.setBlock(i + 12, j + 2, k + 23, Block.cloth.blockID, 11, k);
		world.setBlock(i + 12, j + 2, k + 24, Block.cloth.blockID, 11, k);
		world.setBlock(i + 12, j + 2, k + 25, Block.cobblestone.blockID);
		world.setBlock(i + 12, j + 2, k + 26, Block.cobblestone.blockID);
		world.setBlock(i + 12, j + 2, k + 27, Block.cobblestone.blockID);
		world.setBlock(i + 12, j + 2, k + 28, Block.stoneBrick.blockID);
		world.setBlock(i + 12, j + 2, k + 44, Block.stoneBrick.blockID);
		world.setBlock(i + 12, j + 3, k + 7, Block.stoneBrick.blockID);
		world.setBlock(i + 12, j + 3, k + 14, Block.stoneBrick.blockID);
		world.setBlock(i + 12, j + 3, k + 28, Block.stoneBrick.blockID);
		world.setBlock(i + 12, j + 3, k + 44, Block.stoneBrick.blockID);
		world.setBlock(i + 12, j + 4, k + 7, Block.stoneBrick.blockID);
		world.setBlock(i + 12, j + 4, k + 14, Block.stoneBrick.blockID);
		world.setBlock(i + 12, j + 4, k + 28, Block.stoneBrick.blockID);
		world.setBlock(i + 12, j + 4, k + 44, Block.stoneBrick.blockID);
		world.setBlock(i + 12, j + 5, k + 7, Block.stairsStoneBrick.blockID);
		world.setBlock(i + 12, j + 5, k + 14, Block.stoneBrick.blockID);
		world.setBlock(i + 12, j + 5, k + 15, Block.cobblestone.blockID);
		world.setBlock(i + 12, j + 5, k + 16, Block.cobblestone.blockID);
		world.setBlock(i + 12, j + 5, k + 17, Block.cobblestone.blockID);
		world.setBlock(i + 12, j + 5, k + 18, Block.cobblestone.blockID);
		world.setBlock(i + 12, j + 5, k + 19, Block.cobblestone.blockID);
		world.setBlock(i + 12, j + 5, k + 20, Block.cobblestone.blockID);
		world.setBlock(i + 12, j + 5, k + 21, Block.cobblestone.blockID);
		world.setBlock(i + 12, j + 5, k + 22, Block.cobblestone.blockID);
		world.setBlock(i + 12, j + 5, k + 23, Block.cobblestone.blockID);
		world.setBlock(i + 12, j + 5, k + 24, Block.cobblestone.blockID);
		world.setBlock(i + 12, j + 5, k + 25, Block.cobblestone.blockID);
		world.setBlock(i + 12, j + 5, k + 26, Block.cobblestone.blockID);
		world.setBlock(i + 12, j + 5, k + 27, Block.cobblestone.blockID);
		world.setBlock(i + 12, j + 5, k + 28, Block.stoneBrick.blockID);
		world.setBlock(i + 12, j + 5, k + 44, Block.stairsStoneBrick.blockID, 1, k);
		world.setBlock(i + 12, j + 6, k + 14, Block.stoneBrick.blockID);
		world.setBlock(i + 12, j + 6, k + 28, Block.stoneSingleSlab.blockID, 5, k);
		world.setBlock(i + 12, j + 7, k + 14, Block.stoneBrick.blockID);
		world.setBlock(i + 12, j + 8, k + 14, Block.stoneBrick.blockID);
		world.setBlock(i + 12, j + 8, k + 19, Block.stoneBrick.blockID);
		world.setBlock(i + 12, j + 9, k + 14, Block.stoneBrick.blockID);
		world.setBlock(i + 12, j + 9, k + 15, Block.cobblestone.blockID);
		world.setBlock(i + 12, j + 9, k + 16, Block.cobblestone.blockID);
		world.setBlock(i + 12, j + 9, k + 17, Block.cobblestone.blockID);
		world.setBlock(i + 12, j + 9, k + 18, Block.cobblestone.blockID);
		world.setBlock(i + 12, j + 9, k + 19, Block.stoneBrick.blockID);
		world.setBlock(i + 12, j + 10, k + 14, Block.stoneBrick.blockID);
		world.setBlock(i + 12, j + 10, k + 19, Block.stoneBrick.blockID);
		world.setBlock(i + 13, j + 0, k + 0, Block.grass.blockID);
		world.setBlock(i + 13, j + 0, k + 1, Block.grass.blockID);
		world.setBlock(i + 13, j + 0, k + 2, Block.grass.blockID);
		world.setBlock(i + 13, j + 0, k + 3, Block.grass.blockID);
		world.setBlock(i + 13, j + 0, k + 4, Block.grass.blockID);
		world.setBlock(i + 13, j + 0, k + 5, Block.grass.blockID);
		world.setBlock(i + 13, j + 0, k + 6, Block.grass.blockID);
		world.setBlock(i + 13, j + 0, k + 7, Block.dirt.blockID);
		world.setBlock(i + 13, j + 0, k + 8, Block.grass.blockID);
		world.setBlock(i + 13, j + 0, k + 9, Block.grass.blockID);
		world.setBlock(i + 13, j + 0, k + 10, Block.grass.blockID);
		world.setBlock(i + 13, j + 0, k + 11, Block.grass.blockID);
		world.setBlock(i + 13, j + 0, k + 12, Block.grass.blockID);
		world.setBlock(i + 13, j + 0, k + 13, Block.dirt.blockID);
		world.setBlock(i + 13, j + 0, k + 14, Block.dirt.blockID);
		world.setBlock(i + 13, j + 0, k + 15, Block.dirt.blockID);
		world.setBlock(i + 13, j + 0, k + 16, Block.grass.blockID);
		world.setBlock(i + 13, j + 0, k + 17, Block.grass.blockID);
		world.setBlock(i + 13, j + 0, k + 18, Block.dirt.blockID);
		world.setBlock(i + 13, j + 0, k + 19, Block.grass.blockID);
		world.setBlock(i + 13, j + 0, k + 20, Block.grass.blockID);
		world.setBlock(i + 13, j + 0, k + 21, Block.grass.blockID);
		world.setBlock(i + 13, j + 0, k + 22, Block.grass.blockID);
		world.setBlock(i + 13, j + 0, k + 23, Block.grass.blockID);
		world.setBlock(i + 13, j + 0, k + 24, Block.grass.blockID);
		world.setBlock(i + 13, j + 0, k + 25, Block.grass.blockID);
		world.setBlock(i + 13, j + 0, k + 26, Block.grass.blockID);
		world.setBlock(i + 13, j + 0, k + 27, Block.grass.blockID);
		world.setBlock(i + 13, j + 0, k + 28, Block.grass.blockID);
		world.setBlock(i + 13, j + 0, k + 29, Block.grass.blockID);
		world.setBlock(i + 13, j + 0, k + 30, Block.dirt.blockID);
		world.setBlock(i + 13, j + 0, k + 31, Block.dirt.blockID);
		world.setBlock(i + 13, j + 0, k + 32, Block.grass.blockID);
		world.setBlock(i + 13, j + 0, k + 33, Block.grass.blockID);
		world.setBlock(i + 13, j + 0, k + 34, Block.grass.blockID);
		world.setBlock(i + 13, j + 0, k + 35, Block.grass.blockID);
		world.setBlock(i + 13, j + 0, k + 36, Block.stone.blockID);
		world.setBlock(i + 13, j + 0, k + 37, Block.stone.blockID);
		world.setBlock(i + 13, j + 0, k + 38, Block.stone.blockID);
		world.setBlock(i + 13, j + 0, k + 39, Block.stone.blockID);
		world.setBlock(i + 13, j + 0, k + 40, Block.stone.blockID);
		world.setBlock(i + 13, j + 0, k + 41, Block.stone.blockID);
		world.setBlock(i + 13, j + 0, k + 42, Block.grass.blockID);
		world.setBlock(i + 13, j + 0, k + 43, Block.grass.blockID);
		world.setBlock(i + 13, j + 0, k + 44, Block.dirt.blockID);
		world.setBlock(i + 13, j + 0, k + 45, Block.grass.blockID);
		world.setBlock(i + 13, j + 0, k + 46, Block.grass.blockID);
		world.setBlock(i + 13, j + 0, k + 47, Block.grass.blockID);
		world.setBlock(i + 13, j + 0, k + 48, Block.grass.blockID);
		world.setBlock(i + 13, j + 1, k + 7, Block.stoneBrick.blockID);
		world.setBlock(i + 13, j + 1, k + 13, Block.grass.blockID);
		world.setBlock(i + 13, j + 1, k + 14, Block.grass.blockID);
		world.setBlock(i + 13, j + 1, k + 15, Block.stoneBrick.blockID);
		world.setBlock(i + 13, j + 1, k + 18, Block.stoneBrick.blockID);
		world.setBlock(i + 13, j + 1, k + 30, Block.grass.blockID);
		world.setBlock(i + 13, j + 1, k + 31, Block.grass.blockID);
		world.setBlock(i + 13, j + 1, k + 37, Block.stoneDoubleSlab.blockID);
		world.setBlock(i + 13, j + 1, k + 40, Block.stoneDoubleSlab.blockID);
		world.setBlock(i + 13, j + 1, k + 44, Block.stoneBrick.blockID);
		world.setBlock(i + 13, j + 2, k + 7, Block.stoneBrick.blockID);
		world.setBlock(i + 13, j + 2, k + 15, Block.stoneBrick.blockID);
		world.setBlock(i + 13, j + 2, k + 16, Block.cobblestone.blockID);
		world.setBlock(i + 13, j + 2, k + 17, Block.cobblestone.blockID);
		world.setBlock(i + 13, j + 2, k + 18, Block.cobblestone.blockID);
		world.setBlock(i + 13, j + 2, k + 19, Block.cobblestone.blockID);
		world.setBlock(i + 13, j + 2, k + 20, Block.cloth.blockID, 11, k);
		world.setBlock(i + 13, j + 2, k + 21, Block.cloth.blockID, 11, k);
		world.setBlock(i + 13, j + 2, k + 22, Block.cloth.blockID, 11, k);
		world.setBlock(i + 13, j + 2, k + 23, Block.cloth.blockID, 11, k);
		world.setBlock(i + 13, j + 2, k + 24, Block.cloth.blockID, 11, k);
		world.setBlock(i + 13, j + 2, k + 25, Block.cobblestone.blockID);
		world.setBlock(i + 13, j + 2, k + 26, Block.cobblestone.blockID);
		world.setBlock(i + 13, j + 2, k + 27, Block.cobblestone.blockID);
		world.setBlock(i + 13, j + 2, k + 28, Block.cobblestone.blockID);
		world.setBlock(i + 13, j + 2, k + 29, Block.stoneBrick.blockID);
		world.setBlock(i + 13, j + 2, k + 44, Block.stoneBrick.blockID);
		world.setBlock(i + 13, j + 3, k + 7, Block.stoneBrick.blockID);
		world.setBlock(i + 13, j + 3, k + 15, Block.stoneBrick.blockID);
		world.setBlock(i + 13, j + 3, k + 29, Block.stoneBrick.blockID);
		world.setBlock(i + 13, j + 3, k + 44, Block.stoneBrick.blockID);
		world.setBlock(i + 13, j + 4, k + 7, Block.stoneBrick.blockID);
		world.setBlock(i + 13, j + 4, k + 15, Block.stoneBrick.blockID);
		world.setBlock(i + 13, j + 4, k + 29, Block.stoneBrick.blockID);
		world.setBlock(i + 13, j + 4, k + 44, Block.stoneBrick.blockID);
		world.setBlock(i + 13, j + 5, k + 7, Block.stairsStoneBrick.blockID);
		world.setBlock(i + 13, j + 5, k + 15, Block.stoneBrick.blockID);
		world.setBlock(i + 13, j + 5, k + 16, Block.cobblestone.blockID);
		world.setBlock(i + 13, j + 5, k + 17, Block.cobblestone.blockID);
		world.setBlock(i + 13, j + 5, k + 18, Block.cobblestone.blockID);
		world.setBlock(i + 13, j + 5, k + 19, Block.cobblestone.blockID);
		world.setBlock(i + 13, j + 5, k + 20, Block.cobblestone.blockID);
		world.setBlock(i + 13, j + 5, k + 21, Block.cobblestone.blockID);
		world.setBlock(i + 13, j + 5, k + 22, Block.cobblestone.blockID);
		world.setBlock(i + 13, j + 5, k + 23, Block.cobblestone.blockID);
		world.setBlock(i + 13, j + 5, k + 24, Block.cobblestone.blockID);
		world.setBlock(i + 13, j + 5, k + 25, Block.cobblestone.blockID);
		world.setBlock(i + 13, j + 5, k + 26, Block.cobblestone.blockID);
		world.setBlock(i + 13, j + 5, k + 27, Block.cobblestone.blockID);
		world.setBlock(i + 13, j + 5, k + 28, Block.cobblestone.blockID);
		world.setBlock(i + 13, j + 5, k + 29, Block.stoneBrick.blockID);
		world.setBlock(i + 13, j + 5, k + 44, Block.stairsStoneBrick.blockID, 1, k);
		world.setBlock(i + 13, j + 6, k + 15, Block.stoneBrick.blockID);
		world.setBlock(i + 13, j + 6, k + 19, Block.stoneBrick.blockID);
		world.setBlock(i + 13, j + 6, k + 29, Block.stoneBrick.blockID);
		world.setBlock(i + 13, j + 7, k + 15, Block.stoneBrick.blockID);
		world.setBlock(i + 13, j + 7, k + 19, Block.stoneBrick.blockID);
		world.setBlock(i + 13, j + 8, k + 15, Block.stoneBrick.blockID);
		world.setBlock(i + 13, j + 8, k + 19, Block.stoneBrick.blockID);
		world.setBlock(i + 13, j + 9, k + 15, Block.stoneBrick.blockID);
		world.setBlock(i + 13, j + 9, k + 16, Block.cobblestone.blockID);
		world.setBlock(i + 13, j + 9, k + 17, Block.cobblestone.blockID);
		world.setBlock(i + 13, j + 9, k + 18, Block.cobblestone.blockID);
		world.setBlock(i + 13, j + 9, k + 19, Block.stoneBrick.blockID);
		world.setBlock(i + 13, j + 10, k + 15, Block.stoneSingleSlab.blockID, 5, k);
		world.setBlock(i + 13, j + 10, k + 19, Block.stoneSingleSlab.blockID, 5, k);
		world.setBlock(i + 14, j + 0, k + 0, Block.grass.blockID);
		world.setBlock(i + 14, j + 0, k + 1, Block.grass.blockID);
		world.setBlock(i + 14, j + 0, k + 2, Block.grass.blockID);
		world.setBlock(i + 14, j + 0, k + 3, Block.grass.blockID);
		world.setBlock(i + 14, j + 0, k + 4, Block.grass.blockID);
		world.setBlock(i + 14, j + 0, k + 5, Block.grass.blockID);
		world.setBlock(i + 14, j + 0, k + 6, Block.grass.blockID);
		world.setBlock(i + 14, j + 0, k + 7, Block.dirt.blockID);
		world.setBlock(i + 14, j + 0, k + 8, Block.grass.blockID);
		world.setBlock(i + 14, j + 0, k + 9, Block.grass.blockID);
		world.setBlock(i + 14, j + 0, k + 10, Block.grass.blockID);
		world.setBlock(i + 14, j + 0, k + 11, Block.grass.blockID);
		world.setBlock(i + 14, j + 0, k + 12, Block.grass.blockID);
		world.setBlock(i + 14, j + 0, k + 13, Block.grass.blockID);
		world.setBlock(i + 14, j + 0, k + 14, Block.dirt.blockID);
		world.setBlock(i + 14, j + 0, k + 15, Block.dirt.blockID);
		world.setBlock(i + 14, j + 0, k + 16, Block.dirt.blockID);
		world.setBlock(i + 14, j + 0, k + 17, Block.dirt.blockID);
		world.setBlock(i + 14, j + 0, k + 18, Block.dirt.blockID);
		world.setBlock(i + 14, j + 0, k + 19, Block.dirt.blockID);
		world.setBlock(i + 14, j + 0, k + 20, Block.dirt.blockID);
		world.setBlock(i + 14, j + 0, k + 21, Block.grass.blockID);
		world.setBlock(i + 14, j + 0, k + 22, Block.grass.blockID);
		world.setBlock(i + 14, j + 0, k + 23, Block.grass.blockID);
		world.setBlock(i + 14, j + 0, k + 24, Block.grass.blockID);
		world.setBlock(i + 14, j + 0, k + 25, Block.grass.blockID);
		world.setBlock(i + 14, j + 0, k + 26, Block.grass.blockID);
		world.setBlock(i + 14, j + 0, k + 27, Block.grass.blockID);
		world.setBlock(i + 14, j + 0, k + 28, Block.grass.blockID);
		world.setBlock(i + 14, j + 0, k + 29, Block.grass.blockID);
		world.setBlock(i + 14, j + 0, k + 30, Block.dirt.blockID);
		world.setBlock(i + 14, j + 0, k + 31, Block.dirt.blockID);
		world.setBlock(i + 14, j + 0, k + 32, Block.grass.blockID);
		world.setBlock(i + 14, j + 0, k + 33, Block.grass.blockID);
		world.setBlock(i + 14, j + 0, k + 34, Block.grass.blockID);
		world.setBlock(i + 14, j + 0, k + 35, Block.grass.blockID);
		world.setBlock(i + 14, j + 0, k + 36, Block.stone.blockID);
		world.setBlock(i + 14, j + 0, k + 37, Block.stone.blockID);
		world.setBlock(i + 14, j + 0, k + 38, Block.stone.blockID);
		world.setBlock(i + 14, j + 0, k + 39, Block.stone.blockID);
		world.setBlock(i + 14, j + 0, k + 40, Block.stone.blockID);
		world.setBlock(i + 14, j + 0, k + 41, Block.stone.blockID);
		world.setBlock(i + 14, j + 0, k + 42, Block.grass.blockID);
		world.setBlock(i + 14, j + 0, k + 43, Block.grass.blockID);
		world.setBlock(i + 14, j + 0, k + 44, Block.dirt.blockID);
		world.setBlock(i + 14, j + 0, k + 45, Block.grass.blockID);
		world.setBlock(i + 14, j + 0, k + 46, Block.grass.blockID);
		world.setBlock(i + 14, j + 0, k + 47, Block.grass.blockID);
		world.setBlock(i + 14, j + 0, k + 48, Block.grass.blockID);
		world.setBlock(i + 14, j + 1, k + 7, Block.stoneBrick.blockID);
		world.setBlock(i + 14, j + 1, k + 14, Block.grass.blockID);
		world.setBlock(i + 14, j + 1, k + 15, Block.stoneBrick.blockID);
		world.setBlock(i + 14, j + 1, k + 16, Block.stoneBrick.blockID);
		world.setBlock(i + 14, j + 1, k + 17, Block.stoneBrick.blockID);
		world.setBlock(i + 14, j + 1, k + 18, Block.stoneBrick.blockID);
		world.setBlock(i + 14, j + 1, k + 19, Block.stoneBrick.blockID);
		world.setBlock(i + 14, j + 1, k + 20, Block.stoneBrick.blockID);
		world.setBlock(i + 14, j + 1, k + 30, Block.stoneBrick.blockID);
		world.setBlock(i + 14, j + 1, k + 31, Block.grass.blockID);
		world.setBlock(i + 14, j + 1, k + 37, Block.stoneDoubleSlab.blockID);
		world.setBlock(i + 14, j + 1, k + 40, Block.stoneDoubleSlab.blockID);
		world.setBlock(i + 14, j + 1, k + 44, Block.stoneBrick.blockID);
		world.setBlock(i + 14, j + 2, k + 7, Block.stoneBrick.blockID);
		world.setBlock(i + 14, j + 2, k + 15, Block.stoneBrick.blockID);
		world.setBlock(i + 14, j + 2, k + 16, Block.cobblestone.blockID);
		world.setBlock(i + 14, j + 2, k + 17, Block.cobblestone.blockID);
		world.setBlock(i + 14, j + 2, k + 18, Block.cobblestone.blockID);
		world.setBlock(i + 14, j + 2, k + 19, Block.cobblestone.blockID);
		world.setBlock(i + 14, j + 2, k + 20, Block.cobblestone.blockID);
		world.setBlock(i + 14, j + 2, k + 21, Block.cobblestone.blockID);
		world.setBlock(i + 14, j + 2, k + 22, Block.cobblestone.blockID);
		world.setBlock(i + 14, j + 2, k + 23, Block.cobblestone.blockID);
		world.setBlock(i + 14, j + 2, k + 24, Block.cobblestone.blockID);
		world.setBlock(i + 14, j + 2, k + 25, Block.cobblestone.blockID);
		world.setBlock(i + 14, j + 2, k + 26, Block.cobblestone.blockID);
		world.setBlock(i + 14, j + 2, k + 27, Block.cobblestone.blockID);
		world.setBlock(i + 14, j + 2, k + 28, Block.cobblestone.blockID);
		world.setBlock(i + 14, j + 2, k + 29, Block.cobblestone.blockID);
		world.setBlock(i + 14, j + 2, k + 30, Block.stoneBrick.blockID);
		world.setBlock(i + 14, j + 2, k + 44, Block.stoneBrick.blockID);
		world.setBlock(i + 14, j + 3, k + 7, Block.stoneBrick.blockID);
		world.setBlock(i + 14, j + 3, k + 15, Block.stoneBrick.blockID);
		world.setBlock(i + 14, j + 3, k + 16, Block.stoneBrick.blockID);
		world.setBlock(i + 14, j + 3, k + 17, Block.stoneBrick.blockID);
		world.setBlock(i + 14, j + 3, k + 18, Block.stoneBrick.blockID);
		world.setBlock(i + 14, j + 3, k + 20, Block.stoneBrick.blockID);
		world.setBlock(i + 14, j + 3, k + 21, Block.stoneBrick.blockID);
		world.setBlock(i + 14, j + 3, k + 22, Block.stoneBrick.blockID);
		world.setBlock(i + 14, j + 3, k + 23, Block.stoneBrick.blockID);
		world.setBlock(i + 14, j + 3, k + 24, Block.stoneBrick.blockID);
		world.setBlock(i + 14, j + 3, k + 25, Block.stoneBrick.blockID);
		world.setBlock(i + 14, j + 3, k + 30, Block.stoneBrick.blockID);
		world.setBlock(i + 14, j + 3, k + 44, Block.stoneBrick.blockID);
		world.setBlock(i + 14, j + 4, k + 7, Block.stoneBrick.blockID);
		world.setBlock(i + 14, j + 4, k + 15, Block.stoneBrick.blockID);
		world.setBlock(i + 14, j + 4, k + 16, Block.stoneBrick.blockID);
		world.setBlock(i + 14, j + 4, k + 17, Block.stoneBrick.blockID);
		world.setBlock(i + 14, j + 4, k + 18, Block.stoneBrick.blockID);
		world.setBlock(i + 14, j + 4, k + 20, Block.stoneBrick.blockID);
		world.setBlock(i + 14, j + 4, k + 21, Block.stoneBrick.blockID);
		world.setBlock(i + 14, j + 4, k + 22, Block.stoneBrick.blockID);
		world.setBlock(i + 14, j + 4, k + 23, Block.stoneBrick.blockID);
		world.setBlock(i + 14, j + 4, k + 24, Block.stoneBrick.blockID);
		world.setBlock(i + 14, j + 4, k + 25, Block.stoneBrick.blockID);
		world.setBlock(i + 14, j + 4, k + 30, Block.glass.blockID);
		world.setBlock(i + 14, j + 4, k + 44, Block.stoneBrick.blockID);
		world.setBlock(i + 14, j + 5, k + 7, Block.stairsStoneBrick.blockID);
		world.setBlock(i + 14, j + 5, k + 15, Block.stoneBrick.blockID);
		world.setBlock(i + 14, j + 5, k + 16, Block.cobblestone.blockID);
		world.setBlock(i + 14, j + 5, k + 17, Block.cobblestone.blockID);
		world.setBlock(i + 14, j + 5, k + 18, Block.cobblestone.blockID);
		world.setBlock(i + 14, j + 5, k + 19, Block.cobblestone.blockID);
		world.setBlock(i + 14, j + 5, k + 20, Block.stoneBrick.blockID);
		world.setBlock(i + 14, j + 5, k + 21, Block.stoneBrick.blockID);
		world.setBlock(i + 14, j + 5, k + 22, Block.stoneBrick.blockID);
		world.setBlock(i + 14, j + 5, k + 23, Block.stoneBrick.blockID);
		world.setBlock(i + 14, j + 5, k + 24, Block.stoneBrick.blockID);
		world.setBlock(i + 14, j + 5, k + 25, Block.stoneBrick.blockID);
		world.setBlock(i + 14, j + 5, k + 26, Block.cobblestone.blockID);
		world.setBlock(i + 14, j + 5, k + 27, Block.cobblestone.blockID);
		world.setBlock(i + 14, j + 5, k + 28, Block.cobblestone.blockID);
		world.setBlock(i + 14, j + 5, k + 29, Block.cobblestone.blockID);
		world.setBlock(i + 14, j + 5, k + 30, Block.stoneBrick.blockID);
		world.setBlock(i + 14, j + 5, k + 44, Block.stairsStoneBrick.blockID, 1, k);
		world.setBlock(i + 14, j + 6, k + 15, Block.stoneBrick.blockID);
		world.setBlock(i + 14, j + 6, k + 19, Block.stoneBrick.blockID);
		world.setBlock(i + 14, j + 6, k + 20, Block.stoneBrick.blockID);
		world.setBlock(i + 14, j + 6, k + 21, Block.stoneBrick.blockID);
		world.setBlock(i + 14, j + 6, k + 22, Block.stoneBrick.blockID);
		world.setBlock(i + 14, j + 6, k + 23, Block.stoneBrick.blockID);
		world.setBlock(i + 14, j + 6, k + 24, Block.stoneBrick.blockID);
		world.setBlock(i + 14, j + 6, k + 25, Block.stoneBrick.blockID);
		world.setBlock(i + 14, j + 6, k + 30, Block.stoneSingleSlab.blockID, 5, k);
		world.setBlock(i + 14, j + 7, k + 15, Block.stoneBrick.blockID);
		world.setBlock(i + 14, j + 7, k + 19, Block.stoneBrick.blockID);
		world.setBlock(i + 14, j + 7, k + 20, Block.stoneBrick.blockID);
		world.setBlock(i + 14, j + 7, k + 21, Block.stoneBrick.blockID);
		world.setBlock(i + 14, j + 7, k + 22, Block.stoneBrick.blockID);
		world.setBlock(i + 14, j + 7, k + 23, Block.stoneBrick.blockID);
		world.setBlock(i + 14, j + 7, k + 24, Block.stoneBrick.blockID);
		world.setBlock(i + 14, j + 7, k + 25, Block.stoneBrick.blockID);
		world.setBlock(i + 14, j + 8, k + 15, Block.stoneBrick.blockID);
		world.setBlock(i + 14, j + 8, k + 19, Block.stoneBrick.blockID);
		world.setBlock(i + 14, j + 8, k + 20, Block.stoneBrick.blockID);
		world.setBlock(i + 14, j + 8, k + 21, Block.stoneBrick.blockID);
		world.setBlock(i + 14, j + 8, k + 22, Block.stoneBrick.blockID);
		world.setBlock(i + 14, j + 8, k + 23, Block.stoneBrick.blockID);
		world.setBlock(i + 14, j + 8, k + 24, Block.stoneBrick.blockID);
		world.setBlock(i + 14, j + 8, k + 25, Block.stoneBrick.blockID);
		world.setBlock(i + 14, j + 9, k + 15, Block.stoneBrick.blockID);
		world.setBlock(i + 14, j + 9, k + 16, Block.cobblestone.blockID);
		world.setBlock(i + 14, j + 9, k + 17, Block.cobblestone.blockID);
		world.setBlock(i + 14, j + 9, k + 18, Block.cobblestone.blockID);
		world.setBlock(i + 14, j + 9, k + 19, Block.cobblestone.blockID);
		world.setBlock(i + 14, j + 9, k + 20, Block.stoneBrick.blockID);
		world.setBlock(i + 14, j + 9, k + 21, Block.stoneBrick.blockID);
		world.setBlock(i + 14, j + 9, k + 22, Block.stoneBrick.blockID);
		world.setBlock(i + 14, j + 9, k + 23, Block.stoneBrick.blockID);
		world.setBlock(i + 14, j + 9, k + 24, Block.stoneBrick.blockID);
		world.setBlock(i + 14, j + 9, k + 25, Block.stoneBrick.blockID);
		world.setBlock(i + 14, j + 10, k + 15, Block.stoneBrick.blockID);
		world.setBlock(i + 14, j + 10, k + 20, Block.stoneBrick.blockID);
		world.setBlock(i + 14, j + 10, k + 21, Block.stoneSingleSlab.blockID, 5, k);
		world.setBlock(i + 14, j + 10, k + 22, Block.stoneBrick.blockID);
		world.setBlock(i + 14, j + 10, k + 23, Block.stoneSingleSlab.blockID, 5, k);
		world.setBlock(i + 14, j + 10, k + 24, Block.stoneBrick.blockID);
		world.setBlock(i + 14, j + 10, k + 25, Block.stoneSingleSlab.blockID, 5, k);
		world.setBlock(i + 15, j + 0, k + 0, Block.grass.blockID);
		world.setBlock(i + 15, j + 0, k + 1, Block.grass.blockID);
		world.setBlock(i + 15, j + 0, k + 2, Block.grass.blockID);
		world.setBlock(i + 15, j + 0, k + 3, Block.grass.blockID);
		world.setBlock(i + 15, j + 0, k + 4, Block.grass.blockID);
		world.setBlock(i + 15, j + 0, k + 5, Block.grass.blockID);
		world.setBlock(i + 15, j + 0, k + 6, Block.grass.blockID);
		world.setBlock(i + 15, j + 0, k + 7, Block.dirt.blockID);
		world.setBlock(i + 15, j + 0, k + 8, Block.grass.blockID);
		world.setBlock(i + 15, j + 0, k + 9, Block.grass.blockID);
		world.setBlock(i + 15, j + 0, k + 10, Block.grass.blockID);
		world.setBlock(i + 15, j + 0, k + 11, Block.grass.blockID);
		world.setBlock(i + 15, j + 0, k + 12, Block.grass.blockID);
		world.setBlock(i + 15, j + 0, k + 13, Block.grass.blockID);
		world.setBlock(i + 15, j + 0, k + 14, Block.dirt.blockID);
		world.setBlock(i + 15, j + 0, k + 15, Block.dirt.blockID);
		world.setBlock(i + 15, j + 0, k + 16, Block.grass.blockID);
		world.setBlock(i + 15, j + 0, k + 17, Block.grass.blockID);
		world.setBlock(i + 15, j + 0, k + 18, Block.grass.blockID);
		world.setBlock(i + 15, j + 0, k + 19, Block.grass.blockID);
		world.setBlock(i + 15, j + 0, k + 20, Block.grass.blockID);
		world.setBlock(i + 15, j + 0, k + 21, Block.grass.blockID);
		world.setBlock(i + 15, j + 0, k + 22, Block.grass.blockID);
		world.setBlock(i + 15, j + 0, k + 23, Block.grass.blockID);
		world.setBlock(i + 15, j + 0, k + 24, Block.grass.blockID);
		world.setBlock(i + 15, j + 0, k + 25, Block.grass.blockID);
		world.setBlock(i + 15, j + 0, k + 26, Block.grass.blockID);
		world.setBlock(i + 15, j + 0, k + 27, Block.grass.blockID);
		world.setBlock(i + 15, j + 0, k + 28, Block.grass.blockID);
		world.setBlock(i + 15, j + 0, k + 29, Block.grass.blockID);
		world.setBlock(i + 15, j + 0, k + 30, Block.dirt.blockID);
		world.setBlock(i + 15, j + 0, k + 31, Block.dirt.blockID);
		world.setBlock(i + 15, j + 0, k + 32, Block.grass.blockID);
		world.setBlock(i + 15, j + 0, k + 33, Block.grass.blockID);
		world.setBlock(i + 15, j + 0, k + 34, Block.grass.blockID);
		world.setBlock(i + 15, j + 0, k + 35, Block.grass.blockID);
		world.setBlock(i + 15, j + 0, k + 36, Block.stone.blockID);
		world.setBlock(i + 15, j + 0, k + 37, Block.stone.blockID);
		world.setBlock(i + 15, j + 0, k + 38, Block.stone.blockID);
		world.setBlock(i + 15, j + 0, k + 39, Block.stone.blockID);
		world.setBlock(i + 15, j + 0, k + 40, Block.stone.blockID);
		world.setBlock(i + 15, j + 0, k + 41, Block.stone.blockID);
		world.setBlock(i + 15, j + 0, k + 42, Block.grass.blockID);
		world.setBlock(i + 15, j + 0, k + 43, Block.grass.blockID);
		world.setBlock(i + 15, j + 0, k + 44, Block.dirt.blockID);
		world.setBlock(i + 15, j + 0, k + 45, Block.dirt.blockID);
		world.setBlock(i + 15, j + 0, k + 46, Block.dirt.blockID);
		world.setBlock(i + 15, j + 0, k + 47, Block.dirt.blockID);
		world.setBlock(i + 15, j + 0, k + 48, Block.grass.blockID);
		world.setBlock(i + 15, j + 1, k + 7, Block.stoneBrick.blockID);
		world.setBlock(i + 15, j + 1, k + 14, Block.grass.blockID);
		world.setBlock(i + 15, j + 1, k + 15, Block.stoneBrick.blockID);
		world.setBlock(i + 15, j + 1, k + 30, Block.stoneBrick.blockID);
		world.setBlock(i + 15, j + 1, k + 31, Block.grass.blockID);
		world.setBlock(i + 15, j + 1, k + 37, Block.stoneDoubleSlab.blockID);
		world.setBlock(i + 15, j + 1, k + 38, Block.stoneDoubleSlab.blockID);
		world.setBlock(i + 15, j + 1, k + 39, Block.stoneDoubleSlab.blockID);
		world.setBlock(i + 15, j + 1, k + 40, Block.stoneDoubleSlab.blockID);
		world.setBlock(i + 15, j + 1, k + 44, Block.stoneBrick.blockID);
		world.setBlock(i + 15, j + 1, k + 45, Block.stoneBrick.blockID);
		world.setBlock(i + 15, j + 1, k + 46, Block.stoneBrick.blockID);
		world.setBlock(i + 15, j + 1, k + 47, Block.stoneBrick.blockID);
		world.setBlock(i + 15, j + 2, k + 7, Block.stoneBrick.blockID);
		world.setBlock(i + 15, j + 2, k + 15, Block.stoneBrick.blockID);
		world.setBlock(i + 15, j + 2, k + 16, Block.cloth.blockID, 15, k);
		world.setBlock(i + 15, j + 2, k + 17, Block.cloth.blockID);
		world.setBlock(i + 15, j + 2, k + 18, Block.cloth.blockID, 15, k);
		world.setBlock(i + 15, j + 2, k + 19, Block.cloth.blockID);
		world.setBlock(i + 15, j + 2, k + 20, Block.cloth.blockID, 15, k);
		world.setBlock(i + 15, j + 2, k + 21, Block.cloth.blockID);
		world.setBlock(i + 15, j + 2, k + 22, Block.cloth.blockID, 15, k);
		world.setBlock(i + 15, j + 2, k + 23, Block.cloth.blockID);
		world.setBlock(i + 15, j + 2, k + 24, Block.cloth.blockID, 15, k);
		world.setBlock(i + 15, j + 2, k + 25, Block.cobblestone.blockID);
		world.setBlock(i + 15, j + 2, k + 26, Block.cobblestone.blockID);
		world.setBlock(i + 15, j + 2, k + 27, Block.cobblestone.blockID);
		world.setBlock(i + 15, j + 2, k + 28, Block.cobblestone.blockID);
		world.setBlock(i + 15, j + 2, k + 29, Block.cobblestone.blockID);
		world.setBlock(i + 15, j + 2, k + 30, Block.stoneBrick.blockID);
		world.setBlock(i + 15, j + 2, k + 44, Block.stoneBrick.blockID);
		world.setBlock(i + 15, j + 2, k + 45, Block.stoneBrick.blockID);
		world.setBlock(i + 15, j + 2, k + 46, Block.stoneBrick.blockID);
		world.setBlock(i + 15, j + 2, k + 47, Block.stoneBrick.blockID);
		world.setBlock(i + 15, j + 3, k + 7, Block.stoneBrick.blockID);
		world.setBlock(i + 15, j + 3, k + 15, Block.stoneBrick.blockID);
		world.setBlock(i + 15, j + 3, k + 16, Block.planks.blockID);
		world.setBlock(i + 15, j + 3, k + 23, Block.planks.blockID);
		world.setBlock(i + 15, j + 3, k + 24, Block.planks.blockID);
		world.setBlock(i + 15, j + 3, k + 25, Block.stoneBrick.blockID);
		world.setBlock(i + 15, j + 3, k + 26, Block.stoneBrick.blockID);
		world.setBlock(i + 15, j + 3, k + 27, Block.stoneBrick.blockID);
		world.setBlock(i + 15, j + 3, k + 29, Block.stoneBrick.blockID);
		world.setBlock(i + 15, j + 3, k + 30, Block.stoneBrick.blockID);
		world.setBlock(i + 15, j + 3, k + 44, Block.stoneBrick.blockID);
		world.setBlock(i + 15, j + 3, k + 45, Block.stoneBrick.blockID);
		world.setBlock(i + 15, j + 3, k + 46, Block.stoneBrick.blockID);
		world.setBlock(i + 15, j + 3, k + 47, Block.stoneBrick.blockID);
		world.setBlock(i + 15, j + 4, k + 7, Block.stoneBrick.blockID);
		world.setBlock(i + 15, j + 4, k + 15, Block.stoneBrick.blockID);
		world.setBlock(i + 15, j + 4, k + 20, Block.stoneSingleSlab.blockID, 2, k);
		world.setBlock(i + 15, j + 4, k + 21, Block.stoneSingleSlab.blockID, 2, k);
		world.setBlock(i + 15, j + 4, k + 25, Block.stoneBrick.blockID);
		world.setBlock(i + 15, j + 4, k + 26, Block.stoneBrick.blockID);
		world.setBlock(i + 15, j + 4, k + 27, Block.stoneBrick.blockID);
		world.setBlock(i + 15, j + 4, k + 29, Block.stoneBrick.blockID);
		world.setBlock(i + 15, j + 4, k + 30, Block.stoneBrick.blockID);
		world.setBlock(i + 15, j + 4, k + 44, Block.stoneBrick.blockID);
		world.setBlock(i + 15, j + 4, k + 45, Block.stoneBrick.blockID);
		world.setBlock(i + 15, j + 4, k + 46, Block.stoneBrick.blockID);
		world.setBlock(i + 15, j + 4, k + 47, Block.stoneBrick.blockID);
		world.setBlock(i + 15, j + 5, k + 7, Block.stairsStoneBrick.blockID);
		world.setBlock(i + 15, j + 5, k + 15, Block.stoneBrick.blockID);
		world.setBlock(i + 15, j + 5, k + 16, Block.cobblestone.blockID);
		world.setBlock(i + 15, j + 5, k + 17, Block.cobblestone.blockID);
		world.setBlock(i + 15, j + 5, k + 18, Block.cobblestone.blockID);
		world.setBlock(i + 15, j + 5, k + 19, Block.cobblestone.blockID);
		world.setBlock(i + 15, j + 5, k + 20, Block.cobblestone.blockID);
		world.setBlock(i + 15, j + 5, k + 21, Block.cobblestone.blockID);
		world.setBlock(i + 15, j + 5, k + 22, Block.cobblestone.blockID);
		world.setBlock(i + 15, j + 5, k + 23, Block.cobblestone.blockID);
		world.setBlock(i + 15, j + 5, k + 24, Block.cobblestone.blockID);
		world.setBlock(i + 15, j + 5, k + 25, Block.cobblestone.blockID);
		world.setBlock(i + 15, j + 5, k + 26, Block.stoneBrick.blockID);
		world.setBlock(i + 15, j + 5, k + 27, Block.cobblestone.blockID);
		world.setBlock(i + 15, j + 5, k + 28, Block.cobblestone.blockID);
		world.setBlock(i + 15, j + 5, k + 29, Block.cobblestone.blockID);
		world.setBlock(i + 15, j + 5, k + 30, Block.stoneBrick.blockID);
		world.setBlock(i + 15, j + 5, k + 44, Block.stairsStoneBrick.blockID, 1, k);
		world.setBlock(i + 15, j + 5, k + 45, Block.stoneBrick.blockID);
		world.setBlock(i + 15, j + 5, k + 46, Block.stoneSingleSlab.blockID, 5, k);
		world.setBlock(i + 15, j + 5, k + 47, Block.stoneBrick.blockID);
		world.setBlock(i + 15, j + 6, k + 15, Block.stoneBrick.blockID);
		world.setBlock(i + 15, j + 6, k + 19, Block.stoneBrick.blockID);
		world.setBlock(i + 15, j + 6, k + 21, Block.workbench.blockID);
		world.setBlock(i + 15, j + 6, k + 26, Block.stoneBrick.blockID);
		world.setBlock(i + 15, j + 6, k + 30, Block.stoneBrick.blockID);
		world.setBlock(i + 15, j + 7, k + 15, Block.stoneBrick.blockID);
		world.setBlock(i + 15, j + 7, k + 19, Block.stoneBrick.blockID);
		world.setBlock(i + 15, j + 7, k + 26, Block.stoneBrick.blockID);
		world.setBlock(i + 15, j + 8, k + 15, Block.stoneBrick.blockID);
		world.setBlock(i + 15, j + 8, k + 19, Block.stoneBrick.blockID);
		world.setBlock(i + 15, j + 8, k + 26, Block.stoneBrick.blockID);
		world.setBlock(i + 15, j + 9, k + 15, Block.stoneBrick.blockID);
		world.setBlock(i + 15, j + 9, k + 16, Block.cobblestone.blockID);
		world.setBlock(i + 15, j + 9, k + 17, Block.cobblestone.blockID);
		world.setBlock(i + 15, j + 9, k + 18, Block.cobblestone.blockID);
		world.setBlock(i + 15, j + 9, k + 19, Block.cobblestone.blockID);
		world.setBlock(i + 15, j + 9, k + 20, Block.cobblestone.blockID);
		world.setBlock(i + 15, j + 9, k + 21, Block.cobblestone.blockID);
		world.setBlock(i + 15, j + 9, k + 22, Block.cobblestone.blockID);
		world.setBlock(i + 15, j + 9, k + 23, Block.cobblestone.blockID);
		world.setBlock(i + 15, j + 9, k + 24, Block.cobblestone.blockID);
		world.setBlock(i + 15, j + 9, k + 25, Block.cobblestone.blockID);
		world.setBlock(i + 15, j + 9, k + 26, Block.stoneBrick.blockID);
		world.setBlock(i + 15, j + 10, k + 15, Block.stoneSingleSlab.blockID, 5, k);
		world.setBlock(i + 15, j + 10, k + 26, Block.stoneDoubleSlab.blockID, 5, k);
		world.setBlock(i + 16, j + 0, k + 0, Block.grass.blockID);
		world.setBlock(i + 16, j + 0, k + 1, Block.grass.blockID);
		world.setBlock(i + 16, j + 0, k + 2, Block.grass.blockID);
		world.setBlock(i + 16, j + 0, k + 3, Block.grass.blockID);
		world.setBlock(i + 16, j + 0, k + 4, Block.grass.blockID);
		world.setBlock(i + 16, j + 0, k + 5, Block.grass.blockID);
		world.setBlock(i + 16, j + 0, k + 6, Block.grass.blockID);
		world.setBlock(i + 16, j + 0, k + 7, Block.dirt.blockID);
		world.setBlock(i + 16, j + 0, k + 8, Block.grass.blockID);
		world.setBlock(i + 16, j + 0, k + 9, Block.grass.blockID);
		world.setBlock(i + 16, j + 0, k + 10, Block.grass.blockID);
		world.setBlock(i + 16, j + 0, k + 11, Block.grass.blockID);
		world.setBlock(i + 16, j + 0, k + 12, Block.grass.blockID);
		world.setBlock(i + 16, j + 0, k + 13, Block.grass.blockID);
		world.setBlock(i + 16, j + 0, k + 14, Block.dirt.blockID);
		world.setBlock(i + 16, j + 0, k + 15, Block.dirt.blockID);
		world.setBlock(i + 16, j + 0, k + 16, Block.grass.blockID);
		world.setBlock(i + 16, j + 0, k + 17, Block.grass.blockID);
		world.setBlock(i + 16, j + 0, k + 18, Block.grass.blockID);
		world.setBlock(i + 16, j + 0, k + 19, Block.grass.blockID);
		world.setBlock(i + 16, j + 0, k + 20, Block.grass.blockID);
		world.setBlock(i + 16, j + 0, k + 21, Block.grass.blockID);
		world.setBlock(i + 16, j + 0, k + 22, Block.grass.blockID);
		world.setBlock(i + 16, j + 0, k + 23, Block.grass.blockID);
		world.setBlock(i + 16, j + 0, k + 24, Block.grass.blockID);
		world.setBlock(i + 16, j + 0, k + 25, Block.grass.blockID);
		world.setBlock(i + 16, j + 0, k + 26, Block.grass.blockID);
		world.setBlock(i + 16, j + 0, k + 27, Block.grass.blockID);
		world.setBlock(i + 16, j + 0, k + 28, Block.grass.blockID);
		world.setBlock(i + 16, j + 0, k + 29, Block.grass.blockID);
		world.setBlock(i + 16, j + 0, k + 30, Block.dirt.blockID);
		world.setBlock(i + 16, j + 0, k + 31, Block.dirt.blockID);
		world.setBlock(i + 16, j + 0, k + 32, Block.grass.blockID);
		world.setBlock(i + 16, j + 0, k + 33, Block.grass.blockID);
		world.setBlock(i + 16, j + 0, k + 34, Block.grass.blockID);
		world.setBlock(i + 16, j + 0, k + 35, Block.grass.blockID);
		world.setBlock(i + 16, j + 0, k + 36, Block.stone.blockID);
		world.setBlock(i + 16, j + 0, k + 37, Block.stone.blockID);
		world.setBlock(i + 16, j + 0, k + 38, Block.stone.blockID);

		generate2(world, rand, i, j, k);
		return true;
		}
		return false;}
	

	public boolean generate2(World world, Random rand, int i, int j, int k) {
		
		world.setBlock(i + 16, j + 0, k + 39, Block.stone.blockID);
		world.setBlock(i + 16, j + 0, k + 40, Block.stone.blockID);
		world.setBlock(i + 16, j + 0, k + 41, Block.stone.blockID);
		world.setBlock(i + 16, j + 0, k + 42, Block.grass.blockID);
		world.setBlock(i + 16, j + 0, k + 43, Block.grass.blockID);
		world.setBlock(i + 16, j + 0, k + 44, Block.dirt.blockID);
		world.setBlock(i + 16, j + 0, k + 45, Block.cobblestone.blockID);
		world.setBlock(i + 16, j + 0, k + 46, Block.cobblestone.blockID);
		world.setBlock(i + 16, j + 0, k + 47, Block.cobblestone.blockID);
		world.setBlock(i + 16, j + 0, k + 48, Block.dirt.blockID);
		world.setBlock(i + 16, j + 1, k + 7, Block.stoneBrick.blockID);
		world.setBlock(i + 16, j + 1, k + 14, Block.grass.blockID);
		world.setBlock(i + 16, j + 1, k + 15, Block.stoneBrick.blockID);
		world.setBlock(i + 16, j + 1, k + 30, Block.stoneBrick.blockID);
		world.setBlock(i + 16, j + 1, k + 31, Block.grass.blockID);
		world.setBlock(i + 16, j + 1, k + 44, Block.stoneBrick.blockID);
		world.setBlock(i + 16, j + 1, k + 48, Block.stoneBrick.blockID);
		world.setBlock(i + 16, j + 2, k + 7, Block.stoneBrick.blockID);
		world.setBlock(i + 16, j + 2, k + 15, Block.stoneBrick.blockID);
		world.setBlock(i + 16, j + 2, k + 16, Block.cloth.blockID);
		world.setBlock(i + 16, j + 2, k + 17, Block.cloth.blockID, 15, k);
		world.setBlock(i + 16, j + 2, k + 18, Block.cloth.blockID);
