/*
*** MADE BY MITHION'S .SCHEMATIC TO JAVA CONVERTING TOOL v1.6 ***
*/

package net.minecraft.src;
import java.util.Random;

import net.minecraft.block.Block;
import net.minecraft.item.Item;
import net.minecraft.item.ItemStack;
import net.minecraft.tileentity.TileEntityChest;
import net.minecraft.util.WeightedRandomChestContent;
import net.minecraft.world.World;
import net.minecraft.world.gen.feature.WorldGenerator;

public class WorldGenCastle extends WorldGenerator
{

	
	private static final WeightedRandomChestContent[] bonusChestContent = new WeightedRandomChestContent[]
			{
		
			new WeightedRandomChestContent(mod_BlocksGalore.dlong.itemID, 0, 1, 1, 15),
			new WeightedRandomChestContent(mod_BlocksGalore.Zammystaff.itemID, 0, 1, 1, 45),
			new WeightedRandomChestContent(mod_BlocksGalore.BLKSpawn.blockID, 0, 1, 6, 50),
			new WeightedRandomChestContent(mod_BlocksGalore.EliteBlackSpawn.blockID, 0, 1, 6, 10),
			new WeightedRandomChestContent(Block.oreDiamond.blockID, 0, 1, 2, 30),
			new WeightedRandomChestContent(Item.swordStone.itemID, 0, 1, 4, 40),
			new WeightedRandomChestContent(Item.bow.itemID, 0, 1, 1, 20),
			new WeightedRandomChestContent(mod_MagicBow.Magicbow.itemID, 0, 1, 1, 10),
			new WeightedRandomChestContent(mod_phat.blackChestplate.itemID, 0, 1, 1, 30),
			new WeightedRandomChestContent(mod_phat.blackLeggings.itemID, 0, 1, 1, 30),
			new WeightedRandomChestContent(mod_phat.blackHelmet.itemID, 0, 1, 1, 30),
			new WeightedRandomChestContent(mod_phat.blackBoots.itemID, 0, 1, 1, 30),
			new WeightedRandomChestContent(Item.arrow.itemID, 500, 10, 20, 40),
			};



	public WorldGenCastle() { }

	public boolean generate(World world, Random rand, int i, int j, int k) {
	

		world.setBlock(i + 0, j + 0, k + 0, Block.obsidian.blockID);
		world.setBlock(i + 0, j + 0, k + 1, Block.obsidian.blockID);
		world.setBlock(i + 0, j + 0, k + 2, Block.obsidian.blockID);
		world.setBlock(i + 0, j + 0, k + 3, Block.obsidian.blockID);
		world.setBlock(i + 0, j + 0, k + 4, Block.obsidian.blockID);
		world.setBlock(i + 0, j + 0, k + 5, Block.obsidian.blockID);
		world.setBlock(i + 0, j + 0, k + 6, Block.obsidian.blockID);
		world.setBlock(i + 0, j + 0, k + 7, Block.obsidian.blockID);
		world.setBlock(i + 0, j + 0, k + 8, Block.obsidian.blockID);
		world.setBlock(i + 0, j + 0, k + 9, Block.obsidian.blockID);
		world.setBlock(i + 0, j + 0, k + 10, Block.obsidian.blockID);
		world.setBlock(i + 0, j + 0, k + 11, Block.obsidian.blockID);
		world.setBlock(i + 0, j + 0, k + 12, Block.obsidian.blockID);
		world.setBlock(i + 0, j + 0, k + 13, Block.obsidian.blockID);
		world.setBlock(i + 0, j + 0, k + 14, Block.obsidian.blockID);
		world.setBlock(i + 0, j + 0, k + 15, Block.obsidian.blockID);
		world.setBlock(i + 0, j + 0, k + 16, Block.obsidian.blockID);
		world.setBlock(i + 0, j + 0, k + 17, Block.planks.blockID);
		world.setBlock(i + 0, j + 0, k + 18, Block.planks.blockID);
		world.setBlock(i + 0, j + 0, k + 19, Block.planks.blockID);
		world.setBlock(i + 0, j + 0, k + 20, Block.planks.blockID);
		world.setBlock(i + 0, j + 0, k + 21, Block.planks.blockID);
		world.setBlock(i + 0, j + 0, k + 22, Block.planks.blockID);
		world.setBlock(i + 0, j + 0, k + 23, Block.planks.blockID);
		world.setBlock(i + 0, j + 0, k + 24, Block.planks.blockID);
		world.setBlock(i + 0, j + 0, k + 25, Block.planks.blockID);
		world.setBlock(i + 0, j + 0, k + 26, Block.planks.blockID);
		world.setBlock(i + 0, j + 0, k + 27, Block.planks.blockID);
		world.setBlock(i + 0, j + 0, k + 28, Block.planks.blockID);
		world.setBlock(i + 0, j + 0, k + 29, Block.planks.blockID);
		world.setBlock(i + 0, j + 0, k + 30, Block.planks.blockID);
		world.setBlock(i + 0, j + 0, k + 31, Block.planks.blockID);
		world.setBlock(i + 0, j + 0, k + 32, Block.planks.blockID);
		world.setBlock(i + 0, j + 0, k + 33, Block.planks.blockID);
		world.setBlock(i + 0, j + 0, k + 34, Block.planks.blockID);
		world.setBlock(i + 0, j + 0, k + 35, Block.planks.blockID);
		world.setBlock(i + 0, j + 0, k + 36, Block.planks.blockID);
		world.setBlock(i + 0, j + 0, k + 37, Block.obsidian.blockID);
		world.setBlock(i + 0, j + 0, k + 38, Block.obsidian.blockID);
		world.setBlock(i + 0, j + 0, k + 39, Block.obsidian.blockID);
		world.setBlock(i + 0, j + 0, k + 40, Block.obsidian.blockID);
		world.setBlock(i + 0, j + 0, k + 41, Block.obsidian.blockID);
		world.setBlock(i + 0, j + 0, k + 42, Block.obsidian.blockID);
		world.setBlock(i + 0, j + 0, k + 43, Block.obsidian.blockID);
		world.setBlock(i + 0, j + 0, k + 44, Block.obsidian.blockID);
		world.setBlock(i + 0, j + 0, k + 45, Block.obsidian.blockID);
		world.setBlock(i + 0, j + 0, k + 46, Block.obsidian.blockID);
		world.setBlock(i + 0, j + 0, k + 47, Block.obsidian.blockID);
		world.setBlock(i + 0, j + 0, k + 48, Block.obsidian.blockID);
		world.setBlock(i + 0, j + 0, k + 49, Block.obsidian.blockID);
		world.setBlock(i + 0, j + 0, k + 50, Block.obsidian.blockID);
		world.setBlock(i + 0, j + 0, k + 51, Block.obsidian.blockID);
		world.setBlock(i + 0, j + 0, k + 52, Block.obsidian.blockID);
		world.setBlock(i + 0, j + 0, k + 53, Block.obsidian.blockID);
		world.setBlock(i + 0, j + 0, k + 54, Block.obsidian.blockID);
		world.setBlock(i + 0, j + 0, k + 55, Block.obsidian.blockID);
		world.setBlock(i + 0, j + 1, k + 0, Block.obsidian.blockID);
		world.setBlock(i + 0, j + 1, k + 1, Block.obsidian.blockID);
		world.setBlock(i + 0, j + 1, k + 2, Block.obsidian.blockID);
		world.setBlock(i + 0, j + 1, k + 3, Block.obsidian.blockID);
		world.setBlock(i + 0, j + 1, k + 4, Block.obsidian.blockID);
		world.setBlock(i + 0, j + 1, k + 5, Block.obsidian.blockID);
		world.setBlock(i + 0, j + 1, k + 6, Block.obsidian.blockID);
		world.setBlock(i + 0, j + 1, k + 7, Block.obsidian.blockID);
		world.setBlock(i + 0, j + 1, k + 8, Block.obsidian.blockID);
		world.setBlock(i + 0, j + 1, k + 9, Block.obsidian.blockID);
		world.setBlock(i + 0, j + 1, k + 10, Block.obsidian.blockID);
		world.setBlock(i + 0, j + 1, k + 11, Block.obsidian.blockID);
		world.setBlock(i + 0, j + 1, k + 12, Block.obsidian.blockID);
		world.setBlock(i + 0, j + 1, k + 13, Block.obsidian.blockID);
		world.setBlock(i + 0, j + 1, k + 14, Block.obsidian.blockID);
		world.setBlock(i + 0, j + 1, k + 15, Block.obsidian.blockID);
		world.setBlock(i + 0, j + 1, k + 16, Block.obsidian.blockID);
		world.setBlock(i + 0, j + 1, k + 37, Block.obsidian.blockID);
		world.setBlock(i + 0, j + 1, k + 38, Block.obsidian.blockID);
		world.setBlock(i + 0, j + 1, k + 39, Block.obsidian.blockID);
		world.setBlock(i + 0, j + 1, k + 40, Block.obsidian.blockID);
		world.setBlock(i + 0, j + 1, k + 41, Block.obsidian.blockID);
		world.setBlock(i + 0, j + 1, k + 42, Block.obsidian.blockID);
		world.setBlock(i + 0, j + 1, k + 43, Block.obsidian.blockID);
		world.setBlock(i + 0, j + 1, k + 44, Block.obsidian.blockID);
		world.setBlock(i + 0, j + 1, k + 45, Block.obsidian.blockID);
		world.setBlock(i + 0, j + 1, k + 46, Block.obsidian.blockID);
		world.setBlock(i + 0, j + 1, k + 47, Block.obsidian.blockID);
		world.setBlock(i + 0, j + 1, k + 48, Block.obsidian.blockID);
		world.setBlock(i + 0, j + 1, k + 49, Block.obsidian.blockID);
		world.setBlock(i + 0, j + 1, k + 50, Block.obsidian.blockID);
		world.setBlock(i + 0, j + 1, k + 51, Block.obsidian.blockID);
		world.setBlock(i + 0, j + 1, k + 52, Block.obsidian.blockID);
		world.setBlock(i + 0, j + 1, k + 53, Block.obsidian.blockID);
		world.setBlock(i + 0, j + 1, k + 54, Block.obsidian.blockID);
		world.setBlock(i + 0, j + 1, k + 55, Block.obsidian.blockID);
		world.setBlock(i + 0, j + 2, k + 0, Block.obsidian.blockID);
		world.setBlock(i + 0, j + 2, k + 1, Block.obsidian.blockID);
		world.setBlock(i + 0, j + 2, k + 2, Block.obsidian.blockID);
		world.setBlock(i + 0, j + 2, k + 3, Block.obsidian.blockID);
		world.setBlock(i + 0, j + 2, k + 4, Block.obsidian.blockID);
		world.setBlock(i + 0, j + 2, k + 5, Block.obsidian.blockID);
		world.setBlock(i + 0, j + 2, k + 6, Block.obsidian.blockID);
		world.setBlock(i + 0, j + 2, k + 7, Block.obsidian.blockID);
		world.setBlock(i + 0, j + 2, k + 8, Block.obsidian.blockID);
		world.setBlock(i + 0, j + 2, k + 9, Block.obsidian.blockID);
		world.setBlock(i + 0, j + 2, k + 10, Block.obsidian.blockID);
		world.setBlock(i + 0, j + 2, k + 11, Block.obsidian.blockID);
		world.setBlock(i + 0, j + 2, k + 12, Block.obsidian.blockID);
		world.setBlock(i + 0, j + 2, k + 13, Block.obsidian.blockID);
		world.setBlock(i + 0, j + 2, k + 14, Block.obsidian.blockID);
		world.setBlock(i + 0, j + 2, k + 15, Block.obsidian.blockID);
		world.setBlock(i + 0, j + 2, k + 16, Block.obsidian.blockID);
		world.setBlock(i + 0, j + 2, k + 37, Block.obsidian.blockID);
		world.setBlock(i + 0, j + 2, k + 38, Block.obsidian.blockID);
		world.setBlock(i + 0, j + 2, k + 39, Block.obsidian.blockID);
		world.setBlock(i + 0, j + 2, k + 40, Block.obsidian.blockID);
		world.setBlock(i + 0, j + 2, k + 41, Block.obsidian.blockID);
		world.setBlock(i + 0, j + 2, k + 42, Block.obsidian.blockID);
		world.setBlock(i + 0, j + 2, k + 43, Block.obsidian.blockID);
		world.setBlock(i + 0, j + 2, k + 44, Block.obsidian.blockID);
		world.setBlock(i + 0, j + 2, k + 45, Block.obsidian.blockID);
		world.setBlock(i + 0, j + 2, k + 46, Block.obsidian.blockID);
		world.setBlock(i + 0, j + 2, k + 47, Block.obsidian.blockID);
		world.setBlock(i + 0, j + 2, k + 48, Block.obsidian.blockID);
		world.setBlock(i + 0, j + 2, k + 49, Block.obsidian.blockID);
		world.setBlock(i + 0, j + 2, k + 50, Block.obsidian.blockID);
		world.setBlock(i + 0, j + 2, k + 51, Block.obsidian.blockID);
		world.setBlock(i + 0, j + 2, k + 52, Block.obsidian.blockID);
		world.setBlock(i + 0, j + 2, k + 53, Block.obsidian.blockID);
		world.setBlock(i + 0, j + 2, k + 54, Block.obsidian.blockID);
		world.setBlock(i + 0, j + 2, k + 55, Block.obsidian.blockID);
		world.setBlock(i + 0, j + 3, k + 0, Block.obsidian.blockID);
		world.setBlock(i + 0, j + 3, k + 1, Block.obsidian.blockID);
		world.setBlock(i + 0, j + 3, k + 2, Block.obsidian.blockID);
		world.setBlock(i + 0, j + 3, k + 3, Block.obsidian.blockID);
		world.setBlock(i + 0, j + 3, k + 4, Block.obsidian.blockID);
		world.setBlock(i + 0, j + 3, k + 5, Block.obsidian.blockID);
		world.setBlock(i + 0, j + 3, k + 6, Block.obsidian.blockID);
		world.setBlock(i + 0, j + 3, k + 7, Block.obsidian.blockID);
		world.setBlock(i + 0, j + 3, k + 8, Block.obsidian.blockID);
		world.setBlock(i + 0, j + 3, k + 9, Block.obsidian.blockID);
		world.setBlock(i + 0, j + 3, k + 10, Block.obsidian.blockID);
		world.setBlock(i + 0, j + 3, k + 11, Block.obsidian.blockID);
		world.setBlock(i + 0, j + 3, k + 12, Block.obsidian.blockID);
		world.setBlock(i + 0, j + 3, k + 13, Block.obsidian.blockID);
		world.setBlock(i + 0, j + 3, k + 14, Block.obsidian.blockID);
		world.setBlock(i + 0, j + 3, k + 15, Block.obsidian.blockID);
		world.setBlock(i + 0, j + 3, k + 16, Block.obsidian.blockID);
		world.setBlock(i + 0, j + 3, k + 37, Block.obsidian.blockID);
		world.setBlock(i + 0, j + 3, k + 38, Block.obsidian.blockID);
		world.setBlock(i + 0, j + 3, k + 39, Block.obsidian.blockID);
		world.setBlock(i + 0, j + 3, k + 40, Block.obsidian.blockID);
		world.setBlock(i + 0, j + 3, k + 41, Block.obsidian.blockID);
		world.setBlock(i + 0, j + 3, k + 42, Block.obsidian.blockID);
		world.setBlock(i + 0, j + 3, k + 43, Block.obsidian.blockID);
		world.setBlock(i + 0, j + 3, k + 44, Block.obsidian.blockID);
		world.setBlock(i + 0, j + 3, k + 45, Block.obsidian.blockID);
		world.setBlock(i + 0, j + 3, k + 46, Block.obsidian.blockID);
		world.setBlock(i + 0, j + 3, k + 47, Block.obsidian.blockID);
		world.setBlock(i + 0, j + 3, k + 48, Block.obsidian.blockID);
		world.setBlock(i + 0, j + 3, k + 49, Block.obsidian.blockID);
		world.setBlock(i + 0, j + 3, k + 50, Block.obsidian.blockID);
		world.setBlock(i + 0, j + 3, k + 51, Block.obsidian.blockID);
		world.setBlock(i + 0, j + 3, k + 52, Block.obsidian.blockID);
		world.setBlock(i + 0, j + 3, k + 53, Block.obsidian.blockID);
		world.setBlock(i + 0, j + 3, k + 54, Block.obsidian.blockID);
		world.setBlock(i + 0, j + 3, k + 55, Block.obsidian.blockID);
		world.setBlock(i + 0, j + 4, k + 0, Block.obsidian.blockID);
		world.setBlock(i + 0, j + 4, k + 1, Block.obsidian.blockID);
		world.setBlock(i + 0, j + 4, k + 2, Block.obsidian.blockID);
		world.setBlock(i + 0, j + 4, k + 3, Block.obsidian.blockID);
		world.setBlock(i + 0, j + 4, k + 4, Block.obsidian.blockID);
		world.setBlock(i + 0, j + 4, k + 5, Block.obsidian.blockID);
		world.setBlock(i + 0, j + 4, k + 6, Block.obsidian.blockID);
		world.setBlock(i + 0, j + 4, k + 7, Block.obsidian.blockID);
		world.setBlock(i + 0, j + 4, k + 8, Block.obsidian.blockID);
		world.setBlock(i + 0, j + 4, k + 9, Block.obsidian.blockID);
		world.setBlock(i + 0, j + 4, k + 10, Block.obsidian.blockID);
		world.setBlock(i + 0, j + 4, k + 11, Block.obsidian.blockID);
		world.setBlock(i + 0, j + 4, k + 12, Block.obsidian.blockID);
		world.setBlock(i + 0, j + 4, k + 13, Block.obsidian.blockID);
		world.setBlock(i + 0, j + 4, k + 14, Block.obsidian.blockID);
		world.setBlock(i + 0, j + 4, k + 15, Block.obsidian.blockID);
		world.setBlock(i + 0, j + 4, k + 16, Block.obsidian.blockID);
		world.setBlock(i + 0, j + 4, k + 37, Block.obsidian.blockID);
		world.setBlock(i + 0, j + 4, k + 38, Block.obsidian.blockID);
		world.setBlock(i + 0, j + 4, k + 39, Block.obsidian.blockID);
		world.setBlock(i + 0, j + 4, k + 40, Block.obsidian.blockID);
		world.setBlock(i + 0, j + 4, k + 41, Block.obsidian.blockID);
		world.setBlock(i + 0, j + 4, k + 42, Block.obsidian.blockID);
		world.setBlock(i + 0, j + 4, k + 43, Block.obsidian.blockID);
		world.setBlock(i + 0, j + 4, k + 44, Block.obsidian.blockID);
		world.setBlock(i + 0, j + 4, k + 45, Block.obsidian.blockID);
		world.setBlock(i + 0, j + 4, k + 46, Block.obsidian.blockID);
		world.setBlock(i + 0, j + 4, k + 47, Block.obsidian.blockID);
		world.setBlock(i + 0, j + 4, k + 48, Block.obsidian.blockID);
		world.setBlock(i + 0, j + 4, k + 49, Block.obsidian.blockID);
		world.setBlock(i + 0, j + 4, k + 50, Block.obsidian.blockID);
		world.setBlock(i + 0, j + 4, k + 51, Block.obsidian.blockID);
		world.setBlock(i + 0, j + 4, k + 52, Block.obsidian.blockID);
		world.setBlock(i + 0, j + 4, k + 53, Block.obsidian.blockID);
		world.setBlock(i + 0, j + 4, k + 54, Block.obsidian.blockID);
		world.setBlock(i + 0, j + 4, k + 55, Block.obsidian.blockID);
		world.setBlock(i + 0, j + 5, k + 0, Block.obsidian.blockID);
		world.setBlock(i + 0, j + 5, k + 1, Block.obsidian.blockID);
		world.setBlock(i + 0, j + 5, k + 2, Block.obsidian.blockID);
		world.setBlock(i + 0, j + 5, k + 3, Block.obsidian.blockID);
		world.setBlock(i + 0, j + 5, k + 4, Block.obsidian.blockID);
		world.setBlock(i + 0, j + 5, k + 5, Block.obsidian.blockID);
		world.setBlock(i + 0, j + 5, k + 6, Block.obsidian.blockID);
		world.setBlock(i + 0, j + 5, k + 7, Block.obsidian.blockID);
		world.setBlock(i + 0, j + 5, k + 8, Block.obsidian.blockID);
		world.setBlock(i + 0, j + 5, k + 9, Block.obsidian.blockID);
		world.setBlock(i + 0, j + 5, k + 10, Block.obsidian.blockID);
		world.setBlock(i + 0, j + 5, k + 11, Block.obsidian.blockID);
		world.setBlock(i + 0, j + 5, k + 12, Block.obsidian.blockID);
		world.setBlock(i + 0, j + 5, k + 13, Block.obsidian.blockID);
		world.setBlock(i + 0, j + 5, k + 14, Block.obsidian.blockID);
		world.setBlock(i + 0, j + 5, k + 15, Block.obsidian.blockID);
		world.setBlock(i + 0, j + 5, k + 16, Block.obsidian.blockID);
		world.setBlock(i + 0, j + 5, k + 37, Block.obsidian.blockID);
		world.setBlock(i + 0, j + 5, k + 38, Block.obsidian.blockID);
		world.setBlock(i + 0, j + 5, k + 39, Block.obsidian.blockID);
		world.setBlock(i + 0, j + 5, k + 40, Block.obsidian.blockID);
		world.setBlock(i + 0, j + 5, k + 41, Block.obsidian.blockID);
		world.setBlock(i + 0, j + 5, k + 42, Block.obsidian.blockID);
		world.setBlock(i + 0, j + 5, k + 43, Block.obsidian.blockID);
		world.setBlock(i + 0, j + 5, k + 44, Block.obsidian.blockID);
		world.setBlock(i + 0, j + 5, k + 45, Block.obsidian.blockID);
		world.setBlock(i + 0, j + 5, k + 46, Block.obsidian.blockID);
		world.setBlock(i + 0, j + 5, k + 47, Block.obsidian.blockID);
		world.setBlock(i + 0, j + 5, k + 48, Block.obsidian.blockID);
		world.setBlock(i + 0, j + 5, k + 49, Block.obsidian.blockID);
		world.setBlock(i + 0, j + 5, k + 50, Block.obsidian.blockID);
		world.setBlock(i + 0, j + 5, k + 51, Block.obsidian.blockID);
		world.setBlock(i + 0, j + 5, k + 52, Block.obsidian.blockID);
		world.setBlock(i + 0, j + 5, k + 53, Block.obsidian.blockID);
		world.setBlock(i + 0, j + 5, k + 54, Block.obsidian.blockID);
		world.setBlock(i + 0, j + 5, k + 55, Block.obsidian.blockID);
		world.setBlock(i + 0, j + 6, k + 0, Block.obsidian.blockID);
		world.setBlock(i + 0, j + 6, k + 1, Block.obsidian.blockID);
		world.setBlock(i + 0, j + 6, k + 2, Block.obsidian.blockID);
		world.setBlock(i + 0, j + 6, k + 3, Block.obsidian.blockID);
		world.setBlock(i + 0, j + 6, k + 4, Block.obsidian.blockID);
		world.setBlock(i + 0, j + 6, k + 5, Block.obsidian.blockID);
		world.setBlock(i + 0, j + 6, k + 6, Block.obsidian.blockID);
		world.setBlock(i + 0, j + 6, k + 7, Block.obsidian.blockID);
		world.setBlock(i + 0, j + 6, k + 8, Block.obsidian.blockID);
		world.setBlock(i + 0, j + 6, k + 9, Block.obsidian.blockID);
		world.setBlock(i + 0, j + 6, k + 10, Block.obsidian.blockID);
		world.setBlock(i + 0, j + 6, k + 11, Block.obsidian.blockID);
		world.setBlock(i + 0, j + 6, k + 12, Block.obsidian.blockID);
		world.setBlock(i + 0, j + 6, k + 13, Block.obsidian.blockID);
		world.setBlock(i + 0, j + 6, k + 14, Block.obsidian.blockID);
		world.setBlock(i + 0, j + 6, k + 15, Block.obsidian.blockID);
		world.setBlock(i + 0, j + 6, k + 16, Block.obsidian.blockID);
		world.setBlock(i + 0, j + 6, k + 37, Block.obsidian.blockID);
		world.setBlock(i + 0, j + 6, k + 38, Block.obsidian.blockID);
		world.setBlock(i + 0, j + 6, k + 39, Block.obsidian.blockID);
		world.setBlock(i + 0, j + 6, k + 40, Block.obsidian.blockID);
		world.setBlock(i + 0, j + 6, k + 41, Block.obsidian.blockID);
		world.setBlock(i + 0, j + 6, k + 42, Block.obsidian.blockID);
		world.setBlock(i + 0, j + 6, k + 43, Block.obsidian.blockID);
		world.setBlock(i + 0, j + 6, k + 44, Block.obsidian.blockID);
		world.setBlock(i + 0, j + 6, k + 45, Block.obsidian.blockID);
		world.setBlock(i + 0, j + 6, k + 46, Block.obsidian.blockID);
		world.setBlock(i + 0, j + 6, k + 47, Block.obsidian.blockID);
		world.setBlock(i + 0, j + 6, k + 48, Block.obsidian.blockID);
		world.setBlock(i + 0, j + 6, k + 49, Block.obsidian.blockID);
		world.setBlock(i + 0, j + 6, k + 50, Block.obsidian.blockID);
		world.setBlock(i + 0, j + 6, k + 51, Block.obsidian.blockID);
		world.setBlock(i + 0, j + 6, k + 52, Block.obsidian.blockID);
		world.setBlock(i + 0, j + 6, k + 53, Block.obsidian.blockID);
		world.setBlock(i + 0, j + 6, k + 54, Block.obsidian.blockID);
		world.setBlock(i + 0, j + 6, k + 55, Block.obsidian.blockID);
		world.setBlock(i + 0, j + 7, k + 0, Block.obsidian.blockID);
		world.setBlock(i + 0, j + 7, k + 1, Block.obsidian.blockID);
		world.setBlock(i + 0, j + 7, k + 2, Block.obsidian.blockID);
		world.setBlock(i + 0, j + 7, k + 3, Block.obsidian.blockID);
		world.setBlock(i + 0, j + 7, k + 4, Block.obsidian.blockID);
		world.setBlock(i + 0, j + 7, k + 5, Block.obsidian.blockID);
		world.setBlock(i + 0, j + 7, k + 6, Block.obsidian.blockID);
		world.setBlock(i + 0, j + 7, k + 7, Block.obsidian.blockID);
		world.setBlock(i + 0, j + 7, k + 8, Block.obsidian.blockID);
		world.setBlock(i + 0, j + 7, k + 9, Block.obsidian.blockID);
		world.setBlock(i + 0, j + 7, k + 10, Block.obsidian.blockID);
		world.setBlock(i + 0, j + 7, k + 11, Block.obsidian.blockID);
		world.setBlock(i + 0, j + 7, k + 12, Block.obsidian.blockID);
		world.setBlock(i + 0, j + 7, k + 13, Block.obsidian.blockID);
		world.setBlock(i + 0, j + 7, k + 14, Block.obsidian.blockID);
		world.setBlock(i + 0, j + 7, k + 15, Block.obsidian.blockID);
		world.setBlock(i + 0, j + 7, k + 16, Block.obsidian.blockID);
		world.setBlock(i + 0, j + 7, k + 37, Block.obsidian.blockID);
		world.setBlock(i + 0, j + 7, k + 38, Block.obsidian.blockID);
		world.setBlock(i + 0, j + 7, k + 39, Block.obsidian.blockID);
		world.setBlock(i + 0, j + 7, k + 40, Block.obsidian.blockID);
		world.setBlock(i + 0, j + 7, k + 41, Block.obsidian.blockID);
		world.setBlock(i + 0, j + 7, k + 42, Block.obsidian.blockID);
		world.setBlock(i + 0, j + 7, k + 43, Block.obsidian.blockID);
		world.setBlock(i + 0, j + 7, k + 44, Block.obsidian.blockID);
		world.setBlock(i + 0, j + 7, k + 45, Block.obsidian.blockID);
		world.setBlock(i + 0, j + 7, k + 46, Block.obsidian.blockID);
		world.setBlock(i + 0, j + 7, k + 47, Block.obsidian.blockID);
		world.setBlock(i + 0, j + 7, k + 48, Block.obsidian.blockID);
		world.setBlock(i + 0, j + 7, k + 49, Block.obsidian.blockID);
		world.setBlock(i + 0, j + 7, k + 50, Block.obsidian.blockID);
		world.setBlock(i + 0, j + 7, k + 51, Block.obsidian.blockID);
		world.setBlock(i + 0, j + 7, k + 52, Block.obsidian.blockID);
		world.setBlock(i + 0, j + 7, k + 53, Block.obsidian.blockID);
		world.setBlock(i + 0, j + 7, k + 54, Block.obsidian.blockID);
		world.setBlock(i + 0, j + 7, k + 55, Block.obsidian.blockID);
		world.setBlock(i + 0, j + 8, k + 0, Block.obsidian.blockID);
		world.setBlock(i + 0, j + 8, k + 1, Block.obsidian.blockID);
		world.setBlock(i + 0, j + 8, k + 2, Block.obsidian.blockID);
		world.setBlock(i + 0, j + 8, k + 3, Block.obsidian.blockID);
		world.setBlock(i + 0, j + 8, k + 4, Block.obsidian.blockID);
		world.setBlock(i + 0, j + 8, k + 5, Block.obsidian.blockID);
		world.setBlock(i + 0, j + 8, k + 6, Block.obsidian.blockID);
		world.setBlock(i + 0, j + 8, k + 7, Block.obsidian.blockID);
		world.setBlock(i + 0, j + 8, k + 8, Block.obsidian.blockID);
		world.setBlock(i + 0, j + 8, k + 9, Block.obsidian.blockID);
		world.setBlock(i + 0, j + 8, k + 10, Block.obsidian.blockID);
		world.setBlock(i + 0, j + 8, k + 11, Block.obsidian.blockID);
		world.setBlock(i + 0, j + 8, k + 12, Block.obsidian.blockID);
		world.setBlock(i + 0, j + 8, k + 13, Block.obsidian.blockID);
		world.setBlock(i + 0, j + 8, k + 14, Block.obsidian.blockID);
		world.setBlock(i + 0, j + 8, k + 15, Block.obsidian.blockID);
		world.setBlock(i + 0, j + 8, k + 16, Block.obsidian.blockID);
		world.setBlock(i + 0, j + 8, k + 37, Block.obsidian.blockID);
		world.setBlock(i + 0, j + 8, k + 38, Block.obsidian.blockID);
		world.setBlock(i + 0, j + 8, k + 39, Block.obsidian.blockID);
		world.setBlock(i + 0, j + 8, k + 40, Block.obsidian.blockID);
		world.setBlock(i + 0, j + 8, k + 41, Block.obsidian.blockID);
		world.setBlock(i + 0, j + 8, k + 42, Block.obsidian.blockID);
		world.setBlock(i + 0, j + 8, k + 43, Block.obsidian.blockID);
		world.setBlock(i + 0, j + 8, k + 44, Block.obsidian.blockID);
		world.setBlock(i + 0, j + 8, k + 45, Block.obsidian.blockID);
		world.setBlock(i + 0, j + 8, k + 46, Block.obsidian.blockID);
		world.setBlock(i + 0, j + 8, k + 47, Block.obsidian.blockID);
		world.setBlock(i + 0, j + 8, k + 48, Block.obsidian.blockID);
		world.setBlock(i + 0, j + 8, k + 49, Block.obsidian.blockID);
		world.setBlock(i + 0, j + 8, k + 50, Block.obsidian.blockID);
		world.setBlock(i + 0, j + 8, k + 51, Block.obsidian.blockID);
		world.setBlock(i + 0, j + 8, k + 52, Block.obsidian.blockID);
		world.setBlock(i + 0, j + 8, k + 53, Block.obsidian.blockID);
		world.setBlock(i + 0, j + 8, k + 54, Block.obsidian.blockID);
		world.setBlock(i + 0, j + 8, k + 55, Block.obsidian.blockID);
		world.setBlock(i + 0, j + 9, k + 0, Block.obsidian.blockID);
		world.setBlock(i + 0, j + 9, k + 1, Block.obsidian.blockID);
		world.setBlock(i + 0, j + 9, k + 2, Block.obsidian.blockID);
		world.setBlock(i + 0, j + 9, k + 3, Block.obsidian.blockID);
		world.setBlock(i + 0, j + 9, k + 4, Block.obsidian.blockID);
		world.setBlock(i + 0, j + 9, k + 5, Block.obsidian.blockID);
		world.setBlock(i + 0, j + 9, k + 6, Block.obsidian.blockID);
		world.setBlock(i + 0, j + 9, k + 7, Block.obsidian.blockID);
		world.setBlock(i + 0, j + 9, k + 8, Block.obsidian.blockID);
		world.setBlock(i + 0, j + 9, k + 9, Block.obsidian.blockID);
		world.setBlock(i + 0, j + 9, k + 10, Block.obsidian.blockID);
		world.setBlock(i + 0, j + 9, k + 11, Block.obsidian.blockID);
		world.setBlock(i + 0, j + 9, k + 12, Block.obsidian.blockID);
		world.setBlock(i + 0, j + 9, k + 13, Block.obsidian.blockID);
		world.setBlock(i + 0, j + 9, k + 14, Block.obsidian.blockID);
		world.setBlock(i + 0, j + 9, k + 15, Block.obsidian.blockID);
		world.setBlock(i + 0, j + 9, k + 16, Block.obsidian.blockID);
		world.setBlock(i + 0, j + 9, k + 37, Block.obsidian.blockID);
		world.setBlock(i + 0, j + 9, k + 38, Block.obsidian.blockID);
		world.setBlock(i + 0, j + 9, k + 39, Block.obsidian.blockID);
		world.setBlock(i + 0, j + 9, k + 40, Block.obsidian.blockID);
		world.setBlock(i + 0, j + 9, k + 41, Block.obsidian.blockID);
		world.setBlock(i + 0, j + 9, k + 42, Block.obsidian.blockID);
		world.setBlock(i + 0, j + 9, k + 43, Block.obsidian.blockID);
		world.setBlock(i + 0, j + 9, k + 44, Block.obsidian.blockID);
		world.setBlock(i + 0, j + 9, k + 45, Block.obsidian.blockID);
		world.setBlock(i + 0, j + 9, k + 46, Block.obsidian.blockID);
		world.setBlock(i + 0, j + 9, k + 47, Block.obsidian.blockID);
		world.setBlock(i + 0, j + 9, k + 48, Block.obsidian.blockID);
		world.setBlock(i + 0, j + 9, k + 49, Block.obsidian.blockID);
		world.setBlock(i + 0, j + 9, k + 50, Block.obsidian.blockID);
		world.setBlock(i + 0, j + 9, k + 51, Block.obsidian.blockID);
		world.setBlock(i + 0, j + 9, k + 52, Block.obsidian.blockID);
		world.setBlock(i + 0, j + 9, k + 53, Block.obsidian.blockID);
		world.setBlock(i + 0, j + 9, k + 54, Block.obsidian.blockID);
		world.setBlock(i + 0, j + 9, k + 55, Block.obsidian.blockID);
		world.setBlock(i + 0, j + 10, k + 0, Block.obsidian.blockID);
		world.setBlock(i + 0, j + 10, k + 1, Block.obsidian.blockID);
		world.setBlock(i + 0, j + 10, k + 2, Block.obsidian.blockID);
		world.setBlock(i + 0, j + 10, k + 3, Block.obsidian.blockID);
		world.setBlock(i + 0, j + 10, k + 4, Block.obsidian.blockID);
		world.setBlock(i + 0, j + 10, k + 5, Block.obsidian.blockID);
		world.setBlock(i + 0, j + 10, k + 6, Block.obsidian.blockID);
		world.setBlock(i + 0, j + 10, k + 7, Block.obsidian.blockID);
		world.setBlock(i + 0, j + 10, k + 8, Block.obsidian.blockID);
		world.setBlock(i + 0, j + 10, k + 9, Block.obsidian.blockID);
		world.setBlock(i + 0, j + 10, k + 10, Block.obsidian.blockID);
		world.setBlock(i + 0, j + 10, k + 11, Block.obsidian.blockID);
		world.setBlock(i + 0, j + 10, k + 12, Block.obsidian.blockID);
		world.setBlock(i + 0, j + 10, k + 13, Block.obsidian.blockID);
		world.setBlock(i + 0, j + 10, k + 14, Block.obsidian.blockID);
		world.setBlock(i + 0, j + 10, k + 15, Block.obsidian.blockID);
		world.setBlock(i + 0, j + 10, k + 16, Block.obsidian.blockID);
		world.setBlock(i + 0, j + 10, k + 37, Block.obsidian.blockID);
		world.setBlock(i + 0, j + 10, k + 38, Block.obsidian.blockID);
		world.setBlock(i + 0, j + 10, k + 39, Block.obsidian.blockID);
		world.setBlock(i + 0, j + 10, k + 40, Block.obsidian.blockID);
		world.setBlock(i + 0, j + 10, k + 41, Block.obsidian.blockID);
		world.setBlock(i + 0, j + 10, k + 42, Block.obsidian.blockID);
		world.setBlock(i + 0, j + 10, k + 43, Block.obsidian.blockID);
		world.setBlock(i + 0, j + 10, k + 44, Block.obsidian.blockID);
		world.setBlock(i + 0, j + 10, k + 45, Block.obsidian.blockID);
		world.setBlock(i + 0, j + 10, k + 46, Block.obsidian.blockID);
		world.setBlock(i + 0, j + 10, k + 47, Block.obsidian.blockID);
		world.setBlock(i + 0, j + 10, k + 48, Block.obsidian.blockID);
		world.setBlock(i + 0, j + 10, k + 49, Block.obsidian.blockID);
		world.setBlock(i + 0, j + 10, k + 50, Block.obsidian.blockID);
		world.setBlock(i + 0, j + 10, k + 51, Block.obsidian.blockID);
		world.setBlock(i + 0, j + 10, k + 52, Block.obsidian.blockID);
		world.setBlock(i + 0, j + 10, k + 53, Block.obsidian.blockID);
		world.setBlock(i + 0, j + 10, k + 54, Block.obsidian.blockID);
		world.setBlock(i + 0, j + 10, k + 55, Block.obsidian.blockID);
		world.setBlock(i + 0, j + 11, k + 0, Block.obsidian.blockID);
		world.setBlock(i + 0, j + 11, k + 1, Block.obsidian.blockID);
		world.setBlock(i + 0, j + 11, k + 2, Block.obsidian.blockID);
		world.setBlock(i + 0, j + 11, k + 3, Block.obsidian.blockID);
		world.setBlock(i + 0, j + 11, k + 4, Block.obsidian.blockID);
		world.setBlock(i + 0, j + 11, k + 5, Block.obsidian.blockID);
		world.setBlock(i + 0, j + 11, k + 6, Block.obsidian.blockID);
		world.setBlock(i + 0, j + 11, k + 7, Block.obsidian.blockID);
		world.setBlock(i + 0, j + 11, k + 8, Block.obsidian.blockID);
		world.setBlock(i + 0, j + 11, k + 9, Block.obsidian.blockID);
		world.setBlock(i + 0, j + 11, k + 10, Block.obsidian.blockID);
		world.setBlock(i + 0, j + 11, k + 11, Block.obsidian.blockID);
		world.setBlock(i + 0, j + 11, k + 12, Block.obsidian.blockID);
		world.setBlock(i + 0, j + 11, k + 13, Block.obsidian.blockID);
		world.setBlock(i + 0, j + 11, k + 14, Block.obsidian.blockID);
		world.setBlock(i + 0, j + 11, k + 15, Block.obsidian.blockID);
		world.setBlock(i + 0, j + 11, k + 16, Block.obsidian.blockID);
		world.setBlock(i + 0, j + 11, k + 17, Block.obsidian.blockID);
		world.setBlock(i + 0, j + 11, k + 18, Block.obsidian.blockID);
		world.setBlock(i + 0, j + 11, k + 19, Block.obsidian.blockID);
		world.setBlock(i + 0, j + 11, k + 20, Block.obsidian.blockID);
		world.setBlock(i + 0, j + 11, k + 21, Block.obsidian.blockID);
		world.setBlock(i + 0, j + 11, k + 22, Block.obsidian.blockID);
		world.setBlock(i + 0, j + 11, k + 23, Block.obsidian.blockID);
		world.setBlock(i + 0, j + 11, k + 24, Block.obsidian.blockID);
		world.setBlock(i + 0, j + 11, k + 25, Block.obsidian.blockID);
		world.setBlock(i + 0, j + 11, k + 26, Block.obsidian.blockID);
		world.setBlock(i + 0, j + 11, k + 27, Block.obsidian.blockID);
		world.setBlock(i + 0, j + 11, k + 28, Block.obsidian.blockID);
		world.setBlock(i + 0, j + 11, k + 29, Block.obsidian.blockID);
		world.setBlock(i + 0, j + 11, k + 30, Block.obsidian.blockID);
		world.setBlock(i + 0, j + 11, k + 31, Block.obsidian.blockID);
		world.setBlock(i + 0, j + 11, k + 32, Block.obsidian.blockID);
		world.setBlock(i + 0, j + 11, k + 33, Block.obsidian.blockID);
		world.setBlock(i + 0, j + 11, k + 34, Block.obsidian.blockID);
		world.setBlock(i + 0, j + 11, k + 35, Block.obsidian.blockID);
		world.setBlock(i + 0, j + 11, k + 36, Block.obsidian.blockID);
		world.setBlock(i + 0, j + 11, k + 37, Block.obsidian.blockID);
		world.setBlock(i + 0, j + 11, k + 38, Block.obsidian.blockID);
		world.setBlock(i + 0, j + 11, k + 39, Block.obsidian.blockID);
		world.setBlock(i + 0, j + 11, k + 40, Block.obsidian.blockID);
		world.setBlock(i + 0, j + 11, k + 41, Block.obsidian.blockID);
		world.setBlock(i + 0, j + 11, k + 42, Block.obsidian.blockID);
		world.setBlock(i + 0, j + 11, k + 43, Block.obsidian.blockID);
		world.setBlock(i + 0, j + 11, k + 44, Block.obsidian.blockID);
		world.setBlock(i + 0, j + 11, k + 45, Block.obsidian.blockID);
		world.setBlock(i + 0, j + 11, k + 46, Block.obsidian.blockID);
		world.setBlock(i + 0, j + 11, k + 47, Block.obsidian.blockID);
		world.setBlock(i + 0, j + 11, k + 48, Block.obsidian.blockID);
		world.setBlock(i + 0, j + 11, k + 49, Block.obsidian.blockID);
		world.setBlock(i + 0, j + 11, k + 50, Block.obsidian.blockID);
		world.setBlock(i + 0, j + 11, k + 51, Block.obsidian.blockID);
		world.setBlock(i + 0, j + 11, k + 52, Block.obsidian.blockID);
		world.setBlock(i + 0, j + 11, k + 53, Block.obsidian.blockID);
		world.setBlock(i + 0, j + 11, k + 54, Block.obsidian.blockID);
		world.setBlock(i + 0, j + 11, k + 55, Block.obsidian.blockID);
		world.setBlock(i + 0, j + 12, k + 0, Block.obsidian.blockID);
		world.setBlock(i + 0, j + 12, k + 1, Block.obsidian.blockID);
		world.setBlock(i + 0, j + 12, k + 2, Block.obsidian.blockID);
		world.setBlock(i + 0, j + 12, k + 3, Block.obsidian.blockID);
		world.setBlock(i + 0, j + 12, k + 4, Block.obsidian.blockID);
		world.setBlock(i + 0, j + 12, k + 5, Block.obsidian.blockID);
		world.setBlock(i + 0, j + 12, k + 6, Block.obsidian.blockID);
		world.setBlock(i + 0, j + 12, k + 7, Block.obsidian.blockID);
		world.setBlock(i + 0, j + 12, k + 8, Block.obsidian.blockID);
		world.setBlock(i + 0, j + 12, k + 9, Block.obsidian.blockID);
		world.setBlock(i + 0, j + 12, k + 10, Block.obsidian.blockID);
		world.setBlock(i + 0, j + 12, k + 11, Block.obsidian.blockID);
		world.setBlock(i + 0, j + 12, k + 12, Block.obsidian.blockID);
		world.setBlock(i + 0, j + 12, k + 13, Block.obsidian.blockID);
		world.setBlock(i + 0, j + 12, k + 14, Block.obsidian.blockID);
		world.setBlock(i + 0, j + 12, k + 15, Block.obsidian.blockID);
		world.setBlock(i + 0, j + 12, k + 16, Block.obsidian.blockID);
		world.setBlock(i + 0, j + 12, k + 17, Block.obsidian.blockID);
		world.setBlock(i + 0, j + 12, k + 18, Block.obsidian.blockID);
		world.setBlock(i + 0, j + 12, k + 19, Block.obsidian.blockID);
		world.setBlock(i + 0, j + 12, k + 20, Block.obsidian.blockID);
		world.setBlock(i + 0, j + 12, k + 21, Block.obsidian.blockID);
		world.setBlock(i + 0, j + 12, k + 22, Block.obsidian.blockID);
		world.setBlock(i + 0, j + 12, k + 23, Block.obsidian.blockID);
		world.setBlock(i + 0, j + 12, k + 24, Block.obsidian.blockID);
		world.setBlock(i + 0, j + 12, k + 25, Block.obsidian.blockID);
		world.setBlock(i + 0, j + 12, k + 26, Block.obsidian.blockID);
		world.setBlock(i + 0, j + 12, k + 27, Block.obsidian.blockID);
		world.setBlock(i + 0, j + 12, k + 28, Block.obsidian.blockID);
		world.setBlock(i + 0, j + 12, k + 29, Block.obsidian.blockID);
		world.setBlock(i + 0, j + 12, k + 30, Block.obsidian.blockID);
		world.setBlock(i + 0, j + 12, k + 31, Block.obsidian.blockID);
		world.setBlock(i + 0, j + 12, k + 32, Block.obsidian.blockID);
		world.setBlock(i + 0, j + 12, k + 33, Block.obsidian.blockID);
		world.setBlock(i + 0, j + 12, k + 34, Block.obsidian.blockID);
		world.setBlock(i + 0, j + 12, k + 35, Block.obsidian.blockID);
		world.setBlock(i + 0, j + 12, k + 36, Block.obsidian.blockID);
		world.setBlock(i + 0, j + 12, k + 37, Block.obsidian.blockID);
		world.setBlock(i + 0, j + 12, k + 38, Block.obsidian.blockID);
		world.setBlock(i + 0, j + 12, k + 39, Block.obsidian.blockID);
		world.setBlock(i + 0, j + 12, k + 40, Block.obsidian.blockID);
		world.setBlock(i + 0, j + 12, k + 41, Block.obsidian.blockID);
		world.setBlock(i + 0, j + 12, k + 42, Block.obsidian.blockID);
		world.setBlock(i + 0, j + 12, k + 43, Block.obsidian.blockID);
		world.setBlock(i + 0, j + 12, k + 44, Block.obsidian.blockID);
		world.setBlock(i + 0, j + 12, k + 45, Block.obsidian.blockID);
		world.setBlock(i + 0, j + 12, k + 46, Block.obsidian.blockID);
		world.setBlock(i + 0, j + 12, k + 47, Block.obsidian.blockID);
		world.setBlock(i + 0, j + 12, k + 48, Block.obsidian.blockID);
		world.setBlock(i + 0, j + 12, k + 49, Block.obsidian.blockID);
		world.setBlock(i + 0, j + 12, k + 50, Block.obsidian.blockID);
		world.setBlock(i + 0, j + 12, k + 51, Block.obsidian.blockID);
		world.setBlock(i + 0, j + 12, k + 52, Block.obsidian.blockID);
		world.setBlock(i + 0, j + 12, k + 53, Block.obsidian.blockID);
		world.setBlock(i + 0, j + 12, k + 54, Block.obsidian.blockID);
		world.setBlock(i + 0, j + 12, k + 55, Block.obsidian.blockID);
		world.setBlock(i + 0, j + 13, k + 0, Block.obsidian.blockID);
		world.setBlock(i + 0, j + 13, k + 1, Block.obsidian.blockID);
		world.setBlock(i + 0, j + 13, k + 2, Block.obsidian.blockID);
		world.setBlock(i + 0, j + 13, k + 3, Block.obsidian.blockID);
		world.setBlock(i + 0, j + 13, k + 4, Block.obsidian.blockID);
		world.setBlock(i + 0, j + 13, k + 5, Block.obsidian.blockID);
		world.setBlock(i + 0, j + 13, k + 6, Block.obsidian.blockID);
		world.setBlock(i + 0, j + 13, k + 7, Block.obsidian.blockID);
		world.setBlock(i + 0, j + 13, k + 8, Block.obsidian.blockID);
		world.setBlock(i + 0, j + 13, k + 9, Block.obsidian.blockID);
		world.setBlock(i + 0, j + 13, k + 10, Block.obsidian.blockID);
		world.setBlock(i + 0, j + 13, k + 11, Block.obsidian.blockID);
		world.setBlock(i + 0, j + 13, k + 12, Block.obsidian.blockID);
		world.setBlock(i + 0, j + 13, k + 13, Block.obsidian.blockID);
		world.setBlock(i + 0, j + 13, k + 14, Block.obsidian.blockID);
		world.setBlock(i + 0, j + 13, k + 15, Block.obsidian.blockID);
		world.setBlock(i + 0, j + 13, k + 16, Block.obsidian.blockID);
		world.setBlock(i + 0, j + 13, k + 17, Block.obsidian.blockID);
		world.setBlock(i + 0, j + 13, k + 18, Block.obsidian.blockID);
		world.setBlock(i + 0, j + 13, k + 19, Block.obsidian.blockID);
		world.setBlock(i + 0, j + 13, k + 20, Block.obsidian.blockID);
		world.setBlock(i + 0, j + 13, k + 21, Block.obsidian.blockID);
		world.setBlock(i + 0, j + 13, k + 22, Block.obsidian.blockID);
		world.setBlock(i + 0, j + 13, k + 23, Block.obsidian.blockID);
		world.setBlock(i + 0, j + 13, k + 24, Block.obsidian.blockID);
		world.setBlock(i + 0, j + 13, k + 25, Block.obsidian.blockID);
		world.setBlock(i + 0, j + 13, k + 26, Block.obsidian.blockID);
		world.setBlock(i + 0, j + 13, k + 27, Block.obsidian.blockID);
		world.setBlock(i + 0, j + 13, k + 28, Block.obsidian.blockID);
		world.setBlock(i + 0, j + 13, k + 29, Block.obsidian.blockID);
		world.setBlock(i + 0, j + 13, k + 30, Block.obsidian.blockID);
		world.setBlock(i + 0, j + 13, k + 31, Block.obsidian.blockID);
		world.setBlock(i + 0, j + 13, k + 32, Block.obsidian.blockID);
		world.setBlock(i + 0, j + 13, k + 33, Block.obsidian.blockID);
		world.setBlock(i + 0, j + 13, k + 34, Block.obsidian.blockID);
		world.setBlock(i + 0, j + 13, k + 35, Block.obsidian.blockID);
		world.setBlock(i + 0, j + 13, k + 36, Block.obsidian.blockID);
		world.setBlock(i + 0, j + 13, k + 37, Block.obsidian.blockID);
		world.setBlock(i + 0, j + 13, k + 38, Block.obsidian.blockID);
		world.setBlock(i + 0, j + 13, k + 39, Block.obsidian.blockID);
		world.setBlock(i + 0, j + 13, k + 40, Block.obsidian.blockID);
		world.setBlock(i + 0, j + 13, k + 41, Block.obsidian.blockID);
		world.setBlock(i + 0, j + 13, k + 42, Block.obsidian.blockID);
		world.setBlock(i + 0, j + 13, k + 43, Block.obsidian.blockID);
		world.setBlock(i + 0, j + 13, k + 44, Block.obsidian.blockID);
		world.setBlock(i + 0, j + 13, k + 45, Block.obsidian.blockID);
		world.setBlock(i + 0, j + 13, k + 46, Block.obsidian.blockID);
		world.setBlock(i + 0, j + 13, k + 47, Block.obsidian.blockID);
		world.setBlock(i + 0, j + 13, k + 48, Block.obsidian.blockID);
		world.setBlock(i + 0, j + 13, k + 49, Block.obsidian.blockID);
		world.setBlock(i + 0, j + 13, k + 50, Block.obsidian.blockID);
		world.setBlock(i + 0, j + 13, k + 51, Block.obsidian.blockID);
		world.setBlock(i + 0, j + 13, k + 52, Block.obsidian.blockID);
		world.setBlock(i + 0, j + 13, k + 53, Block.obsidian.blockID);
		world.setBlock(i + 0, j + 13, k + 54, Block.obsidian.blockID);
		world.setBlock(i + 0, j + 13, k + 55, Block.obsidian.blockID);
		world.setBlock(i + 0, j + 14, k + 0, Block.obsidian.blockID);
		world.setBlock(i + 0, j + 14, k + 1, Block.obsidian.blockID);
		world.setBlock(i + 0, j + 14, k + 2, Block.obsidian.blockID);
		world.setBlock(i + 0, j + 14, k + 3, Block.obsidian.blockID);
		world.setBlock(i + 0, j + 14, k + 4, Block.obsidian.blockID);
		world.setBlock(i + 0, j + 14, k + 5, Block.obsidian.blockID);
		world.setBlock(i + 0, j + 14, k + 6, Block.obsidian.blockID);
		world.setBlock(i + 0, j + 14, k + 7, Block.obsidian.blockID);
		world.setBlock(i + 0, j + 14, k + 8, Block.obsidian.blockID);
		world.setBlock(i + 0, j + 14, k + 9, Block.obsidian.blockID);
		world.setBlock(i + 0, j + 14, k + 10, Block.obsidian.blockID);
		world.setBlock(i + 0, j + 14, k + 11, Block.obsidian.blockID);
		world.setBlock(i + 0, j + 14, k + 12, Block.obsidian.blockID);
		world.setBlock(i + 0, j + 14, k + 13, Block.obsidian.blockID);
		world.setBlock(i + 0, j + 14, k + 14, Block.obsidian.blockID);
		world.setBlock(i + 0, j + 14, k + 15, Block.obsidian.blockID);
		world.setBlock(i + 0, j + 14, k + 16, Block.obsidian.blockID);
		world.setBlock(i + 0, j + 14, k + 17, Block.obsidian.blockID);
		world.setBlock(i + 0, j + 14, k + 18, Block.obsidian.blockID);
		world.setBlock(i + 0, j + 14, k + 19, Block.obsidian.blockID);
		world.setBlock(i + 0, j + 14, k + 20, Block.obsidian.blockID);
		world.setBlock(i + 0, j + 14, k + 21, Block.obsidian.blockID);
		world.setBlock(i + 0, j + 14, k + 22, Block.obsidian.blockID);
		world.setBlock(i + 0, j + 14, k + 23, Block.obsidian.blockID);
		world.setBlock(i + 0, j + 14, k + 24, Block.obsidian.blockID);
		world.setBlock(i + 0, j + 14, k + 25, Block.obsidian.blockID);
		world.setBlock(i + 0, j + 14, k + 26, Block.obsidian.blockID);
		world.setBlock(i + 0, j + 14, k + 27, Block.obsidian.blockID);
		world.setBlock(i + 0, j + 14, k + 28, Block.obsidian.blockID);
		world.setBlock(i + 0, j + 14, k + 29, Block.obsidian.blockID);
		world.setBlock(i + 0, j + 14, k + 30, Block.obsidian.blockID);
		world.setBlock(i + 0, j + 14, k + 31, Block.obsidian.blockID);
		world.setBlock(i + 0, j + 14, k + 32, Block.obsidian.blockID);
		world.setBlock(i + 0, j + 14, k + 33, Block.obsidian.blockID);
		world.setBlock(i + 0, j + 14, k + 34, Block.obsidian.blockID);
		world.setBlock(i + 0, j + 14, k + 35, Block.obsidian.blockID);
		world.setBlock(i + 0, j + 14, k + 36, Block.obsidian.blockID);
		world.setBlock(i + 0, j + 14, k + 37, Block.obsidian.blockID);
		world.setBlock(i + 0, j + 14, k + 38, Block.obsidian.blockID);
		world.setBlock(i + 0, j + 14, k + 39, Block.obsidian.blockID);
		world.setBlock(i + 0, j + 14, k + 40, Block.obsidian.blockID);
		world.setBlock(i + 0, j + 14, k + 41, Block.obsidian.blockID);
		world.setBlock(i + 0, j + 14, k + 42, Block.obsidian.blockID);
		world.setBlock(i + 0, j + 14, k + 43, Block.obsidian.blockID);
		world.setBlock(i + 0, j + 14, k + 44, Block.obsidian.blockID);
		world.setBlock(i + 0, j + 14, k + 45, Block.obsidian.blockID);
		world.setBlock(i + 0, j + 14, k + 46, Block.obsidian.blockID);
		world.setBlock(i + 0, j + 14, k + 47, Block.obsidian.blockID);
		world.setBlock(i + 0, j + 14, k + 48, Block.obsidian.blockID);
		world.setBlock(i + 0, j + 14, k + 49, Block.obsidian.blockID);
		world.setBlock(i + 0, j + 14, k + 50, Block.obsidian.blockID);
		world.setBlock(i + 0, j + 14, k + 51, Block.obsidian.blockID);
		world.setBlock(i + 0, j + 14, k + 52, Block.obsidian.blockID);
		world.setBlock(i + 0, j + 14, k + 53, Block.obsidian.blockID);
		world.setBlock(i + 0, j + 14, k + 54, Block.obsidian.blockID);
		world.setBlock(i + 0, j + 14, k + 55, Block.obsidian.blockID);
		world.setBlock(i + 0, j + 15, k + 0, Block.obsidian.blockID);
		world.setBlock(i + 0, j + 15, k + 1, Block.obsidian.blockID);
		world.setBlock(i + 0, j + 15, k + 2, Block.obsidian.blockID);
		world.setBlock(i + 0, j + 15, k + 3, Block.obsidian.blockID);
		world.setBlock(i + 0, j + 15, k + 4, Block.obsidian.blockID);
		world.setBlock(i + 0, j + 15, k + 5, Block.obsidian.blockID);
		world.setBlock(i + 0, j + 15, k + 6, Block.obsidian.blockID);
		world.setBlock(i + 0, j + 15, k + 7, Block.obsidian.blockID);
		world.setBlock(i + 0, j + 15, k + 8, Block.obsidian.blockID);
		world.setBlock(i + 0, j + 15, k + 9, Block.obsidian.blockID);
		world.setBlock(i + 0, j + 15, k + 22, Block.obsidian.blockID);
		world.setBlock(i + 0, j + 15, k + 23, Block.obsidian.blockID);
		world.setBlock(i + 0, j + 15, k + 24, Block.obsidian.blockID);
		world.setBlock(i + 0, j + 15, k + 25, Block.obsidian.blockID);
		world.setBlock(i + 0, j + 15, k + 26, Block.obsidian.blockID);
		world.setBlock(i + 0, j + 15, k + 27, Block.obsidian.blockID);
		world.setBlock(i + 0, j + 15, k + 28, Block.obsidian.blockID);
		world.setBlock(i + 0, j + 15, k + 29, Block.obsidian.blockID);
		world.setBlock(i + 0, j + 15, k + 30, Block.obsidian.blockID);
		world.setBlock(i + 0, j + 15, k + 31, Block.obsidian.blockID);
		world.setBlock(i + 0, j + 15, k + 46, Block.obsidian.blockID);
		world.setBlock(i + 0, j + 15, k + 47, Block.obsidian.blockID);
		world.setBlock(i + 0, j + 15, k + 48, Block.obsidian.blockID);
		world.setBlock(i + 0, j + 15, k + 49, Block.obsidian.blockID);
		world.setBlock(i + 0, j + 15, k + 50, Block.obsidian.blockID);
		world.setBlock(i + 0, j + 15, k + 51, Block.obsidian.blockID);
		world.setBlock(i + 0, j + 15, k + 52, Block.obsidian.blockID);
		world.setBlock(i + 0, j + 15, k + 53, Block.obsidian.blockID);
		world.setBlock(i + 0, j + 15, k + 54, Block.obsidian.blockID);
		world.setBlock(i + 0, j + 15, k + 55, Block.obsidian.blockID);
		world.setBlock(i + 0, j + 16, k + 0, Block.obsidian.blockID);
		world.setBlock(i + 0, j + 16, k + 1, Block.obsidian.blockID);
		world.setBlock(i + 0, j + 16, k + 2, Block.obsidian.blockID);
		world.setBlock(i + 0, j + 16, k + 3, Block.obsidian.blockID);
		world.setBlock(i + 0, j + 16, k + 4, Block.obsidian.blockID);
		world.setBlock(i + 0, j + 16, k + 5, Block.obsidian.blockID);
		world.setBlock(i + 0, j + 16, k + 6, Block.obsidian.blockID);
		world.setBlock(i + 0, j + 16, k + 7, Block.obsidian.blockID);
		world.setBlock(i + 0, j + 16, k + 8, Block.obsidian.blockID);
		world.setBlock(i + 0, j + 16, k + 9, Block.obsidian.blockID);
		world.setBlock(i + 0, j + 16, k + 22, Block.obsidian.blockID);
		world.setBlock(i + 0, j + 16, k + 23, Block.obsidian.blockID);
		world.setBlock(i + 0, j + 16, k + 24, Block.obsidian.blockID);
		world.setBlock(i + 0, j + 16, k + 25, Block.obsidian.blockID);
		world.setBlock(i + 0, j + 16, k + 26, Block.obsidian.blockID);
		world.setBlock(i + 0, j + 16, k + 27, Block.obsidian.blockID);
		world.setBlock(i + 0, j + 16, k + 28, Block.obsidian.blockID);
		world.setBlock(i + 0, j + 16, k + 29, Block.obsidian.blockID);
		world.setBlock(i + 0, j + 16, k + 30, Block.obsidian.blockID);
		world.setBlock(i + 0, j + 16, k + 31, Block.obsidian.blockID);
		world.setBlock(i + 0, j + 16, k + 46, Block.obsidian.blockID);
		world.setBlock(i + 0, j + 16, k + 47, Block.obsidian.blockID);
		world.setBlock(i + 0, j + 16, k + 48, Block.obsidian.blockID);
		world.setBlock(i + 0, j + 16, k + 49, Block.obsidian.blockID);
		world.setBlock(i + 0, j + 16, k + 50, Block.obsidian.blockID);
		world.setBlock(i + 0, j + 16, k + 51, Block.obsidian.blockID);
		world.setBlock(i + 0, j + 16, k + 52, Block.obsidian.blockID);
		world.setBlock(i + 0, j + 16, k + 53, Block.obsidian.blockID);
		world.setBlock(i + 0, j + 16, k + 54, Block.obsidian.blockID);
		world.setBlock(i + 0, j + 16, k + 55, Block.obsidian.blockID);
		world.setBlock(i + 0, j + 17, k + 0, Block.obsidian.blockID);
		world.setBlock(i + 0, j + 17, k + 1, Block.obsidian.blockID);
		world.setBlock(i + 0, j + 17, k + 2, Block.obsidian.blockID);
		world.setBlock(i + 0, j + 17, k + 3, Block.obsidian.blockID);
		world.setBlock(i + 0, j + 17, k + 4, Block.obsidian.blockID);
		world.setBlock(i + 0, j + 17, k + 5, Block.obsidian.blockID);
		world.setBlock(i + 0, j + 17, k + 6, Block.obsidian.blockID);
		world.setBlock(i + 0, j + 17, k + 7, Block.obsidian.blockID);
		world.setBlock(i + 0, j + 17, k + 8, Block.obsidian.blockID);
		world.setBlock(i + 0, j + 17, k + 9, Block.obsidian.blockID);
		world.setBlock(i + 0, j + 17, k + 22, Block.obsidian.blockID);
		world.setBlock(i + 0, j + 17, k + 23, Block.obsidian.blockID);
		world.setBlock(i + 0, j + 17, k + 24, Block.obsidian.blockID);
		world.setBlock(i + 0, j + 17, k + 25, Block.obsidian.blockID);
		world.setBlock(i + 0, j + 17, k + 26, Block.obsidian.blockID);
		world.setBlock(i + 0, j + 17, k + 27, Block.obsidian.blockID);
		world.setBlock(i + 0, j + 17, k + 28, Block.obsidian.blockID);
		world.setBlock(i + 0, j + 17, k + 29, Block.obsidian.blockID);
		world.setBlock(i + 0, j + 17, k + 30, Block.obsidian.blockID);
		world.setBlock(i + 0, j + 17, k + 31, Block.obsidian.blockID);
		world.setBlock(i + 0, j + 17, k + 46, Block.obsidian.blockID);
		world.setBlock(i + 0, j + 17, k + 47, Block.obsidian.blockID);
		world.setBlock(i + 0, j + 17, k + 48, Block.obsidian.blockID);
		world.setBlock(i + 0, j + 17, k + 49, Block.obsidian.blockID);
		world.setBlock(i + 0, j + 17, k + 50, Block.obsidian.blockID);
		world.setBlock(i + 0, j + 17, k + 51, Block.obsidian.blockID);
		world.setBlock(i + 0, j + 17, k + 52, Block.obsidian.blockID);
		world.setBlock(i + 0, j + 17, k + 53, Block.obsidian.blockID);
		world.setBlock(i + 0, j + 17, k + 54, Block.obsidian.blockID);
		world.setBlock(i + 0, j + 17, k + 55, Block.obsidian.blockID);
		world.setBlock(i + 0, j + 18, k + 1, Block.obsidian.blockID);
		world.setBlock(i + 0, j + 18, k + 2, Block.obsidian.blockID);
		world.setBlock(i + 0, j + 18, k + 4, Block.obsidian.blockID);
		world.setBlock(i + 0, j + 18, k + 5, Block.obsidian.blockID);
		world.setBlock(i + 0, j + 18, k + 7, Block.obsidian.blockID);
		world.setBlock(i + 0, j + 18, k + 8, Block.obsidian.blockID);
		world.setBlock(i + 0, j + 18, k + 23, Block.obsidian.blockID);
		world.setBlock(i + 0, j + 18, k + 24, Block.obsidian.blockID);
		world.setBlock(i + 0, j + 18, k + 26, Block.obsidian.blockID);
		world.setBlock(i + 0, j + 18, k + 27, Block.obsidian.blockID);
		world.setBlock(i + 0, j + 18, k + 29, Block.obsidian.blockID);
		world.setBlock(i + 0, j + 18, k + 30, Block.obsidian.blockID);
		world.setBlock(i + 0, j + 18, k + 47, Block.obsidian.blockID);
		world.setBlock(i + 0, j + 18, k + 48, Block.obsidian.blockID);
		world.setBlock(i + 0, j + 18, k + 50, Block.obsidian.blockID);
		world.setBlock(i + 0, j + 18, k + 51, Block.obsidian.blockID);
		world.setBlock(i + 0, j + 18, k + 53, Block.obsidian.blockID);
		world.setBlock(i + 0, j + 18, k + 54, Block.obsidian.blockID);
		world.setBlock(i + 1, j + 0, k + 0, Block.obsidian.blockID);
		world.setBlock(i + 1, j + 0, k + 1, Block.obsidian.blockID);
		world.setBlock(i + 1, j + 0, k + 2, Block.obsidian.blockID);
		world.setBlock(i + 1, j + 0, k + 3, Block.obsidian.blockID);
		world.setBlock(i + 1, j + 0, k + 4, Block.obsidian.blockID);
		world.setBlock(i + 1, j + 0, k + 5, Block.obsidian.blockID);
		world.setBlock(i + 1, j + 0, k + 6, Block.obsidian.blockID);
		world.setBlock(i + 1, j + 0, k + 7, Block.obsidian.blockID);
		world.setBlock(i + 1, j + 0, k + 8, Block.obsidian.blockID);
		world.setBlock(i + 1, j + 0, k + 9, Block.obsidian.blockID);
		world.setBlock(i + 1, j + 0, k + 10, Block.obsidian.blockID);
		world.setBlock(i + 1, j + 0, k + 11, Block.obsidian.blockID);
		world.setBlock(i + 1, j + 0, k + 12, Block.obsidian.blockID);
		world.setBlock(i + 1, j + 0, k + 13, Block.obsidian.blockID);
		world.setBlock(i + 1, j + 0, k + 14, Block.obsidian.blockID);
		world.setBlock(i + 1, j + 0, k + 15, Block.obsidian.blockID);
		world.setBlock(i + 1, j + 0, k + 16, Block.obsidian.blockID);
		world.setBlock(i + 1, j + 0, k + 17, Block.obsidian.blockID);
		world.setBlock(i + 1, j + 0, k + 18, Block.obsidian.blockID);
		world.setBlock(i + 1, j + 0, k + 19, Block.obsidian.blockID);
		world.setBlock(i + 1, j + 0, k + 20, Block.obsidian.blockID);
		world.setBlock(i + 1, j + 0, k + 21, Block.obsidian.blockID);
		world.setBlock(i + 1, j + 0, k + 22, Block.obsidian.blockID);
		world.setBlock(i + 1, j + 0, k + 23, Block.obsidian.blockID);
		world.setBlock(i + 1, j + 0, k + 24, Block.obsidian.blockID);
		world.setBlock(i + 1, j + 0, k + 25, Block.obsidian.blockID);
		world.setBlock(i + 1, j + 0, k + 26, Block.obsidian.blockID);
		world.setBlock(i + 1, j + 0, k + 27, Block.obsidian.blockID);
		world.setBlock(i + 1, j + 0, k + 28, Block.obsidian.blockID);
		world.setBlock(i + 1, j + 0, k + 29, Block.obsidian.blockID);
		world.setBlock(i + 1, j + 0, k + 30, Block.obsidian.blockID);
		world.setBlock(i + 1, j + 0, k + 31, Block.obsidian.blockID);
		world.setBlock(i + 1, j + 0, k + 32, Block.obsidian.blockID);
		world.setBlock(i + 1, j + 0, k + 33, Block.obsidian.blockID);
		world.setBlock(i + 1, j + 0, k + 34, Block.obsidian.blockID);
		world.setBlock(i + 1, j + 0, k + 35, Block.obsidian.blockID);
		world.setBlock(i + 1, j + 0, k + 36, Block.obsidian.blockID);
		world.setBlock(i + 1, j + 0, k + 37, Block.obsidian.blockID);
		world.setBlock(i + 1, j + 0, k + 38, Block.obsidian.blockID);
		world.setBlock(i + 1, j + 0, k + 39, Block.obsidian.blockID);
		world.setBlock(i + 1, j + 0, k + 40, Block.obsidian.blockID);
		world.setBlock(i + 1, j + 0, k + 41, Block.obsidian.blockID);
		world.setBlock(i + 1, j + 0, k + 42, Block.obsidian.blockID);
		world.setBlock(i + 1, j + 0, k + 43, Block.obsidian.blockID);
		world.setBlock(i + 1, j + 0, k + 44, Block.obsidian.blockID);
		world.setBlock(i + 1, j + 0, k + 45, Block.obsidian.blockID);
		world.setBlock(i + 1, j + 0, k + 46, Block.obsidian.blockID);
		world.setBlock(i + 1, j + 0, k + 47, Block.obsidian.blockID);
		world.setBlock(i + 1, j + 0, k + 48, Block.obsidian.blockID);
		world.setBlock(i + 1, j + 0, k + 49, Block.obsidian.blockID);
		world.setBlock(i + 1, j + 0, k + 50, Block.obsidian.blockID);
		world.setBlock(i + 1, j + 0, k + 51, Block.obsidian.blockID);
		world.setBlock(i + 1, j + 0, k + 52, Block.obsidian.blockID);
		world.setBlock(i + 1, j + 0, k + 53, Block.obsidian.blockID);
		world.setBlock(i + 1, j + 0, k + 54, Block.obsidian.blockID);
		world.setBlock(i + 1, j + 0, k + 55, Block.obsidian.blockID);
		world.setBlock(i + 1, j + 1, k + 0, Block.obsidian.blockID);
		world.setBlock(i + 1, j + 1, k + 16, Block.obsidian.blockID);
		world.setBlock(i + 1, j + 1, k + 17, Block.planks.blockID);
		world.setBlock(i + 1, j + 1, k + 18, Block.planks.blockID);
		world.setBlock(i + 1, j + 1, k + 19, Block.planks.blockID);
		world.setBlock(i + 1, j + 1, k + 20, Block.planks.blockID);
		world.setBlock(i + 1, j + 1, k + 21, Block.planks.blockID);
		world.setBlock(i + 1, j + 1, k + 22, Block.planks.blockID);
		world.setBlock(i + 1, j + 1, k + 23, Block.planks.blockID);
		world.setBlock(i + 1, j + 1, k + 24, Block.planks.blockID);
		world.setBlock(i + 1, j + 1, k + 25, Block.planks.blockID);
		world.setBlock(i + 1, j + 1, k + 26, Block.planks.blockID);
		world.setBlock(i + 1, j + 1, k + 27, Block.planks.blockID);
		world.setBlock(i + 1, j + 1, k + 28, Block.planks.blockID);
		world.setBlock(i + 1, j + 1, k + 29, Block.planks.blockID);
		world.setBlock(i + 1, j + 1, k + 30, Block.planks.blockID);
		world.setBlock(i + 1, j + 1, k + 31, Block.planks.blockID);
		world.setBlock(i + 1, j + 1, k + 32, Block.planks.blockID);
		world.setBlock(i + 1, j + 1, k + 33, Block.planks.blockID);
		world.setBlock(i + 1, j + 1, k + 34, Block.planks.blockID);
		world.setBlock(i + 1, j + 1, k + 35, Block.planks.blockID);
		world.setBlock(i + 1, j + 1, k + 36, Block.planks.blockID);
		world.setBlock(i + 1, j + 1, k + 37, Block.obsidian.blockID);
		world.setBlock(i + 1, j + 1, k + 47, Block.obsidian.blockID);
		world.setBlock(i + 1, j + 1, k + 50, Block.obsidian.blockID);
		world.setBlock(i + 1, j + 1, k + 55, Block.obsidian.blockID);
		world.setBlock(i + 1, j + 2, k + 0, Block.obsidian.blockID);
		world.setBlock(i + 1, j + 2, k + 1, Block.obsidian.blockID);
		world.setBlock(i + 1, j + 2, k + 2, Block.obsidian.blockID);
		world.setBlock(i + 1, j + 2, k + 3, Block.obsidian.blockID);
		world.setBlock(i + 1, j + 2, k + 4, Block.obsidian.blockID);
		world.setBlock(i + 1, j + 2, k + 5, Block.obsidian.blockID);
		world.setBlock(i + 1, j + 2, k + 6, Block.obsidian.blockID);
		world.setBlock(i + 1, j + 2, k + 7, Block.obsidian.blockID);
		world.setBlock(i + 1, j + 2, k + 8, Block.obsidian.blockID);
		world.setBlock(i + 1, j + 2, k + 9, Block.obsidian.blockID);
		world.setBlock(i + 1, j + 2, k + 10, Block.obsidian.blockID);
		world.setBlock(i + 1, j + 2, k + 11, Block.obsidian.blockID);
		world.setBlock(i + 1, j + 2, k + 12, Block.obsidian.blockID);
		world.setBlock(i + 1, j + 2, k + 13, Block.obsidian.blockID);
		world.setBlock(i + 1, j + 2, k + 14, Block.obsidian.blockID);
		world.setBlock(i + 1, j + 2, k + 15, Block.obsidian.blockID);
		world.setBlock(i + 1, j + 2, k + 16, Block.obsidian.blockID);
		world.setBlock(i + 1, j + 2, k + 37, Block.obsidian.blockID);
		world.setBlock(i + 1, j + 2, k + 38, Block.obsidian.blockID);
		world.setBlock(i + 1, j + 2, k + 39, Block.obsidian.blockID);
		world.setBlock(i + 1, j + 2, k + 40, Block.obsidian.blockID);
		world.setBlock(i + 1, j + 2, k + 41, Block.obsidian.blockID);
		world.setBlock(i + 1, j + 2, k + 42, Block.obsidian.blockID);
		world.setBlock(i + 1, j + 2, k + 43, Block.obsidian.blockID);
		world.setBlock(i + 1, j + 2, k + 44, Block.obsidian.blockID);
		world.setBlock(i + 1, j + 2, k + 45, Block.obsidian.blockID);
		world.setBlock(i + 1, j + 2, k + 46, Block.obsidian.blockID);
		world.setBlock(i + 1, j + 2, k + 47, Block.obsidian.blockID);
		world.setBlock(i + 1, j + 2, k + 48, Block.obsidian.blockID);
		world.setBlock(i + 1, j + 2, k + 49, Block.obsidian.blockID);
		world.setBlock(i + 1, j + 2, k + 50, Block.obsidian.blockID);
		world.setBlock(i + 1, j + 2, k + 51, Block.obsidian.blockID);
		world.setBlock(i + 1, j + 2, k + 52, Block.obsidian.blockID);
		world.setBlock(i + 1, j + 2, k + 53, Block.obsidian.blockID);
		world.setBlock(i + 1, j + 2, k + 54, Block.obsidian.blockID);
		world.setBlock(i + 1, j + 2, k + 55, Block.obsidian.blockID);
		world.setBlock(i + 1, j + 3, k + 0, Block.obsidian.blockID);
		world.setBlock(i + 1, j + 3, k + 16, Block.obsidian.blockID);
		world.setBlock(i + 1, j + 3, k + 37, Block.obsidian.blockID);
		world.setBlock(i + 1, j + 3, k + 55, Block.obsidian.blockID);
		world.setBlock(i + 1, j + 4, k + 0, Block.obsidian.blockID);
		world.setBlock(i + 1, j + 4, k + 55, Block.obsidian.blockID);
		world.setBlock(i + 1, j + 5, k + 0, Block.obsidian.blockID);
		world.setBlock(i + 1, j + 5, k + 55, Block.obsidian.blockID);
		world.setBlock(i + 1, j + 6, k + 0, Block.obsidian.blockID);
		world.setBlock(i + 1, j + 6, k + 55, Block.obsidian.blockID);
		world.setBlock(i + 1, j + 7, k + 0, Block.obsidian.blockID);
		world.setBlock(i + 1, j + 7, k + 55, Block.obsidian.blockID);
		world.setBlock(i + 1, j + 8, k + 0, Block.obsidian.blockID);
		world.setBlock(i + 1, j + 8, k + 55, Block.obsidian.blockID);
		world.setBlock(i + 1, j + 9, k + 0, Block.obsidian.blockID);
		world.setBlock(i + 1, j + 9, k + 55, Block.obsidian.blockID);
		world.setBlock(i + 1, j + 10, k + 0, Block.obsidian.blockID);
		world.setBlock(i + 1, j + 10, k + 55, Block.obsidian.blockID);
		world.setBlock(i + 1, j + 11, k + 0, Block.obsidian.blockID);
		world.setBlock(i + 1, j + 11, k + 1, Block.glowStone.blockID);
		world.setBlock(i + 1, j + 11, k + 2, Block.glowStone.blockID);
		world.setBlock(i + 1, j + 11, k + 3, Block.glowStone.blockID);
		world.setBlock(i + 1, j + 11, k + 4, Block.glowStone.blockID);
		world.setBlock(i + 1, j + 11, k + 5, Block.glowStone.blockID);
		world.setBlock(i + 1, j + 11, k + 6, Block.glowStone.blockID);
		world.setBlock(i + 1, j + 11, k + 7, Block.glowStone.blockID);
		world.setBlock(i + 1, j + 11, k + 8, Block.glowStone.blockID);
		world.setBlock(i + 1, j + 11, k + 9, Block.glowStone.blockID);
		world.setBlock(i + 1, j + 11, k + 10, Block.glowStone.blockID);
		world.setBlock(i + 1, j + 11, k + 11, Block.glowStone.blockID);
		world.setBlock(i + 1, j + 11, k + 12, Block.glowStone.blockID);
		world.setBlock(i + 1, j + 11, k + 13, Block.glowStone.blockID);
		world.setBlock(i + 1, j + 11, k + 14, Block.glowStone.blockID);
		world.setBlock(i + 1, j + 11, k + 15, Block.glowStone.blockID);
		world.setBlock(i + 1, j + 11, k + 16, Block.glowStone.blockID);
		world.setBlock(i + 1, j + 11, k + 17, Block.glowStone.blockID);
		world.setBlock(i + 1, j + 11, k + 18, Block.glowStone.blockID);
		world.setBlock(i + 1, j + 11, k + 19, Block.glowStone.blockID);
		world.setBlock(i + 1, j + 11, k + 20, Block.glowStone.blockID);
		world.setBlock(i + 1, j + 11, k + 21, Block.glowStone.blockID);
		world.setBlock(i + 1, j + 11, k + 22, Block.glowStone.blockID);
		world.setBlock(i + 1, j + 11, k + 23, Block.glowStone.blockID);
		world.setBlock(i + 1, j + 11, k + 24, Block.glowStone.blockID);
		world.setBlock(i + 1, j + 11, k + 25, Block.glowStone.blockID);
		world.setBlock(i + 1, j + 11, k + 26, Block.glowStone.blockID);
		world.setBlock(i + 1, j + 11, k + 27, Block.glowStone.blockID);
		world.setBlock(i + 1, j + 11, k + 28, Block.glowStone.blockID);
		world.setBlock(i + 1, j + 11, k + 29, Block.glowStone.blockID);
		world.setBlock(i + 1, j + 11, k + 30, Block.glowStone.blockID);
		world.setBlock(i + 1, j + 11, k + 31, Block.glowStone.blockID);
		world.setBlock(i + 1, j + 11, k + 32, Block.glowStone.blockID);
		world.setBlock(i + 1, j + 11, k + 33, Block.glowStone.blockID);
		world.setBlock(i + 1, j + 11, k + 34, Block.glowStone.blockID);
		world.setBlock(i + 1, j + 11, k + 35, Block.glowStone.blockID);
		world.setBlock(i + 1, j + 11, k + 36, Block.glowStone.blockID);
		world.setBlock(i + 1, j + 11, k + 37, Block.glowStone.blockID);
		world.setBlock(i + 1, j + 11, k + 38, Block.glowStone.blockID);
		world.setBlock(i + 1, j + 11, k + 39, Block.glowStone.blockID);
		world.setBlock(i + 1, j + 11, k + 40, Block.glowStone.blockID);
		world.setBlock(i + 1, j + 11, k + 41, Block.glowStone.blockID);
		world.setBlock(i + 1, j + 11, k + 42, Block.glowStone.blockID);
		world.setBlock(i + 1, j + 11, k + 43, Block.glowStone.blockID);
		world.setBlock(i + 1, j + 11, k + 44, Block.glowStone.blockID);
		world.setBlock(i + 1, j + 11, k + 45, Block.glowStone.blockID);
		world.setBlock(i + 1, j + 11, k + 46, Block.glowStone.blockID);
		world.setBlock(i + 1, j + 11, k + 47, Block.glowStone.blockID);
		world.setBlock(i + 1, j + 11, k + 48, Block.glowStone.blockID);
		world.setBlock(i + 1, j + 11, k + 49, Block.glowStone.blockID);
		world.setBlock(i + 1, j + 11, k + 50, Block.glowStone.blockID);
		world.setBlock(i + 1, j + 11, k + 51, Block.glowStone.blockID);
		world.setBlock(i + 1, j + 11, k + 52, Block.glowStone.blockID);
		world.setBlock(i + 1, j + 11, k + 53, Block.glowStone.blockID);
		world.setBlock(i + 1, j + 11, k + 54, Block.glowStone.blockID);
		world.setBlock(i + 1, j + 11, k + 55, Block.obsidian.blockID);
		world.setBlock(i + 1, j + 12, k + 0, Block.obsidian.blockID);
		world.setBlock(i + 1, j + 12, k + 1, Block.obsidian.blockID);
		world.setBlock(i + 1, j + 12, k + 2, Block.obsidian.blockID);
		world.setBlock(i + 1, j + 12, k + 3, Block.obsidian.blockID);
		world.setBlock(i + 1, j + 12, k + 4, Block.obsidian.blockID);
		world.setBlock(i + 1, j + 12, k + 5, Block.obsidian.blockID);
		world.setBlock(i + 1, j + 12, k + 6, Block.obsidian.blockID);
		world.setBlock(i + 1, j + 12, k + 7, Block.obsidian.blockID);
		world.setBlock(i + 1, j + 12, k + 8, Block.obsidian.blockID);
		world.setBlock(i + 1, j + 12, k + 9, Block.obsidian.blockID);
		world.setBlock(i + 1, j + 12, k + 10, Block.obsidian.blockID);
		world.setBlock(i + 1, j + 12, k + 11, Block.obsidian.blockID);
		world.setBlock(i + 1, j + 12, k + 12, Block.obsidian.blockID);
		world.setBlock(i + 1, j + 12, k + 13, Block.obsidian.blockID);
		world.setBlock(i + 1, j + 12, k + 14, Block.obsidian.blockID);
		world.setBlock(i + 1, j + 12, k + 15, Block.obsidian.blockID);
		world.setBlock(i + 1, j + 12, k + 16, Block.obsidian.blockID);
		world.setBlock(i + 1, j + 12, k + 17, Block.obsidian.blockID);
		world.setBlock(i + 1, j + 12, k + 18, Block.obsidian.blockID);
		world.setBlock(i + 1, j + 12, k + 19, Block.obsidian.blockID);
		world.setBlock(i + 1, j + 12, k + 20, Block.obsidian.blockID);
		world.setBlock(i + 1, j + 12, k + 21, Block.obsidian.blockID);
		world.setBlock(i + 1, j + 12, k + 22, Block.obsidian.blockID);
		world.setBlock(i + 1, j + 12, k + 23, Block.obsidian.blockID);
		world.setBlock(i + 1, j + 12, k + 24, Block.obsidian.blockID);
		world.setBlock(i + 1, j + 12, k + 25, Block.obsidian.blockID);
		world.setBlock(i + 1, j + 12, k + 26, Block.obsidian.blockID);
		world.setBlock(i + 1, j + 12, k + 27, Block.obsidian.blockID);
		world.setBlock(i + 1, j + 12, k + 28, Block.obsidian.blockID);
		world.setBlock(i + 1, j + 12, k + 29, Block.obsidian.blockID);
		world.setBlock(i + 1, j + 12, k + 30, Block.obsidian.blockID);
		world.setBlock(i + 1, j + 12, k + 31, Block.obsidian.blockID);
		world.setBlock(i + 1, j + 12, k + 32, Block.obsidian.blockID);
		world.setBlock(i + 1, j + 12, k + 33, Block.obsidian.blockID);
		world.setBlock(i + 1, j + 12, k + 34, Block.obsidian.blockID);
		world.setBlock(i + 1, j + 12, k + 35, Block.obsidian.blockID);
		world.setBlock(i + 1, j + 12, k + 36, Block.obsidian.blockID);
		world.setBlock(i + 1, j + 12, k + 37, Block.obsidian.blockID);
		world.setBlock(i + 1, j + 12, k + 38, Block.obsidian.blockID);
		world.setBlock(i + 1, j + 12, k + 39, Block.obsidian.blockID);
		world.setBlock(i + 1, j + 12, k + 40, Block.obsidian.blockID);
		world.setBlock(i + 1, j + 12, k + 41, Block.obsidian.blockID);
		world.setBlock(i + 1, j + 12, k + 42, Block.obsidian.blockID);
		world.setBlock(i + 1, j + 12, k + 43, Block.obsidian.blockID);
		world.setBlock(i + 1, j + 12, k + 44, Block.obsidian.blockID);
		world.setBlock(i + 1, j + 12, k + 45, Block.obsidian.blockID);
		world.setBlock(i + 1, j + 12, k + 46, Block.obsidian.blockID);
		world.setBlock(i + 1, j + 12, k + 47, Block.obsidian.blockID);
		world.setBlock(i + 1, j + 12, k + 48, Block.obsidian.blockID);
		world.setBlock(i + 1, j + 12, k + 49, Block.obsidian.blockID);
		world.setBlock(i + 1, j + 12, k + 50, Block.obsidian.blockID);
		world.setBlock(i + 1, j + 12, k + 51, Block.obsidian.blockID);
		world.setBlock(i + 1, j + 12, k + 52, Block.obsidian.blockID);
		world.setBlock(i + 1, j + 12, k + 53, Block.obsidian.blockID);
		world.setBlock(i + 1, j + 12, k + 54, Block.obsidian.blockID);
		world.setBlock(i + 1, j + 12, k + 55, Block.obsidian.blockID);
		world.setBlock(i + 1, j + 13, k + 0, Block.obsidian.blockID);
		world.setBlock(i + 1, j + 13, k + 1, Block.obsidian.blockID);
		world.setBlock(i + 1, j + 13, k + 2, Block.obsidian.blockID);
		world.setBlock(i + 1, j + 13, k + 3, Block.obsidian.blockID);
		world.setBlock(i + 1, j + 13, k + 4, Block.obsidian.blockID);
		world.setBlock(i + 1, j + 13, k + 5, Block.obsidian.blockID);
		world.setBlock(i + 1, j + 13, k + 6, Block.obsidian.blockID);
		world.setBlock(i + 1, j + 13, k + 7, Block.obsidian.blockID);
		world.setBlock(i + 1, j + 13, k + 8, Block.obsidian.blockID);
		world.setBlock(i + 1, j + 13, k + 9, Block.obsidian.blockID);
		world.setBlock(i + 1, j + 13, k + 10, Block.obsidian.blockID);
		world.setBlock(i + 1, j + 13, k + 11, Block.obsidian.blockID);
		world.setBlock(i + 1, j + 13, k + 12, Block.obsidian.blockID);
		world.setBlock(i + 1, j + 13, k + 13, Block.obsidian.blockID);
		world.setBlock(i + 1, j + 13, k + 14, Block.obsidian.blockID);
		world.setBlock(i + 1, j + 13, k + 15, Block.obsidian.blockID);
		world.setBlock(i + 1, j + 13, k + 16, Block.obsidian.blockID);
		world.setBlock(i + 1, j + 13, k + 17, Block.obsidian.blockID);
		world.setBlock(i + 1, j + 13, k + 18, Block.obsidian.blockID);
		world.setBlock(i + 1, j + 13, k + 19, Block.obsidian.blockID);
		world.setBlock(i + 1, j + 13, k + 20, Block.obsidian.blockID);
		world.setBlock(i + 1, j + 13, k + 21, Block.obsidian.blockID);
		world.setBlock(i + 1, j + 13, k + 22, Block.obsidian.blockID);
		world.setBlock(i + 1, j + 13, k + 23, Block.obsidian.blockID);
		world.setBlock(i + 1, j + 13, k + 24, Block.obsidian.blockID);
		world.setBlock(i + 1, j + 13, k + 25, Block.obsidian.blockID);
		world.setBlock(i + 1, j + 13, k + 26, Block.obsidian.blockID);
		world.setBlock(i + 1, j + 13, k + 27, Block.obsidian.blockID);
		world.setBlock(i + 1, j + 13, k + 28, Block.obsidian.blockID);
		world.setBlock(i + 1, j + 13, k + 29, Block.obsidian.blockID);
		world.setBlock(i + 1, j + 13, k + 30, Block.obsidian.blockID);
		world.setBlock(i + 1, j + 13, k + 31, Block.obsidian.blockID);
		world.setBlock(i + 1, j + 13, k + 32, Block.obsidian.blockID);
		world.setBlock(i + 1, j + 13, k + 33, Block.obsidian.blockID);
		world.setBlock(i + 1, j + 13, k + 34, Block.obsidian.blockID);
		world.setBlock(i + 1, j + 13, k + 35, Block.obsidian.blockID);
		world.setBlock(i + 1, j + 13, k + 36, Block.obsidian.blockID);
		world.setBlock(i + 1, j + 13, k + 37, Block.obsidian.blockID);
		world.setBlock(i + 1, j + 13, k + 38, Block.obsidian.blockID);
		world.setBlock(i + 1, j + 13, k + 39, Block.obsidian.blockID);
		world.setBlock(i + 1, j + 13, k + 40, Block.obsidian.blockID);
		world.setBlock(i + 1, j + 13, k + 41, Block.obsidian.blockID);
		world.setBlock(i + 1, j + 13, k + 42, Block.obsidian.blockID);
		world.setBlock(i + 1, j + 13, k + 43, Block.obsidian.blockID);
		world.setBlock(i + 1, j + 13, k + 44, Block.obsidian.blockID);
		world.setBlock(i + 1, j + 13, k + 45, Block.obsidian.blockID);
		world.setBlock(i + 1, j + 13, k + 46, Block.obsidian.blockID);
		world.setBlock(i + 1, j + 13, k + 47, Block.obsidian.blockID);
		world.setBlock(i + 1, j + 13, k + 48, Block.obsidian.blockID);
		world.setBlock(i + 1, j + 13, k + 49, Block.obsidian.blockID);
		world.setBlock(i + 1, j + 13, k + 50, Block.obsidian.blockID);
		world.setBlock(i + 1, j + 13, k + 51, Block.obsidian.blockID);
		world.setBlock(i + 1, j + 13, k + 52, Block.obsidian.blockID);
		world.setBlock(i + 1, j + 13, k + 53, Block.obsidian.blockID);
		world.setBlock(i + 1, j + 13, k + 54, Block.obsidian.blockID);
		world.setBlock(i + 1, j + 13, k + 55, Block.obsidian.blockID);
		world.setBlock(i + 1, j + 14, k + 0, Block.obsidian.blockID);
		world.setBlock(i + 1, j + 14, k + 1, Block.obsidian.blockID);
		world.setBlock(i + 1, j + 14, k + 2, Block.obsidian.blockID);
		world.setBlock(i + 1, j + 14, k + 3, Block.obsidian.blockID);
		world.setBlock(i + 1, j + 14, k + 4, Block.obsidian.blockID);
		world.setBlock(i + 1, j + 14, k + 5, Block.obsidian.blockID);
		world.setBlock(i + 1, j + 14, k + 6, Block.obsidian.blockID);
		world.setBlock(i + 1, j + 14, k + 7, Block.obsidian.blockID);
		world.setBlock(i + 1, j + 14, k + 8, Block.obsidian.blockID);
		world.setBlock(i + 1, j + 14, k + 9, Block.obsidian.blockID);
		world.setBlock(i + 1, j + 14, k + 10, Block.obsidian.blockID);
		world.setBlock(i + 1, j + 14, k + 11, Block.obsidian.blockID);
		world.setBlock(i + 1, j + 14, k + 12, Block.obsidian.blockID);
		world.setBlock(i + 1, j + 14, k + 13, Block.obsidian.blockID);
		world.setBlock(i + 1, j + 14, k + 14, Block.obsidian.blockID);
		world.setBlock(i + 1, j + 14, k + 15, Block.obsidian.blockID);
		world.setBlock(i + 1, j + 14, k + 16, Block.obsidian.blockID);
		world.setBlock(i + 1, j + 14, k + 17, Block.obsidian.blockID);
		world.setBlock(i + 1, j + 14, k + 18, Block.obsidian.blockID);
		world.setBlock(i + 1, j + 14, k + 19, Block.obsidian.blockID);
		world.setBlock(i + 1, j + 14, k + 20, Block.obsidian.blockID);
		world.setBlock(i + 1, j + 14, k + 21, Block.obsidian.blockID);
		world.setBlock(i + 1, j + 14, k + 22, Block.obsidian.blockID);
		world.setBlock(i + 1, j + 14, k + 23, Block.obsidian.blockID);
		world.setBlock(i + 1, j + 14, k + 24, Block.obsidian.blockID);
		world.setBlock(i + 1, j + 14, k + 25, Block.obsidian.blockID);
		world.setBlock(i + 1, j + 14, k + 26, Block.obsidian.blockID);
		world.setBlock(i + 1, j + 14, k + 27, Block.obsidian.blockID);
		world.setBlock(i + 1, j + 14, k + 28, Block.obsidian.blockID);
		world.setBlock(i + 1, j + 14, k + 29, Block.obsidian.blockID);
		world.setBlock(i + 1, j + 14, k + 30, Block.obsidian.blockID);
		world.setBlock(i + 1, j + 14, k + 31, Block.obsidian.blockID);
		world.setBlock(i + 1, j + 14, k + 32, Block.obsidian.blockID);
		world.setBlock(i + 1, j + 14, k + 33, Block.obsidian.blockID);
		world.setBlock(i + 1, j + 14, k + 34, Block.obsidian.blockID);
		world.setBlock(i + 1, j + 14, k + 35, Block.obsidian.blockID);
		world.setBlock(i + 1, j + 14, k + 36, Block.obsidian.blockID);
		world.setBlock(i + 1, j + 14, k + 37, Block.obsidian.blockID);
		world.setBlock(i + 1, j + 14, k + 38, Block.obsidian.blockID);
		world.setBlock(i + 1, j + 14, k + 39, Block.obsidian.blockID);
		world.setBlock(i + 1, j + 14, k + 40, Block.obsidian.blockID);
		world.setBlock(i + 1, j + 14, k + 41, Block.obsidian.blockID);
		world.setBlock(i + 1, j + 14, k + 42, Block.obsidian.blockID);
		world.setBlock(i + 1, j + 14, k + 43, Block.obsidian.blockID);
		world.setBlock(i + 1, j + 14, k + 44, Block.obsidian.blockID);
		world.setBlock(i + 1, j + 14, k + 45, Block.obsidian.blockID);
		world.setBlock(i + 1, j + 14, k + 46, Block.obsidian.blockID);
		world.setBlock(i + 1, j + 14, k + 47, Block.obsidian.blockID);
		world.setBlock(i + 1, j + 14, k + 48, Block.obsidian.blockID);
		world.setBlock(i + 1, j + 14, k + 49, Block.obsidian.blockID);
		world.setBlock(i + 1, j + 14, k + 50, Block.obsidian.blockID);
		world.setBlock(i + 1, j + 14, k + 51, Block.obsidian.blockID);
		world.setBlock(i + 1, j + 14, k + 52, Block.obsidian.blockID);
		world.setBlock(i + 1, j + 14, k + 53, Block.obsidian.blockID);
		world.setBlock(i + 1, j + 14, k + 54, Block.obsidian.blockID);
		world.setBlock(i + 1, j + 14, k + 55, Block.obsidian.blockID);
		world.setBlock(i + 1, j + 15, k + 0, Block.obsidian.blockID);
		world.setBlock(i + 1, j + 15, k + 9, Block.obsidian.blockID);
		world.setBlock(i + 1, j + 15, k + 22, Block.obsidian.blockID);
		world.setBlock(i + 1, j + 15, k + 31, Block.obsidian.blockID);
		world.setBlock(i + 1, j + 15, k + 46, Block.obsidian.blockID);
		world.setBlock(i + 1, j + 15, k + 55, Block.obsidian.blockID);
		world.setBlock(i + 1, j + 16, k + 0, Block.obsidian.blockID);
		world.setBlock(i + 1, j + 16, k + 9, Block.obsidian.blockID);
		world.setBlock(i + 1, j + 16, k + 22, Block.obsidian.blockID);
		world.setBlock(i + 1, j + 16, k + 31, Block.obsidian.blockID);
		world.setBlock(i + 1, j + 16, k + 46, Block.obsidian.blockID);
		world.setBlock(i + 1, j + 16, k + 55, Block.obsidian.blockID);
		world.setBlock(i + 1, j + 17, k + 0, Block.obsidian.blockID);
		world.setBlock(i + 1, j + 17, k + 9, Block.obsidian.blockID);
		world.setBlock(i + 1, j + 17, k + 22, Block.obsidian.blockID);
		world.setBlock(i + 1, j + 17, k + 31, Block.obsidian.blockID);
		world.setBlock(i + 1, j + 17, k + 46, Block.obsidian.blockID);
		world.setBlock(i + 1, j + 17, k + 55, Block.obsidian.blockID);
		world.setBlock(i + 1, j + 18, k + 0, Block.obsidian.blockID);
		world.setBlock(i + 1, j + 18, k + 9, Block.obsidian.blockID);
		world.setBlock(i + 1, j + 18, k + 22, Block.obsidian.blockID);
		world.setBlock(i + 1, j + 18, k + 31, Block.obsidian.blockID);
		world.setBlock(i + 1, j + 18, k + 46, Block.obsidian.blockID);
		world.setBlock(i + 1, j + 18, k + 55, Block.obsidian.blockID);
		world.setBlock(i + 2, j + 0, k + 0, Block.obsidian.blockID);
		world.setBlock(i + 2, j + 0, k + 1, Block.obsidian.blockID);
		world.setBlock(i + 2, j + 0, k + 2, Block.obsidian.blockID);
		world.setBlock(i + 2, j + 0, k + 3, Block.obsidian.blockID);
		world.setBlock(i + 2, j + 0, k + 4, Block.obsidian.blockID);
		world.setBlock(i + 2, j + 0, k + 5, Block.obsidian.blockID);
		world.setBlock(i + 2, j + 0, k + 6, Block.obsidian.blockID);
		world.setBlock(i + 2, j + 0, k + 7, Block.obsidian.blockID);
		world.setBlock(i + 2, j + 0, k + 8, Block.obsidian.blockID);
		world.setBlock(i + 2, j + 0, k + 9, Block.obsidian.blockID);
		world.setBlock(i + 2, j + 0, k + 10, Block.obsidian.blockID);
		world.setBlock(i + 2, j + 0, k + 11, Block.obsidian.blockID);
		world.setBlock(i + 2, j + 0, k + 12, Block.obsidian.blockID);
		world.setBlock(i + 2, j + 0, k + 13, Block.obsidian.blockID);
		world.setBlock(i + 2, j + 0, k + 14, Block.obsidian.blockID);
		world.setBlock(i + 2, j + 0, k + 15, Block.obsidian.blockID);
		world.setBlock(i + 2, j + 0, k + 16, Block.obsidian.blockID);
		world.setBlock(i + 2, j + 0, k + 17, Block.obsidian.blockID);
		world.setBlock(i + 2, j + 0, k + 18, Block.obsidian.blockID);
		world.setBlock(i + 2, j + 0, k + 19, Block.obsidian.blockID);
		world.setBlock(i + 2, j + 0, k + 20, Block.obsidian.blockID);
		world.setBlock(i + 2, j + 0, k + 21, Block.obsidian.blockID);
		world.setBlock(i + 2, j + 0, k + 22, Block.obsidian.blockID);
		world.setBlock(i + 2, j + 0, k + 23, Block.obsidian.blockID);
		world.setBlock(i + 2, j + 0, k + 24, Block.obsidian.blockID);
		world.setBlock(i + 2, j + 0, k + 25, Block.obsidian.blockID);
		world.setBlock(i + 2, j + 0, k + 26, Block.obsidian.blockID);
		world.setBlock(i + 2, j + 0, k + 27, Block.obsidian.blockID);
		world.setBlock(i + 2, j + 0, k + 28, Block.obsidian.blockID);
		world.setBlock(i + 2, j + 0, k + 29, Block.obsidian.blockID);
		world.setBlock(i + 2, j + 0, k + 30, Block.obsidian.blockID);
		world.setBlock(i + 2, j + 0, k + 31, Block.obsidian.blockID);
		world.setBlock(i + 2, j + 0, k + 32, Block.obsidian.blockID);
		world.setBlock(i + 2, j + 0, k + 33, Block.obsidian.blockID);
		world.setBlock(i + 2, j + 0, k + 34, Block.obsidian.blockID);
		world.setBlock(i + 2, j + 0, k + 35, Block.obsidian.blockID);
		world.setBlock(i + 2, j + 0, k + 36, Block.obsidian.blockID);
		world.setBlock(i + 2, j + 0, k + 37, Block.obsidian.blockID);
		world.setBlock(i + 2, j + 0, k + 38, Block.obsidian.blockID);
		world.setBlock(i + 2, j + 0, k + 39, Block.obsidian.blockID);
		world.setBlock(i + 2, j + 0, k + 40, Block.obsidian.blockID);
		world.setBlock(i + 2, j + 0, k + 41, Block.obsidian.blockID);
		world.setBlock(i + 2, j + 0, k + 42, Block.obsidian.blockID);
		world.setBlock(i + 2, j + 0, k + 43, Block.obsidian.blockID);
		world.setBlock(i + 2, j + 0, k + 44, Block.obsidian.blockID);
		world.setBlock(i + 2, j + 0, k + 45, Block.obsidian.blockID);
		world.setBlock(i + 2, j + 0, k + 46, Block.obsidian.blockID);
		world.setBlock(i + 2, j + 0, k + 47, Block.obsidian.blockID);
		world.setBlock(i + 2, j + 0, k + 48, Block.obsidian.blockID);
		world.setBlock(i + 2, j + 0, k + 49, Block.obsidian.blockID);
		world.setBlock(i + 2, j + 0, k + 50, Block.obsidian.blockID);
		world.setBlock(i + 2, j + 0, k + 51, Block.obsidian.blockID);
		world.setBlock(i + 2, j + 0, k + 52, Block.obsidian.blockID);
		world.setBlock(i + 2, j + 0, k + 53, Block.obsidian.blockID);
		world.setBlock(i + 2, j + 0, k + 54, Block.obsidian.blockID);
		world.setBlock(i + 2, j + 0, k + 55, Block.obsidian.blockID);
		world.setBlock(i + 2, j + 1, k + 0, Block.obsidian.blockID);
		world.setBlock(i + 2, j + 1, k + 16, Block.obsidian.blockID);
		world.setBlock(i + 2, j + 1, k + 17, Block.obsidian.blockID);
		world.setBlock(i + 2, j + 1, k + 18, Block.obsidian.blockID);
		world.setBlock(i + 2, j + 1, k + 19, Block.obsidian.blockID);
		world.setBlock(i + 2, j + 1, k + 20, Block.obsidian.blockID);
		world.setBlock(i + 2, j + 1, k + 21, Block.obsidian.blockID);
		world.setBlock(i + 2, j + 1, k + 22, Block.obsidian.blockID);
		world.setBlock(i + 2, j + 1, k + 23, Block.obsidian.blockID);
		world.setBlock(i + 2, j + 1, k + 24, Block.obsidian.blockID);
		world.setBlock(i + 2, j + 1, k + 25, Block.obsidian.blockID);
		world.setBlock(i + 2, j + 1, k + 26, Block.obsidian.blockID);
		world.setBlock(i + 2, j + 1, k + 27, Block.obsidian.blockID);
		world.setBlock(i + 2, j + 1, k + 28, Block.obsidian.blockID);
		world.setBlock(i + 2, j + 1, k + 29, Block.obsidian.blockID);
		world.setBlock(i + 2, j + 1, k + 30, Block.obsidian.blockID);
		world.setBlock(i + 2, j + 1, k + 31, Block.obsidian.blockID);
		world.setBlock(i + 2, j + 1, k + 32, Block.obsidian.blockID);
		world.setBlock(i + 2, j + 1, k + 33, Block.obsidian.blockID);
		world.setBlock(i + 2, j + 1, k + 34, Block.obsidian.blockID);
		world.setBlock(i + 2, j + 1, k + 35, Block.obsidian.blockID);
		world.setBlock(i + 2, j + 1, k + 36, Block.obsidian.blockID);
		world.setBlock(i + 2, j + 1, k + 37, Block.obsidian.blockID);
		world.setBlock(i + 2, j + 1, k + 48, Block.obsidian.blockID);
		world.setBlock(i + 2, j + 1, k + 49, Block.obsidian.blockID);
		world.setBlock(i + 2, j + 1, k + 50, Block.obsidian.blockID);
		world.setBlock(i + 2, j + 1, k + 55, Block.obsidian.blockID);
		world.setBlock(i + 2, j + 2, k + 0, Block.obsidian.blockID);
		world.setBlock(i + 2, j + 2, k + 16, Block.obsidian.blockID);
		world.setBlock(i + 2, j + 2, k + 17, Block.planks.blockID);
		world.setBlock(i + 2, j + 2, k + 18, Block.planks.blockID);
		world.setBlock(i + 2, j + 2, k + 19, Block.planks.blockID);
		world.setBlock(i + 2, j + 2, k + 20, Block.planks.blockID);
		world.setBlock(i + 2, j + 2, k + 21, Block.planks.blockID);
		world.setBlock(i + 2, j + 2, k + 22, Block.planks.blockID);
		world.setBlock(i + 2, j + 2, k + 23, Block.planks.blockID);
		world.setBlock(i + 2, j + 2, k + 24, Block.planks.blockID);
		world.setBlock(i + 2, j + 2, k + 25, Block.planks.blockID);
		world.setBlock(i + 2, j + 2, k + 26, Block.planks.blockID);
		world.setBlock(i + 2, j + 2, k + 27, Block.planks.blockID);
		world.setBlock(i + 2, j + 2, k + 28, Block.planks.blockID);
		world.setBlock(i + 2, j + 2, k + 29, Block.planks.blockID);
		world.setBlock(i + 2, j + 2, k + 30, Block.planks.blockID);
		world.setBlock(i + 2, j + 2, k + 31, Block.planks.blockID);
		world.setBlock(i + 2, j + 2, k + 32, Block.planks.blockID);
		world.setBlock(i + 2, j + 2, k + 33, Block.planks.blockID);
		world.setBlock(i + 2, j + 2, k + 34, Block.planks.blockID);
		world.setBlock(i + 2, j + 2, k + 35, Block.planks.blockID);
		world.setBlock(i + 2, j + 2, k + 36, Block.planks.blockID);
		world.setBlock(i + 2, j + 2, k + 37, Block.obsidian.blockID);
		world.setBlock(i + 2, j + 2, k + 48, Block.obsidian.blockID);
		world.setBlock(i + 2, j + 2, k + 49, Block.obsidian.blockID);
		world.setBlock(i + 2, j + 2, k + 50, Block.obsidian.blockID);
		world.setBlock(i + 2, j + 2, k + 55, Block.obsidian.blockID);
		world.setBlock(i + 2, j + 3, k + 0, Block.obsidian.blockID);
		world.setBlock(i + 2, j + 3, k + 1, Block.obsidian.blockID);
		world.setBlock(i + 2, j + 3, k + 2, Block.obsidian.blockID);
		world.setBlock(i + 2, j + 3, k + 3, Block.obsidian.blockID);
		world.setBlock(i + 2, j + 3, k + 4, Block.obsidian.blockID);
		world.setBlock(i + 2, j + 3, k + 5, Block.obsidian.blockID);
		world.setBlock(i + 2, j + 3, k + 6, Block.obsidian.blockID);
		world.setBlock(i + 2, j + 3, k + 7, Block.obsidian.blockID);
		world.setBlock(i + 2, j + 3, k + 8, Block.obsidian.blockID);
		world.setBlock(i + 2, j + 3, k + 9, Block.obsidian.blockID);
		world.setBlock(i + 2, j + 3, k + 10, Block.obsidian.blockID);
		world.setBlock(i + 2, j + 3, k + 11, Block.obsidian.blockID);
		world.setBlock(i + 2, j + 3, k + 12, Block.obsidian.blockID);
		world.setBlock(i + 2, j + 3, k + 13, Block.obsidian.blockID);
		world.setBlock(i + 2, j + 3, k + 14, Block.obsidian.blockID);
		world.setBlock(i + 2, j + 3, k + 15, Block.obsidian.blockID);
		world.setBlock(i + 2, j + 3, k + 16, Block.obsidian.blockID);
		world.setBlock(i + 2, j + 3, k + 37, Block.obsidian.blockID);
		world.setBlock(i + 2, j + 3, k + 38, Block.obsidian.blockID);
		world.setBlock(i + 2, j + 3, k + 39, Block.obsidian.blockID);
		world.setBlock(i + 2, j + 3, k + 40, Block.obsidian.blockID);
		world.setBlock(i + 2, j + 3, k + 41, Block.obsidian.blockID);
		world.setBlock(i + 2, j + 3, k + 42, Block.obsidian.blockID);
		world.setBlock(i + 2, j + 3, k + 43, Block.obsidian.blockID);
		world.setBlock(i + 2, j + 3, k + 44, Block.obsidian.blockID);
		world.setBlock(i + 2, j + 3, k + 45, Block.obsidian.blockID);
		world.setBlock(i + 2, j + 3, k + 46, Block.obsidian.blockID);
		world.setBlock(i + 2, j + 3, k + 47, Block.obsidian.blockID);
		world.setBlock(i + 2, j + 3, k + 48, Block.obsidian.blockID);
		world.setBlock(i + 2, j + 3, k + 49, Block.obsidian.blockID);
		world.setBlock(i + 2, j + 3, k + 50, Block.obsidian.blockID);
		world.setBlock(i + 2, j + 3, k + 51, Block.obsidian.blockID);
		world.setBlock(i + 2, j + 3, k + 52, Block.obsidian.blockID);
		world.setBlock(i + 2, j + 3, k + 53, Block.obsidian.blockID);
		world.setBlock(i + 2, j + 3, k + 54, Block.obsidian.blockID);
		world.setBlock(i + 2, j + 3, k + 55, Block.obsidian.blockID);
		world.setBlock(i + 2, j + 4, k + 0, Block.obsidian.blockID);
		world.setBlock(i + 2, j + 4, k + 1, Block.obsidian.blockID);
		world.setBlock(i + 2, j + 4, k + 2, Block.obsidian.blockID);
		world.setBlock(i + 2, j + 4, k + 3, Block.obsidian.blockID);
		world.setBlock(i + 2, j + 4, k + 4, Block.obsidian.blockID);
		world.setBlock(i + 2, j + 4, k + 5, Block.obsidian.blockID);
		world.setBlock(i + 2, j + 4, k + 6, Block.obsidian.blockID);
		world.setBlock(i + 2, j + 4, k + 7, Block.obsidian.blockID);
		world.setBlock(i + 2, j + 4, k + 8, Block.obsidian.blockID);
		world.setBlock(i + 2, j + 4, k + 9, Block.obsidian.blockID);
		world.setBlock(i + 2, j + 4, k + 10, Block.obsidian.blockID);
		world.setBlock(i + 2, j + 4, k + 11, Block.obsidian.blockID);
		world.setBlock(i + 2, j + 4, k + 12, Block.obsidian.blockID);
		world.setBlock(i + 2, j + 4, k + 13, Block.obsidian.blockID);
		world.setBlock(i + 2, j + 4, k + 14, Block.obsidian.blockID);
		world.setBlock(i + 2, j + 4, k + 15, Block.obsidian.blockID);
		world.setBlock(i + 2, j + 4, k + 16, Block.obsidian.blockID);
		world.setBlock(i + 2, j + 4, k + 37, Block.obsidian.blockID);
		world.setBlock(i + 2, j + 4, k + 38, Block.obsidian.blockID);
		world.setBlock(i + 2, j + 4, k + 39, Block.obsidian.blockID);
		world.setBlock(i + 2, j + 4, k + 40, Block.obsidian.blockID);
		world.setBlock(i + 2, j + 4, k + 41, Block.obsidian.blockID);
		world.setBlock(i + 2, j + 4, k + 42, Block.obsidian.blockID);
		world.setBlock(i + 2, j + 4, k + 43, Block.obsidian.blockID);
		world.setBlock(i + 2, j + 4, k + 44, Block.obsidian.blockID);
		world.setBlock(i + 2, j + 4, k + 45, Block.obsidian.blockID);
		world.setBlock(i + 2, j + 4, k + 46, Block.obsidian.blockID);
		world.setBlock(i + 2, j + 4, k + 47, Block.obsidian.blockID);
		world.setBlock(i + 2, j + 4, k + 48, Block.obsidian.blockID);
		world.setBlock(i + 2, j + 4, k + 49, Block.obsidian.blockID);
		world.setBlock(i + 2, j + 4, k + 50, Block.obsidian.blockID);
		world.setBlock(i + 2, j + 4, k + 51, Block.obsidian.blockID);
		world.setBlock(i + 2, j + 4, k + 52, Block.obsidian.blockID);
		world.setBlock(i + 2, j + 4, k + 53, Block.obsidian.blockID);
		world.setBlock(i + 2, j + 4, k + 54, Block.obsidian.blockID);
		world.setBlock(i + 2, j + 4, k + 55, Block.obsidian.blockID);
		world.setBlock(i + 2, j + 5, k + 0, Block.obsidian.blockID);
		world.setBlock(i + 2, j + 5, k + 1, Block.obsidian.blockID);
		world.setBlock(i + 2, j + 5, k + 2, Block.obsidian.blockID);
		world.setBlock(i + 2, j + 5, k + 3, Block.obsidian.blockID);
		world.setBlock(i + 2, j + 5, k + 4, Block.obsidian.blockID);
		world.setBlock(i + 2, j + 5, k + 5, Block.obsidian.blockID);
		world.setBlock(i + 2, j + 5, k + 6, Block.obsidian.blockID);
		world.setBlock(i + 2, j + 5, k + 7, Block.obsidian.blockID);
		world.setBlock(i + 2, j + 5, k + 8, Block.obsidian.blockID);
		world.setBlock(i + 2, j + 5, k + 9, Block.obsidian.blockID);
		world.setBlock(i + 2, j + 5, k + 10, Block.obsidian.blockID);
		world.setBlock(i + 2, j + 5, k + 11, Block.obsidian.blockID);
		world.setBlock(i + 2, j + 5, k + 12, Block.obsidian.blockID);
		world.setBlock(i + 2, j + 5, k + 13, Block.obsidian.blockID);
		world.setBlock(i + 2, j + 5, k + 14, Block.obsidian.blockID);
		world.setBlock(i + 2, j + 5, k + 15, Block.obsidian.blockID);
		world.setBlock(i + 2, j + 5, k + 16, Block.obsidian.blockID);
		world.setBlock(i + 2, j + 5, k + 37, Block.obsidian.blockID);
		world.setBlock(i + 2, j + 5, k + 38, Block.obsidian.blockID);
		world.setBlock(i + 2, j + 5, k + 39, Block.obsidian.blockID);
		world.setBlock(i + 2, j + 5, k + 40, Block.obsidian.blockID);
		world.setBlock(i + 2, j + 5, k + 41, Block.obsidian.blockID);
		world.setBlock(i + 2, j + 5, k + 42, Block.obsidian.blockID);
		world.setBlock(i + 2, j + 5, k + 43, Block.obsidian.blockID);
		world.setBlock(i + 2, j + 5, k + 44, Block.obsidian.blockID);
		world.setBlock(i + 2, j + 5, k + 45, Block.obsidian.blockID);
		world.setBlock(i + 2, j + 5, k + 46, Block.obsidian.blockID);
		world.setBlock(i + 2, j + 5, k + 47, Block.obsidian.blockID);
		world.setBlock(i + 2, j + 5, k + 48, Block.obsidian.blockID);
		world.setBlock(i + 2, j + 5, k + 49, Block.obsidian.blockID);
		world.setBlock(i + 2, j + 5, k + 50, Block.obsidian.blockID);
		world.setBlock(i + 2, j + 5, k + 51, Block.obsidian.blockID);
		world.setBlock(i + 2, j + 5, k + 52, Block.obsidian.blockID);
		world.setBlock(i + 2, j + 5, k + 53, Block.obsidian.blockID);
		world.setBlock(i + 2, j + 5, k + 54, Block.obsidian.blockID);
		world.setBlock(i + 2, j + 5, k + 55, Block.obsidian.blockID);
		world.setBlock(i + 2, j + 6, k + 0, Block.obsidian.blockID);
		world.setBlock(i + 2, j + 6, k + 1, Block.obsidian.blockID);
		world.setBlock(i + 2, j + 6, k + 2, Block.obsidian.blockID);
		world.setBlock(i + 2, j + 6, k + 3, Block.obsidian.blockID);
		world.setBlock(i + 2, j + 6, k + 4, Block.obsidian.blockID);
		world.setBlock(i + 2, j + 6, k + 5, Block.obsidian.blockID);
		world.setBlock(i + 2, j + 6, k + 6, Block.obsidian.blockID);
		world.setBlock(i + 2, j + 6, k + 7, Block.obsidian.blockID);
		world.setBlock(i + 2, j + 6, k + 8, Block.obsidian.blockID);
		world.setBlock(i + 2, j + 6, k + 9, Block.obsidian.blockID);
		world.setBlock(i + 2, j + 6, k + 10, Block.obsidian.blockID);
		world.setBlock(i + 2, j + 6, k + 11, Block.obsidian.blockID);
		world.setBlock(i + 2, j + 6, k + 12, Block.obsidian.blockID);
		world.setBlock(i + 2, j + 6, k + 13, Block.obsidian.blockID);
		world.setBlock(i + 2, j + 6, k + 14, Block.obsidian.blockID);
		world.setBlock(i + 2, j + 6, k + 15, Block.obsidian.blockID);
		world.setBlock(i + 2, j + 6, k + 16, Block.obsidian.blockID);
		world.setBlock(i + 2, j + 6, k + 37, Block.obsidian.blockID);
		world.setBlock(i + 2, j + 6, k + 38, Block.obsidian.blockID);
		world.setBlock(i + 2, j + 6, k + 39, Block.obsidian.blockID);
		world.setBlock(i + 2, j + 6, k + 40, Block.obsidian.blockID);
		world.setBlock(i + 2, j + 6, k + 41, Block.obsidian.blockID);
		world.setBlock(i + 2, j + 6, k + 42, Block.obsidian.blockID);
		world.setBlock(i + 2, j + 6, k + 43, Block.obsidian.blockID);
		world.setBlock(i + 2, j + 6, k + 44, Block.obsidian.blockID);
		world.setBlock(i + 2, j + 6, k + 45, Block.obsidian.blockID);
		world.setBlock(i + 2, j + 6, k + 46, Block.obsidian.blockID);
		world.setBlock(i + 2, j + 6, k + 47, Block.obsidian.blockID);
		world.setBlock(i + 2, j + 6, k + 48, Block.obsidian.blockID);
		world.setBlock(i + 2, j + 6, k + 49, Block.obsidian.blockID);
		world.setBlock(i + 2, j + 6, k + 50, Block.obsidian.blockID);
		world.setBlock(i + 2, j + 6, k + 51, Block.obsidian.blockID);
		world.setBlock(i + 2, j + 6, k + 52, Block.obsidian.blockID);
		world.setBlock(i + 2, j + 6, k + 53, Block.obsidian.blockID);
		world.setBlock(i + 2, j + 6, k + 54, Block.obsidian.blockID);
		world.setBlock(i + 2, j + 6, k + 55, Block.obsidian.blockID);
		world.setBlock(i + 2, j + 7, k + 0, Block.obsidian.blockID);
		world.setBlock(i + 2, j + 7, k + 1, Block.obsidian.blockID);
		world.setBlock(i + 2, j + 7, k + 2, Block.obsidian.blockID);
		world.setBlock(i + 2, j + 7, k + 3, Block.obsidian.blockID);
		world.setBlock(i + 2, j + 7, k + 4, Block.obsidian.blockID);
		world.setBlock(i + 2, j + 7, k + 5, Block.obsidian.blockID);
		world.setBlock(i + 2, j + 7, k + 6, Block.obsidian.blockID);
		world.setBlock(i + 2, j + 7, k + 7, Block.obsidian.blockID);
		world.setBlock(i + 2, j + 7, k + 8, Block.obsidian.blockID);
		world.setBlock(i + 2, j + 7, k + 9, Block.obsidian.blockID);
		world.setBlock(i + 2, j + 7, k + 10, Block.obsidian.blockID);
		world.setBlock(i + 2, j + 7, k + 11, Block.obsidian.blockID);
		world.setBlock(i + 2, j + 7, k + 12, Block.obsidian.blockID);
		world.setBlock(i + 2, j + 7, k + 13, Block.obsidian.blockID);
		world.setBlock(i + 2, j + 7, k + 14, Block.obsidian.blockID);
		world.setBlock(i + 2, j + 7, k + 15, Block.obsidian.blockID);
		world.setBlock(i + 2, j + 7, k + 16, Block.obsidian.blockID);
		world.setBlock(i + 2, j + 7, k + 37, Block.obsidian.blockID);
		world.setBlock(i + 2, j + 7, k + 38, Block.obsidian.blockID);
		world.setBlock(i + 2, j + 7, k + 39, Block.obsidian.blockID);
		world.setBlock(i + 2, j + 7, k + 40, Block.obsidian.blockID);
		world.setBlock(i + 2, j + 7, k + 41, Block.obsidian.blockID);
		world.setBlock(i + 2, j + 7, k + 42, Block.obsidian.blockID);
		world.setBlock(i + 2, j + 7, k + 43, Block.obsidian.blockID);
		world.setBlock(i + 2, j + 7, k + 44, Block.obsidian.blockID);
		world.setBlock(i + 2, j + 7, k + 45, Block.obsidian.blockID);
		world.setBlock(i + 2, j + 7, k + 46, Block.obsidian.blockID);
		world.setBlock(i + 2, j + 7, k + 47, Block.obsidian.blockID);
		world.setBlock(i + 2, j + 7, k + 48, Block.obsidian.blockID);
		world.setBlock(i + 2, j + 7, k + 49, Block.obsidian.blockID);
		world.setBlock(i + 2, j + 7, k + 50, Block.obsidian.blockID);
		world.setBlock(i + 2, j + 7, k + 51, Block.obsidian.blockID);
		world.setBlock(i + 2, j + 7, k + 52, Block.obsidian.blockID);
		world.setBlock(i + 2, j + 7, k + 53, Block.obsidian.blockID);
		world.setBlock(i + 2, j + 7, k + 54, Block.obsidian.blockID);
		world.setBlock(i + 2, j + 7, k + 55, Block.obsidian.blockID);
		world.setBlock(i + 2, j + 8, k + 0, Block.obsidian.blockID);
		world.setBlock(i + 2, j + 8, k + 1, Block.obsidian.blockID);
		world.setBlock(i + 2, j + 8, k + 2, Block.obsidian.blockID);
		world.setBlock(i + 2, j + 8, k + 3, Block.obsidian.blockID);
		world.setBlock(i + 2, j + 8, k + 4, Block.obsidian.blockID);
		world.setBlock(i + 2, j + 8, k + 5, Block.obsidian.blockID);
		world.setBlock(i + 2, j + 8, k + 6, Block.obsidian.blockID);
		world.setBlock(i + 2, j + 8, k + 7, Block.obsidian.blockID);
		world.setBlock(i + 2, j + 8, k + 8, Block.obsidian.blockID);
		world.setBlock(i + 2, j + 8, k + 9, Block.obsidian.blockID);
		world.setBlock(i + 2, j + 8, k + 10, Block.obsidian.blockID);
		world.setBlock(i + 2, j + 8, k + 11, Block.obsidian.blockID);
		world.setBlock(i + 2, j + 8, k + 12, Block.obsidian.blockID);
		world.setBlock(i + 2, j + 8, k + 13, Block.obsidian.blockID);
		world.setBlock(i + 2, j + 8, k + 14, Block.obsidian.blockID);
		world.setBlock(i + 2, j + 8, k + 15, Block.obsidian.blockID);
		world.setBlock(i + 2, j + 8, k + 16, Block.obsidian.blockID);
		world.setBlock(i + 2, j + 8, k + 37, Block.obsidian.blockID);
		world.setBlock(i + 2, j + 8, k + 38, Block.obsidian.blockID);
		world.setBlock(i + 2, j + 8, k + 39, Block.obsidian.blockID);
		world.setBlock(i + 2, j + 8, k + 40, Block.obsidian.blockID);
		world.setBlock(i + 2, j + 8, k + 41, Block.obsidian.blockID);
		world.setBlock(i + 2, j + 8, k + 42, Block.obsidian.blockID);
		world.setBlock(i + 2, j + 8, k + 43, Block.obsidian.blockID);
		world.setBlock(i + 2, j + 8, k + 44, Block.obsidian.blockID);
		world.setBlock(i + 2, j + 8, k + 45, Block.obsidian.blockID);
		world.setBlock(i + 2, j + 8, k + 46, Block.obsidian.blockID);
		world.setBlock(i + 2, j + 8, k + 47, Block.obsidian.blockID);
		world.setBlock(i + 2, j + 8, k + 48, Block.obsidian.blockID);
		world.setBlock(i + 2, j + 8, k + 49, Block.obsidian.blockID);
		world.setBlock(i + 2, j + 8, k + 50, Block.obsidian.blockID);
		world.setBlock(i + 2, j + 8, k + 51, Block.obsidian.blockID);
		world.setBlock(i + 2, j + 8, k + 52, Block.obsidian.blockID);
		world.setBlock(i + 2, j + 8, k + 53, Block.obsidian.blockID);
		world.setBlock(i + 2, j + 8, k + 54, Block.obsidian.blockID);
		world.setBlock(i + 2, j + 8, k + 55, Block.obsidian.blockID);
		world.setBlock(i + 2, j + 9, k + 0, Block.obsidian.blockID);
		world.setBlock(i + 2, j + 9, k + 1, Block.obsidian.blockID);
		world.setBlock(i + 2, j + 9, k + 2, Block.obsidian.blockID);
		world.setBlock(i + 2, j + 9, k + 3, Block.obsidian.blockID);
		world.setBlock(i + 2, j + 9, k + 4, Block.obsidian.blockID);
		world.setBlock(i + 2, j + 9, k + 5, Block.obsidian.blockID);
		world.setBlock(i + 2, j + 9, k + 6, Block.obsidian.blockID);
		world.setBlock(i + 2, j + 9, k + 7, Block.obsidian.blockID);
		world.setBlock(i + 2, j + 9, k + 8, Block.obsidian.blockID);
		world.setBlock(i + 2, j + 9, k + 9, Block.obsidian.blockID);
		world.setBlock(i + 2, j + 9, k + 10, Block.obsidian.blockID);
		world.setBlock(i + 2, j + 9, k + 11, Block.obsidian.blockID);
		world.setBlock(i + 2, j + 9, k + 12, Block.obsidian.blockID);
		world.setBlock(i + 2, j + 9, k + 13, Block.obsidian.blockID);
		world.setBlock(i + 2, j + 9, k + 14, Block.obsidian.blockID);
		world.setBlock(i + 2, j + 9, k + 15, Block.obsidian.blockID);
		world.setBlock(i + 2, j + 9, k + 16, Block.obsidian.blockID);
		world.setBlock(i + 2, j + 9, k + 37, Block.obsidian.blockID);
		world.setBlock(i + 2, j + 9, k + 38, Block.obsidian.blockID);
		world.setBlock(i + 2, j + 9, k + 39, Block.obsidian.blockID);
		world.setBlock(i + 2, j + 9, k + 40, Block.obsidian.blockID);
		world.setBlock(i + 2, j + 9, k + 41, Block.obsidian.blockID);
		world.setBlock(i + 2, j + 9, k + 42, Block.obsidian.blockID);
		world.setBlock(i + 2, j + 9, k + 43, Block.obsidian.blockID);
		world.setBlock(i + 2, j + 9, k + 44, Block.obsidian.blockID);
		world.setBlock(i + 2, j + 9, k + 45, Block.obsidian.blockID);
		world.setBlock(i + 2, j + 9, k + 46, Block.obsidian.blockID);
		world.setBlock(i + 2, j + 9, k + 47, Block.obsidian.blockID);
		world.setBlock(i + 2, j + 9, k + 48, Block.obsidian.blockID);
		world.setBlock(i + 2, j + 9, k + 49, Block.obsidian.blockID);
		world.setBlock(i + 2, j + 9, k + 50, Block.obsidian.blockID);
		world.setBlock(i + 2, j + 9, k + 51, Block.obsidian.blockID);
		world.setBlock(i + 2, j + 9, k + 52, Block.obsidian.blockID);
		world.setBlock(i + 2, j + 9, k + 53, Block.obsidian.blockID);
		world.setBlock(i + 2, j + 9, k + 54, Block.obsidian.blockID);
		world.setBlock(i + 2, j + 9, k + 55, Block.obsidian.blockID);
		world.setBlock(i + 2, j + 10, k + 0, Block.obsidian.blockID);
		world.setBlock(i + 2, j + 10, k + 1, Block.obsidian.blockID);
		world.setBlock(i + 2, j + 10, k + 2, Block.obsidian.blockID);
		world.setBlock(i + 2, j + 10, k + 3, Block.obsidian.blockID);
		world.setBlock(i + 2, j + 10, k + 4, Block.obsidian.blockID);
		world.setBlock(i + 2, j + 10, k + 5, Block.obsidian.blockID);

		generate2(world, rand, i, j, k);
		return true;
	}

	public boolean generate2(World world, Random rand, int i, int j, int k) {
		world.setBlock(i + 2, j + 10, k + 6, Block.obsidian.blockID);
		world.setBlock(i + 2, j + 10, k + 7, Block.obsidian.blockID);
		world.setBlock(i + 2, j + 10, k + 8, Block.obsidian.blockID);
		world.setBlock(i + 2, j + 10, k + 9, Block.obsidian.blockID);
		world.setBlock(i + 2, j + 10, k + 10, Block.obsidian.blockID);
		world.setBlock(i + 2, j + 10, k + 11, Block.obsidian.blockID);
		world.setBlock(i + 2, j + 10, k + 12, Block.obsidian.blockID);
		world.setBlock(i + 2, j + 10, k + 13, Block.obsidian.blockID);
		world.setBlock(i + 2, j + 10, k + 14, Block.obsidian.blockID);
		world.setBlock(i + 2, j + 10, k + 15, Block.obsidian.blockID);
		world.setBlock(i + 2, j + 10, k + 16, Block.obsidian.blockID);
		world.setBlock(i + 2, j + 10, k + 37, Block.obsidian.blockID);
		world.setBlock(i + 2, j + 10, k + 38, Block.obsidian.blockID);
		world.setBlock(i + 2, j + 10, k + 39, Block.obsidian.blockID);
		world.setBlock(i + 2, j + 10, k + 40, Block.obsidian.blockID);
		world.setBlock(i + 2, j + 10, k + 41, Block.obsidian.blockID);
		world.setBlock(i + 2, j + 10, k + 42, Block.obsidian.blockID);
		world.setBlock(i + 2, j + 10, k + 43, Block.obsidian.blockID);
		world.setBlock(i + 2, j + 10, k + 44, Block.obsidian.blockID);
		world.setBlock(i + 2, j + 10, k + 45, Block.obsidian.blockID);
		world.setBlock(i + 2, j + 10, k + 46, Block.obsidian.blockID);
		world.setBlock(i + 2, j + 10, k + 47, Block.obsidian.blockID);
		world.setBlock(i + 2, j + 10, k + 48, Block.obsidian.blockID);
		world.setBlock(i + 2, j + 10, k + 49, Block.obsidian.blockID);
		world.setBlock(i + 2, j + 10, k + 50, Block.obsidian.blockID);
		world.setBlock(i + 2, j + 10, k + 51, Block.obsidian.blockID);
		world.setBlock(i + 2, j + 10, k + 52, Block.obsidian.blockID);
		world.setBlock(i + 2, j + 10, k + 53, Block.obsidian.blockID);
		world.setBlock(i + 2, j + 10, k + 54, Block.obsidian.blockID);
		world.setBlock(i + 2, j + 10, k + 55, Block.obsidian.blockID);
